Workbook

Sheet Caetés
A1: CMS Alerts
A2: Status | B2: WTG | C2: Data do alarme | D2: Priority | E2: Case Title | F2: Component | G2: Diagnosis | H2: Data do Diagnóstico | I2: Service Order | J2: Action | K2: Deadline interpretado | L2: Programação | M2: Data Realizada | N2: Observação | O2: Categorização Boroscopia Componente | P2: Link do Relatório | Q2: Óleo | R2: Fe (ppm)
A3: Closed | B3: EBR05-09 | C3: 46223 | D3: 3 | E3: Main Bearing Accelerometer Issue | G3: Os acelerômetros do main bearing estão indicando um curto-circuito; recomenda-se inspecionar a fiação e as conexões. Substitua o sensor, se necessário. | H3: 46223 | I3: SS00719 | J3: Solicitada inspeções dos sensoriamentos em até 15 dias | K3: =IF(OR(H3="",J3=""),"",IF(ISNUMBER(SEARCH("15*dias",J3)),H3+15,IF(ISNUMBER(SEARCH("1*mês",J3)),EDATE(H3,1),IF(ISNUMBER(SEARCH("2*meses",J3)),EDATE(H3,2),"Prazo não definido")))) -> 46238 | L3: 46269 | M3: 46269 | N3: Resolvido. | Q3: =VLOOKUP(Tabela1[[#This Row],[WTG]],Óleo!N:NA,27,FALSE) -> Anormal | R3: =VLOOKUP(Tabela1[[#This Row],[WTG]],Óleo!N:BL,51,FALSE) -> 23
A4: Closed | B4: EBR05-12 | C4: 46223 | D4: 3 | E4: Stage 2 Parellel Accelerometer Issue | G4: Os acelerômetros do estágio intermediário estão indicando um curto-circuito; recomenda-se inspecionar a fiação e as conexões. Substitua o sensor, se necessário. | H4: 46223 | I4: SS00720 | J4: Solicitada inspeções dos sensoriamentos em até 15 dias | K4: =IF(OR(H4="",J4=""),"",IF(ISNUMBER(SEARCH("15*dias",J4)),H4+15,IF(ISNUMBER(SEARCH("1*mês",J4)),EDATE(H4,1),IF(ISNUMBER(SEARCH("2*meses",J4)),EDATE(H4,2),"Prazo não definido")))) -> 46238 | L4: 46269 | M4: 46269 | N4: Resolvido. | Q4: =VLOOKUP(Tabela1[[#This Row],[WTG]],Óleo!N:NA,27,FALSE) -> Normal | R4: =VLOOKUP(Tabela1[[#This Row],[WTG]],Óleo!N:BL,51,FALSE) -> 51
A5: Closed | B5: EBR05-17 | C5: 46223 | D5: 3 | E5: Stage 3 Parellel Accelerometer Issue | G5: Os acelerômetros do estágio de saída (HSS) estão indicando um curto-circuito; recomenda-se inspecionar a fiação e as conexões. Substitua o sensor, se necessário. | H5: 46223 | I5: SS00721 | J5: Solicitada inspeções dos sensoriamentos em até 15 dias | K5: =IF(OR(H5="",J5=""),"",IF(ISNUMBER(SEARCH("15*dias",J5)),H5+15,IF(ISNUMBER(SEARCH("1*mês",J5)),EDATE(H5,1),IF(ISNUMBER(SEARCH("2*meses",J5)),EDATE(H5,2),"Prazo não definido")))) -> 46238 | M5: 46288 | N5: Resolvido. | Q5: =VLOOKUP(Tabela1[[#This Row],[WTG]],Óleo!N:NA,27,FALSE) -> Normal | R5: =VLOOKUP(Tabela1[[#This Row],[WTG]],Óleo!N:BL,51,FALSE) -> 10
A6: Open | B6: EBR06-11 | C6: 46223 | D6: 3 | E6: Stage 1 Planetary Accelerometer Issue | G6: Os acelerômetros do estágio planetário estão indicando um curto-circuito; recomenda-se inspecionar a fiação e as conexões. Substitua o sensor, se necessário. | H6: 46223 | I6: SS00722 | J6: Solicitada inspeções dos sensoriamentos em até 15 dias | K6: =IF(OR(H6="",J6=""),"",IF(ISNUMBER(SEARCH("15*dias",J6)),H6+15,IF(ISNUMBER(SEARCH("1*mês",J6)),EDATE(H6,1),IF(ISNUMBER(SEARCH("2*meses",J6)),EDATE(H6,2),"Prazo não definido")))) -> 46238 | Q6: =VLOOKUP(Tabela1[[#This Row],[WTG]],Óleo!N:NA,27,FALSE) -> Normal | R6: =VLOOKUP(Tabela1[[#This Row],[WTG]],Óleo!N:BL,51,FALSE) -> 23
A7: Open | B7: EBR07-09 | C7: 46223 | D7: 3 | E7: Stage 2 Parellel Accelerometer Issue | G7: Os acelerômetros do estágio intermediário estão indicando um curto-circuito; recomenda-se inspecionar a fiação e as conexões. Substitua o sensor, se necessário. | H7: 46223 | I7: SS00723 | J7: Solicitada inspeções dos sensoriamentos em até 15 dias | K7: =IF(OR(H7="",J7=""),"",IF(ISNUMBER(SEARCH("15*dias",J7)),H7+15,IF(ISNUMBER(SEARCH("1*mês",J7)),EDATE(H7,1),IF(ISNUMBER(SEARCH("2*meses",J7)),EDATE(H7,2),"Prazo não definido")))) -> 46238 | Q7: =VLOOKUP(Tabela1[[#This Row],[WTG]],Óleo!N:NA,27,FALSE) -> #N/A | R7: =VLOOKUP(Tabela1[[#This Row],[WTG]],Óleo!N:BL,51,FALSE) -> #N/A
A8: Open | B8: EBR07-10 | C8: 46223 | D8: 3 | E8: Main Bearing Accelerometer Issue | G8: Os acelerômetros do main bearing estão indicando um curto-circuito; recomenda-se inspecionar a fiação e as conexões. Substitua o sensor, se necessário. | H8: 46223 | I8: SS00724 | J8: Solicitada inspeções dos sensoriamentos em até 15 dias | K8: =IF(OR(H8="",J8=""),"",IF(ISNUMBER(SEARCH("15*dias",J8)),H8+15,IF(ISNUMBER(SEARCH("1*mês",J8)),EDATE(H8,1),IF(ISNUMBER(SEARCH("2*meses",J8)),EDATE(H8,2),"Prazo não definido")))) -> 46238 | Q8: =VLOOKUP(Tabela1[[#This Row],[WTG]],Óleo!N:NA,27,FALSE) -> Normal | R8: =VLOOKUP(Tabela1[[#This Row],[WTG]],Óleo!N:BL,51,FALSE) -> 6
A9: Open | B9: EBR07-14 | C9: 46223 | D9: 3 | E9: Stage 2 Parellel Accelerometer Issue | G9: Os acelerômetros do estágio intermediário estão indicando um curto-circuito; recomenda-se inspecionar a fiação e as conexões. Substitua o sensor, se necessário. | H9: 46223 | I9: SS00725 | J9: Solicitada inspeções dos sensoriamentos em até 15 dias | K9: =IF(OR(H9="",J9=""),"",IF(ISNUMBER(SEARCH("15*dias",J9)),H9+15,IF(ISNUMBER(SEARCH("1*mês",J9)),EDATE(H9,1),IF(ISNUMBER(SEARCH("2*meses",J9)),EDATE(H9,2),"Prazo não definido")))) -> 46238 | Q9: =VLOOKUP(Tabela1[[#This Row],[WTG]],Óleo!N:NA,27,FALSE) -> Crítico | R9: =VLOOKUP(Tabela1[[#This Row],[WTG]],Óleo!N:BL,51,FALSE) -> 99
A10: Closed | B10: EBR01-01 | C10: 46202 | D10: 2 | E10: HSS Rotational | F10: Generator Hitachi | G10: Dados de CMS apresentam indícios de desalinhamento do gerador. Recomenda-se a verificação do alinhamento do gerador e inspeção do acoplamento flexível do HSS. | H10: 46262 | I10: SS00868 | J10: Solicitada a verificação do alinhamento do gerador e inspeção do acoplamento flexível do HSS para quaisquer sinais de danos | K10: =IF(OR(H10="",J10=""),"",IF(ISNUMBER(SEARCH("15*dias",J10)),H10+15,IF(ISNUMBER(SEARCH("1*mês",J10)),EDATE(H10,1),IF(ISNUMBER(SEARCH("2*meses",J10)),EDATE(H10,2),"Prazo não definido")))) -> Prazo não definido | L10: 46175 | M10: 46175 | N10: Gearbox substituida em 01/05/2026, alinhamento realizado em 02/06/2026 junto a preventiva de lubrificação - Atividade Invenergy | O10: - | P10: - | Q10: =VLOOKUP(Tabela1[[#This Row],[WTG]],Óleo!N:NA,27,FALSE) -> Anormal | R10: =VLOOKUP(Tabela1[[#This Row],[WTG]],Óleo!N:BL,51,FALSE) -> 15
A11: Closed | B11: EBR01-02 | C11: 46261 | D11: 2 | E11: HSS Rotational | F11: Generator Hitachi | G11: Dados de CMS apresentam indícios de desalinhamento do gerador. Recomenda-se a verificação do alinhamento do gerador e inspeção do acoplamento flexível do HSS. | H11: 46262 | I11: SS00869 | J11: Solicitada a verificação do alinhamento do gerador e inspeção do acoplamento flexível do HSS para quaisquer sinais de danos | K11: =IF(OR(H11="",J11=""),"",IF(ISNUMBER(SEARCH("15*dias",J11)),H11+15,IF(ISNUMBER(SEARCH("1*mês",J11)),EDATE(H11,1),IF(ISNUMBER(SEARCH("2*meses",J11)),EDATE(H11,2),"Prazo não definido")))) -> Prazo não definido | L11: 46262 | M11: 46262 | N11: Substituido os rolamento DW e DWR do HSS + Substituido os Elastômeros + Microfiltragem do Óleo + Alinhamento do gerador em 27/08/2026 - Atividade Invenergy | P11: - | Q11: =VLOOKUP(Tabela1[[#This Row],[WTG]],Óleo!N:NA,27,FALSE) -> Normal | R11: =VLOOKUP(Tabela1[[#This Row],[WTG]],Óleo!N:BL,51,FALSE) -> 15
A12: Closed | B12: EBR01-07 | C12: 45939 | D12: 3 | E12: Planetary Stage Accelerometer Issue | F12: Nanjing FDMD | G12: Dados de CMS indicam que os acelerômetros do estágio planetário estão indicando um curto-circuito. | H12: 46262 | I12: SS00870 | J12: Solicitada inspeção dos sensores do estágio planetário e suas fiações em até 2 meses | K12: =IF(OR(H12="",J12=""),"",IF(ISNUMBER(SEARCH("15*dias",J12)),H12+15,IF(ISNUMBER(SEARCH("1*mês",J12)),EDATE(H12,1),IF(ISNUMBER(SEARCH("2*meses",J12)),EDATE(H12,2),"Prazo não definido")))) -> 46323 | L12: 46273 | M12: 46273 | N12: Caso resolvido. | P12: - | Q12: =VLOOKUP(Tabela1[[#This Row],[WTG]],Óleo!N:NA,27,FALSE) -> Normal | R12: =VLOOKUP(Tabela1[[#This Row],[WTG]],Óleo!N:BL,51,FALSE) -> 17
A13: Waiting report | B13: EBR02-03 | C13: 46246 | D13: 3 | E13: Main Bearing ORBP | F13: Main Bearing KOYO | G13: Dados de CMS apresentam indícios de danos de pista externa do Main Bearing. Recomenda-se realizar uma boroscopia e uma purga de graxa. | H13: 46262 | I13: SS00877 | J13: Solicitada a realização da inspeção boroscópica em até 2 meses | K13: =IF(OR(H13="",J13=""),"",IF(ISNUMBER(SEARCH("15*dias",J13)),H13+15,IF(ISNUMBER(SEARCH("1*mês",J13)),EDATE(H13,1),IF(ISNUMBER(SEARCH("2*meses",J13)),EDATE(H13,2),"Prazo não definido")))) -> 46323 | L13: 46290 | M13: 46290 | N13: Realizada boroscopia. Pendente relatório. | Q13: =VLOOKUP(Tabela1[[#This Row],[WTG]],Óleo!N:NA,27,FALSE) -> Normal | R13: =VLOOKUP(Tabela1[[#This Row],[WTG]],Óleo!N:BL,51,FALSE) -> 11
A14: Closed | B14: EBR02-12 | C14: 46175 | D14: 3 | E14: Main Bearing IRBP/ORBP | F14: Main Bearing KOYO | G14: Dados de CMS apresentam indícios de danos de pista interna e externa do Main Bearing. Recomenda-se realizar uma boroscopia e uma purga de graxa. | H14: 46262 | I14: SS00878 | J14: Solicitada a realização da inspeção boroscópica em até 2 meses | K14: =IF(OR(H14="",J14=""),"",IF(ISNUMBER(SEARCH("15*dias",J14)),H14+15,IF(ISNUMBER(SEARCH("1*mês",J14)),EDATE(H14,1),IF(ISNUMBER(SEARCH("2*meses",J14)),EDATE(H14,2),"Prazo não definido")))) -> 46323 | L14: 46265 | M14: 46265 | N14: Inspeção e flushing do main bearing realizado em 31/08/2026 - Atividade Auren. Boroscopia compartilhada evidencia descamação na pista externa do rolamento. Questionar Auren se haverá troca. Sem recomendação de troca e limitação. | O14: CAT03 | P14: https://invenergy.sharepoint.com/:b:/r/sites/assetmanagement/InvenergyServicesBrazilOpPortal/Engineering/01.%20Engineering%20%26%20O%26M/04.%20Alto%20Sert%C3%A3o%20II%20%26%20Caet%C3%A9s/05.%20Boroscopias/Inspe%C3%A7%C3%A3o%20Main%20Bearing%20EBR2-12.pdf?d=weeddd45da83140389811db7bfde40535&csf=1&web=1&e=w0YtW8 | Q14: =VLOOKUP(Tabela1[[#This Row],[WTG]],Óleo!N:NA,27,FALSE) -> Normal | R14: =VLOOKUP(Tabela1[[#This Row],[WTG]],Óleo!N:BL,51,FALSE) -> 10
A15: Waiting report | B15: EBR02-14 | C15: 45973 | D15: 3 | E15: Main Bearing IRBP/ORBP | F15: Main Bearing KOYO | G15: Dados de CMS apresentam indícios de danos de pista externa do Main Bearing. Recomenda-se realizar uma boroscopia e uma purga de graxa. | H15: 46262 | I15: SS00879 | J15: Solicitada a realização da inspeção boroscópica em até 2 meses | K15: =IF(OR(H15="",J15=""),"",IF(ISNUMBER(SEARCH("15*dias",J15)),H15+15,IF(ISNUMBER(SEARCH("1*mês",J15)),EDATE(H15,1),IF(ISNUMBER(SEARCH("2*meses",J15)),EDATE(H15,2),"Prazo não definido")))) -> 46323 | L15: 46304 | Q15: =VLOOKUP(Tabela1[[#This Row],[WTG]],Óleo!N:NA,27,FALSE) -> Normal | R15: =VLOOKUP(Tabela1[[#This Row],[WTG]],Óleo!N:BL,51,FALSE) -> 10
A16: Closed | B16: EBR03-03 | C16: 46196 | D16: 3 | E16: Generator Outboard Accelerometer issue | F16: Generator Hitachi | G16: Dados de CMS indicam que os acelerômetros do rolamento downwind do gerador estão indicando um curto-circuito. | H16: 46262 | I16: SS00880 | J16: Solicitada inspeção do sensor do gerador e suas fiações em até 2 meses | K16: =IF(OR(H16="",J16=""),"",IF(ISNUMBER(SEARCH("15*dias",J16)),H16+15,IF(ISNUMBER(SEARCH("1*mês",J16)),EDATE(H16,1),IF(ISNUMBER(SEARCH("2*meses",J16)),EDATE(H16,2),"Prazo não definido")))) -> 46323 | L16: 46274 | M16: 46274 | N16: OM - 17768 - Foiexecutada, porém, não foi corrigido. Será aberta nova SS. | P16: - | Q16: =VLOOKUP(Tabela1[[#This Row],[WTG]],Óleo!N:NA,27,FALSE) -> Normal | R16: =VLOOKUP(Tabela1[[#This Row],[WTG]],Óleo!N:BL,51,FALSE) -> 25
A17: Waiting report | B17: EBR03-04 | C17: 46262 | D17: 3 | E17: Intermediate stage gear issue | F17: Nanjing FDMD | G17: Dados de CMS apresentam indícios de danos na engrenagem do estágio intermediário. Recomenda-se realizar uma boroscopia com foco no segundo estágio. | H17: 46262 | I17: SS00881 | J17: Solicitada a realização da inspeção boroscópica em até 2 meses | K17: =IF(OR(H17="",J17=""),"",IF(ISNUMBER(SEARCH("15*dias",J17)),H17+15,IF(ISNUMBER(SEARCH("1*mês",J17)),EDATE(H17,1),IF(ISNUMBER(SEARCH("2*meses",J17)),EDATE(H17,2),"Prazo não definido")))) -> 46323 | L17: 46309 | M17: 46288 | N17: Realizada boroscopia. Pendente relatório. | Q17: =VLOOKUP(Tabela1[[#This Row],[WTG]],Óleo!N:NA,27,FALSE) -> Normal | R17: =VLOOKUP(Tabela1[[#This Row],[WTG]],Óleo!N:BL,51,FALSE) -> 5
A18: Waiting report | B18: EBR03-08 | C18: 46120 | D18: 3 | E18: Main Bearing ORBP | F18: Main Bearing KOYO | G18: Dados de CMS apresentam indícios de danos de pista externa do Main Bearing. Recomenda-se realizar uma boroscopia e uma purga de graxa. | H18: 46262 | I18: SS00882 | J18: Solicitada a realização da inspeção boroscópica em até 2 meses | K18: =IF(OR(H18="",J18=""),"",IF(ISNUMBER(SEARCH("15*dias",J18)),H18+15,IF(ISNUMBER(SEARCH("1*mês",J18)),EDATE(H18,1),IF(ISNUMBER(SEARCH("2*meses",J18)),EDATE(H18,2),"Prazo não definido")))) -> 46323 | L18: 46311 | Q18: =VLOOKUP(Tabela1[[#This Row],[WTG]],Óleo!N:NA,27,FALSE) -> Normal | R18: =VLOOKUP(Tabela1[[#This Row],[WTG]],Óleo!N:BL,51,FALSE) -> 16
A19: Derating recommended | B19: EBR03-14 | C19: 45950 | D19: 3 | E19: Planetary stage bearing issue | F19: Nanjing FDMD | G19: Dados de CMS apresentam indícios de danos nos rolamentos dos planetas do estágio planetário da gearbox. Recomenda-se realizar uma boroscopia com foco no estágio planetário. | H19: 46262 | I19: SS00883 | J19: Solicitada a realização da inspeção boroscópica em até 2 meses | K19: =IF(OR(H19="",J19=""),"",IF(ISNUMBER(SEARCH("15*dias",J19)),H19+15,IF(ISNUMBER(SEARCH("1*mês",J19)),EDATE(H19,1),IF(ISNUMBER(SEARCH("2*meses",J19)),EDATE(H19,2),"Prazo não definido")))) -> 46323 | L19: 46281 | M19: 46281 | N19: Realizada boroscopia. Relatório já disponível. | O19: CAT03 | P19: https://app.safetyculture.com/report/public/audit/ec0829e010fe42de02239419e6319c0af42a222e541d96a5897d750c645b50d5 | Q19: =VLOOKUP(Tabela1[[#This Row],[WTG]],Óleo!N:NA,27,FALSE) -> Anormal | R19: =VLOOKUP(Tabela1[[#This Row],[WTG]],Óleo!N:BL,51,FALSE) -> 26
A20: Waiting report | B20: EBR03-15 | C20: 46189 | D20: 3 | E20: Main Bearing ORBP | F20: Main Bearing KOYO | G20: Dados de CMS apresentam indícios de danos de pista externa do Main Bearing. Recomenda-se realizar uma boroscopia e uma purga de graxa. | H20: 46262 | I20: SS00884 | J20: Solicitada a realização da inspeção boroscópica em até 2 meses | K20: =IF(OR(H20="",J20=""),"",IF(ISNUMBER(SEARCH("15*dias",J20)),H20+15,IF(ISNUMBER(SEARCH("1*mês",J20)),EDATE(H20,1),IF(ISNUMBER(SEARCH("2*meses",J20)),EDATE(H20,2),"Prazo não definido")))) -> 46323 | L20: 46318 | Q20: =VLOOKUP(Tabela1[[#This Row],[WTG]],Óleo!N:NA,27,FALSE) -> Anormal | R20: =VLOOKUP(Tabela1[[#This Row],[WTG]],Óleo!N:BL,51,FALSE) -> 8
A21: Closed | B21: EBR04-03 | D21: 3 | E21: Planetary stage bearing issue | F21: Nanjing FDMD | G21: Dados de CMS apresentam indícios de danos nos rolamentos dos planetas do estágio planetário da gearbox. Recomenda-se realizar uma boroscopia com foco no estágio planetário. | H21: 46262 | I21: SS00885 | J21: Solicitada a realização da inspeção boroscópica em até 2 meses | K21: =IF(OR(H21="",J21=""),"",IF(ISNUMBER(SEARCH("15*dias",J21)),H21+15,IF(ISNUMBER(SEARCH("1*mês",J21)),EDATE(H21,1),IF(ISNUMBER(SEARCH("2*meses",J21)),EDATE(H21,2),"Prazo não definido")))) -> 46323 | L21: 46248 | M21: 46248 | N21: Boroscopia completa da Gearbox realizada em 14/08/2026 - Atividade Auren. Identificado quebra do dente da planetária 01, além de endentação nos demais estágios. Iniciada a troca do componente pela Auren. | O21: CAT04 | P21: https://invenergy.sharepoint.com/:b:/r/sites/assetmanagement/InvenergyServicesBrazilOpPortal/Engineering/01.%20Engineering%20%26%20O%26M/04.%20Alto%20Sert%C3%A3o%20II%20%26%20Caet%C3%A9s/05.%20Boroscopias/Inspection_GEARBOX_ATT-EBR4-03%20(1).pdf?d=wd679fab2dbff4ec48677f4b75898f4e5&csf=1&web=1&e=liwmmn | Q21: =VLOOKUP(Tabela1[[#This Row],[WTG]],Óleo!N:NA,27,FALSE) -> Normal | R21: =VLOOKUP(Tabela1[[#This Row],[WTG]],Óleo!N:BL,51,FALSE) -> 18
A22: Monitor | B22: EBR04-08 | C22: 45965 | D22: 2 | E22: HSS Rotational | F22: Generator Hitachi | G22: Dados de CMS apresentam indícios de desalinhamento do gerador. Recomenda-se a verificação do alinhamento do gerador e inspeção do acoplamento flexível do HSS. | H22: 46262 | I22: SS00886 | J22: Solicitada a verificação do alinhamento do gerador e inspeção do acoplamento flexível do HSS para quaisquer sinais de danos | K22: =IF(OR(H22="",J22=""),"",IF(ISNUMBER(SEARCH("15*dias",J22)),H22+15,IF(ISNUMBER(SEARCH("1*mês",J22)),EDATE(H22,1),IF(ISNUMBER(SEARCH("2*meses",J22)),EDATE(H22,2),"Prazo não definido")))) -> Prazo não definido | L22: 46267 | M22: 46267 | N22: Realizada Inspeção e alinhamento do acoplamento do gerador, conferência dos elementos de fixação e instrumentação - 02/09/26 - Time Invenergy | P22: - | Q22: =VLOOKUP(Tabela1[[#This Row],[WTG]],Óleo!N:NA,27,FALSE) -> Normal | R22: =VLOOKUP(Tabela1[[#This Row],[WTG]],Óleo!N:BL,51,FALSE) -> 20
A23: Cobrar Auren | B23: EBR05-04 | D23: 3 | E23: Main Bearing Accelerometer Issue | F23: Main Bearing KOYO | G23: Dados de CMS indicam que os acelerômetros do main bearing estão indicando uma leitura incorreta. | H23: 46262 | I23: SS00887 | J23: Solicitada inspeção dos sensores do main bearing e suas fiações em até 2 meses | K23: =IF(OR(H23="",J23=""),"",IF(ISNUMBER(SEARCH("15*dias",J23)),H23+15,IF(ISNUMBER(SEARCH("1*mês",J23)),EDATE(H23,1),IF(ISNUMBER(SEARCH("2*meses",J23)),EDATE(H23,2),"Prazo não definido")))) -> 46323 | L23: 46244 | M23: 46219 | N23: Inspeção e flushing do main bearing realizado em 16/07/2026 - Atividade Auren. | Q23: =VLOOKUP(Tabela1[[#This Row],[WTG]],Óleo!N:NA,27,FALSE) -> Normal | R23: =VLOOKUP(Tabela1[[#This Row],[WTG]],Óleo!N:BL,51,FALSE) -> 25
A24: Monitor | B24: EBR05-08 | C24: 46238 | D24: 3 | E24: Intermediate Stage Issue | F24: Nanjing FDMD | G24: Dados de CMS apresentam indícios de danos no estágio intermediário da gearbox. Recomenda-se realizar uma boroscopia com foco no segundo estágio. | H24: 46262 | I24: SS00888 | J24: Solicitada a realização da inspeção boroscópica em até 2 meses | K24: =IF(OR(H24="",J24=""),"",IF(ISNUMBER(SEARCH("15*dias",J24)),H24+15,IF(ISNUMBER(SEARCH("1*mês",J24)),EDATE(H24,1),IF(ISNUMBER(SEARCH("2*meses",J24)),EDATE(H24,2),"Prazo não definido")))) -> 46323 | L24: 46283 | M24: 46282 | N24: Realizada boroscopia. Relatório já disponível. | O24: CAT02 | P24: https://app.safetyculture.com/report/public/audit/afad19bb3b7b6719bd691b1bc664a0d798ab4901b5d9bbfc4bed83fa07bd2cab | Q24: =VLOOKUP(Tabela1[[#This Row],[WTG]],Óleo!N:NA,27,FALSE) -> Anormal | R24: =VLOOKUP(Tabela1[[#This Row],[WTG]],Óleo!N:BL,51,FALSE) -> 118
A25: Closed | B25: EBR05-10 | C25: 46089 | D25: 3 | E25: HSS DnWind Rear Bearing Issue | F25: Nanjing FDMD | G25: Dados de CMS apresentam indícios de danos no rolamento down wind rear da gearbox. Recomenda-se realizar uma inspeção no filtro de óleo da gearbox para verificar existência de limalhas. | H25: 46262 | I25: SS00889 | J25: Solicitada a realização da inspeção no filtro de óleo da gearbox em até 2 meses | K25: =IF(OR(H25="",J25=""),"",IF(ISNUMBER(SEARCH("15*dias",J25)),H25+15,IF(ISNUMBER(SEARCH("1*mês",J25)),EDATE(H25,1),IF(ISNUMBER(SEARCH("2*meses",J25)),EDATE(H25,2),"Prazo não definido")))) -> 46323 | L25: 46288 | M25: 46276 | N25: Turbina já monitorada pela engenharia Auren para substituição do rolamento DWR. OM18179. | P25: - | Q25: =VLOOKUP(Tabela1[[#This Row],[WTG]],Óleo!N:NA,27,FALSE) -> Normal | R25: =VLOOKUP(Tabela1[[#This Row],[WTG]],Óleo!N:BL,51,FALSE) -> 16
A26: Closed | B26: EBR06-09 | C26: 45931 | D26: 3 | E26: Planetary stage bearing issue | F26: Nanjing FDMD | G26: Dados de CMS apresentam indícios de danos nos rolamentos dos planetas do estágio planetário da gearbox. Recomenda-se realizar uma boroscopia com foco no estágio planetário. | H26: 46262 | I26: SS00890 | J26: Solicitada a realização da inspeção boroscópica em até 2 meses | K26: =IF(OR(H26="",J26=""),"",IF(ISNUMBER(SEARCH("15*dias",J26)),H26+15,IF(ISNUMBER(SEARCH("1*mês",J26)),EDATE(H26,1),IF(ISNUMBER(SEARCH("2*meses",J26)),EDATE(H26,2),"Prazo não definido")))) -> 46323 | M26: 46188 | N26: Boroscopia completa da Gearbox realizada em 15/06/2026 - Atividade Auren. Turbina limitada em 716KW com acompanhamento por dano no rolamento PG2 da planetária. Descamação avançada no rolamento da planetária 2, além de presença de endentações avançadas nas engrenagens planetárias. | O26: CAT03 | P26: https://invenergy.sharepoint.com/:b:/r/sites/assetmanagement/InvenergyServicesBrazilOpPortal/Engineering/01.%20Engineering%20%26%20O%26M/04.%20Alto%20Sert%C3%A3o%20II%20%26%20Caet%C3%A9s/05.%20Boroscopias/Inspection_GEARBOX_ATT-EBR6-09.docx.pdf?d=w21c561e784c34f5fadcc850492165271&csf=1&web=1&e=BkGkDS | Q26: =VLOOKUP(Tabela1[[#This Row],[WTG]],Óleo!N:NA,27,FALSE) -> Normal | R26: =VLOOKUP(Tabela1[[#This Row],[WTG]],Óleo!N:BL,51,FALSE) -> 18
A27: Closed | B27: EBR07-02 | C27: 45931 | D27: 3 | E27: Planetary Accelerometer issue | F27: Nanjing FDMD | G27: Dados de CMS indicam que os acelerômetros do estágio planetário estão indicando uma leitura incorreta. | H27: 46262 | I27: SS00891 | J27: Solicitada inspeção dos sensores do estágio planetário e suas fiações em até 2 meses | K27: =IF(OR(H27="",J27=""),"",IF(ISNUMBER(SEARCH("15*dias",J27)),H27+15,IF(ISNUMBER(SEARCH("1*mês",J27)),EDATE(H27,1),IF(ISNUMBER(SEARCH("2*meses",J27)),EDATE(H27,2),"Prazo não definido")))) -> 46323 | L27: 46273 | M27: 46273 | N27: OM - 17653 | Q27: =VLOOKUP(Tabela1[[#This Row],[WTG]],Óleo!N:NA,27,FALSE) -> Normal | R27: =VLOOKUP(Tabela1[[#This Row],[WTG]],Óleo!N:BL,51,FALSE) -> 37
A28: Waiting report | B28: EBR07-07 | C28: 46262 | D28: 3 | E28: Main Bearing IRBP | F28: Main Bearing KOYO | G28: Dados de CMS apresentam indícios de danos de pista interna do Main Bearing. Recomenda-se realizar uma boroscopia e uma purga de graxa. | H28: 46262 | I28: SS00892 | J28: Solicitada a realização da inspeção boroscópica em até 2 meses | K28: =IF(OR(H28="",J28=""),"",IF(ISNUMBER(SEARCH("15*dias",J28)),H28+15,IF(ISNUMBER(SEARCH("1*mês",J28)),EDATE(H28,1),IF(ISNUMBER(SEARCH("2*meses",J28)),EDATE(H28,2),"Prazo não definido")))) -> 46323 | L28: 46330 | Q28: =VLOOKUP(Tabela1[[#This Row],[WTG]],Óleo!N:NA,27,FALSE) -> #VALUE! | R28: =VLOOKUP(Tabela1[[#This Row],[WTG]],Óleo!N:BL,51,FALSE) -> #VALUE!
A29: Open | B29: EBR05-12 | C29: 46286 | D29: 3 | E29: Intermediate Stage Issue | G29: Dados de CMS apresentam indícios de danos no estágio intermediário da gearbox. Recomenda-se realizar uma boroscopia com foco no segundo estágio. | H29: 46287 | I29: SS00941 | J29: Solicitada a realização da inspeção boroscópica em até 2 meses | K29: =IF(OR(H29="",J29=""),"",IF(ISNUMBER(SEARCH("15*dias",J29)),H29+15,IF(ISNUMBER(SEARCH("1*mês",J29)),EDATE(H29,1),IF(ISNUMBER(SEARCH("2*meses",J29)),EDATE(H29,2),"Prazo não definido")))) -> 46348 | M29: 46289 | N29: Realizada boroscopia. Pendente relatório. | P29: https://app.safetyculture.com/report/public/audit/44ae15060eb83ee29a6dec946eaf8f88719a5a48be7bec4ebfaf862c05765a19 | Q29: =VLOOKUP(Tabela1[[#This Row],[WTG]],Óleo!N:NA,27,FALSE) -> #VALUE! | R29: =VLOOKUP(Tabela1[[#This Row],[WTG]],Óleo!N:BL,51,FALSE) -> #VALUE!
A30: Monitor | B30: EBR01-06 | C30: 46289 | D30: 4 | E30: HSS DnWind IRBP | G30: Dados de CMS indicam possíveis danos no rolamento DownWind do HSS. Recomenda-se realizar uma boroscopia com foco no HSS e seus rolamentos. | H30: 46293 | J30: Solicitada a realização da inspeção boroscópica em até 2 meses | K30: =IF(OR(H30="",J30=""),"",IF(ISNUMBER(SEARCH("15*dias",J30)),H30+15,IF(ISNUMBER(SEARCH("1*mês",J30)),EDATE(H30,1),IF(ISNUMBER(SEARCH("2*meses",J30)),EDATE(H30,2),"Prazo não definido")))) -> 46354 | N30: Boroscopia de março evidencia endentações nos rolamentos e no pinhão. | O30: CAT02 | P30: https://app.safetyculture.com/report/public/audit/7e12e1ceeec6bd99cca393d91c7a9f719a556c34d209c086905733a8c3c124a0 | Q30: =VLOOKUP(Tabela1[[#This Row],[WTG]],Óleo!N:NA,27,FALSE) -> #VALUE! | R30: =VLOOKUP(Tabela1[[#This Row],[WTG]],Óleo!N:BL,51,FALSE) -> #VALUE!
A31: Open | B31: EBR03-03 | C31: 46289 | D31: 3 | E31: Generator Outboard Accelerometer issue | F31: Generator Hitachi | G31: Dados de CMS indicam que os acelerômetros do rolamento downwind do gerador estão indicando um curto-circuito. | H31: 46293 | I31: SS00954 | J31: Solicitada inspeção do sensor do gerador e suas fiações em até 1 mês | K31: =IF(OR(H31="",J31=""),"",IF(ISNUMBER(SEARCH("15*dias",J31)),H31+15,IF(ISNUMBER(SEARCH("1*mês",J31)),EDATE(H31,1),IF(ISNUMBER(SEARCH("2*meses",J31)),EDATE(H31,2),"Prazo não definido")))) -> 46323 | Q31: =VLOOKUP(Tabela1[[#This Row],[WTG]],Óleo!N:NA,27,FALSE) -> #VALUE! | R31: =VLOOKUP(Tabela1[[#This Row],[WTG]],Óleo!N:BL,51,FALSE) -> #VALUE!
A32: Monitor | B32: EBR05-04 | C32: 46293 | D32: 3 | E32: Intermediate stage gear issue | F32: Gearbox | G32: Dados de CMS indicam possíveis danos no estágio intermediário, como foco no HSIS. | H32: 46300 | J32: Monitoramento | K32: =IF(OR(H32="",J32=""),"",IF(ISNUMBER(SEARCH("15*dias",J32)),H32+15,IF(ISNUMBER(SEARCH("1*mês",J32)),EDATE(H32,1),IF(ISNUMBER(SEARCH("2*meses",J32)),EDATE(H32,2),"Prazo não definido")))) -> Prazo não definido | N32: Foram identificadas marcas circunferenciais nos rolamentos do HSS, além de marcas de paradas moderadas no pinhão do HSS. Ring gear com marcas superficiais. Monitoramento. | O32: CAT02 | P32: https://invenergy.sharepoint.com/:b:/r/sites/assetmanagement/InvenergyServicesBrazilOpPortal/Engineering/01.%20Engineering%20%26%20O%26M/04.%20Alto%20Sert%C3%A3o%20II%20%26%20Caet%C3%A9s/05.%20Boroscopias/Inspection_GEARBOX_ATT-EBR5-04_0434.pdf?d=wa4915ca2ee5a4eb1ba88b528296eaceb&csf=1&web=1&e=t78Mmj | Q32: =VLOOKUP(Tabela1[[#This Row],[WTG]],Óleo!N:NA,27,FALSE) -> #VALUE! | R32: =VLOOKUP(Tabela1[[#This Row],[WTG]],Óleo!N:BL,51,FALSE) -> #VALUE!
A33: Open | B33: EBR07-02 | C33: 46294 | D33: 2 | E33: Gearbox Accelerometer issue | F33: Nanjing FDMD | G33: O acelerômetros da gearbox estão indicando curtos-circuitos; recomenda-se inspecionar a fiação e as conexões. Substitua os sensores, se necessário. | H33: 46300 | I33: SS00988 | J33: Solicitada inspeção dos sensores da gearbox e suas fiações em até 1 mês | K33: =IF(OR(H33="",J33=""),"",IF(ISNUMBER(SEARCH("15*dias",J33)),H33+15,IF(ISNUMBER(SEARCH("1*mês",J33)),EDATE(H33,1),IF(ISNUMBER(SEARCH("2*meses",J33)),EDATE(H33,2),"Prazo não definido")))) -> 46331 | Q33: =VLOOKUP(Tabela1[[#This Row],[WTG]],Óleo!N:NA,27,FALSE) -> #VALUE! | R33: =VLOOKUP(Tabela1[[#This Row],[WTG]],Óleo!N:BL,51,FALSE) -> #VALUE!

Sheet Alto Sertão 2
A1: CMS Alerts
A2: Status | B2: WTG | C2: Data do alarme | D2: Priority | E2: Case Title | F2: Component | G2: Diagnosis | H2: Data do Diagnóstico | I2: Service Order | J2: Action | K2: Deadline interpretado | L2: Programação | M2: Data Realizada | N2: Observação | O2: Categorização Boroscopia Gearbox | P2: Link do Relatório | Q2: Óleo | R2: Fe (ppm)
A3: Open | B3: CAE-01 | D3: 3 | E3: HSS Bearing Issue | F3: Gearbox | G3: Dados de CMS apresentam indícios de danos nos rolamentos do HSS da gearbox. Recomenda-se realizar uma inspeção visual do eixo, através da janela de inspeção. | H3: 46273 | I3: SS00903 | J3: Solicitada a realização da inspeção visual em até 2 meses | K3: =IF(OR(H3="",J3=""),"",IF(ISNUMBER(SEARCH("15*dias",J3)),H3+15,IF(ISNUMBER(SEARCH("1*mês",J3)),EDATE(H3,1),IF(ISNUMBER(SEARCH("2*meses",J3)),EDATE(H3,2),"Prazo não definido")))) -> 46334 | L3: 46274 | M3: 46274 | N3: OM - 17901. OM não apresenta fotos. | O3: =IFERROR(VLOOKUP(Tabela1[[#This Row],[WTG]],Boroscopias!B:C,2,FALSE),"") | Q3: =VLOOKUP(Tabela1[[#This Row],[WTG]],Óleo!N:NA,27,FALSE) -> Anormal | R3: =VLOOKUP(Tabela1[[#This Row],[WTG]],Óleo!N:BL,51,FALSE) -> 23
A4: Monitor | B4: CAE-04 | D4: 3 | E4: HSIS DnWind Bearing Issue | F4: Gearbox | G4: Dados de CMS apresentam indícios de danos nos rolamentos do HSIS da gearbox. Recomenda-se realizar uma boroscopia com foco nos rolamentos do HSIS. | H4: 46273 | I4: SS00904 | J4: Solicitada a realização da inspeção boroscópica em até 2 meses | K4: =IF(OR(H4="",J4=""),"",IF(ISNUMBER(SEARCH("15*dias",J4)),H4+15,IF(ISNUMBER(SEARCH("1*mês",J4)),EDATE(H4,1),IF(ISNUMBER(SEARCH("2*meses",J4)),EDATE(H4,2),"Prazo não definido")))) -> 46334 | L4: 46293 | M4: 46293 | N4: Diante do exposto, recomenda-se manter o componente em monitoramento para os demais componentes e se possível a troca do HSS e seus rolamentos. | O4: =IFERROR(VLOOKUP(Tabela1[[#This Row],[WTG]],Boroscopias!B:C,2,FALSE),"") -> CAT02 | P4: https://app.safetyculture.com/report/public/audit/3ba27a2f68f2c0f03460b98d6254d316d9f65801ee9fa76bfac6261505d732f2 | Q4: =VLOOKUP(Tabela1[[#This Row],[WTG]],Óleo!N:NA,27,FALSE) -> Normal | R4: =VLOOKUP(Tabela1[[#This Row],[WTG]],Óleo!N:BL,51,FALSE) -> 51
A5: Monitor | B5: CAE-07 | D5: 3 | E5: Planetary Bearing IRBP | F5: Gearbox | G5: Dados de CMS apresentam indícios de danos nos rolamentos dos planetas do estágio planetário da gearbox. Recomenda-se realizar uma boroscopia com foco no estágio planetário. | H5: 46273 | I5: SS00905 | J5: Solicitada a realização da inspeção boroscópica em até 2 meses | K5: =IF(OR(H5="",J5=""),"",IF(ISNUMBER(SEARCH("15*dias",J5)),H5+15,IF(ISNUMBER(SEARCH("1*mês",J5)),EDATE(H5,1),IF(ISNUMBER(SEARCH("2*meses",J5)),EDATE(H5,2),"Prazo não definido")))) -> 46334 | L5: 46294 | M5: 46297 | N5: Diante do exposto, recomenda-se manter o componente em monitoramento próximo e planejamento de troca do componente em até 12 meses. | O5: =IFERROR(VLOOKUP(Tabela1[[#This Row],[WTG]],Boroscopias!B:C,2,FALSE),"") -> CAT03 | P5: https://app.safetyculture.com/report/public/audit/f8a16a681cbfcaeb0f24b00b3c9b691a529f47a4c3b6ce3938b121d869b1a83c | Q5: =VLOOKUP(Tabela1[[#This Row],[WTG]],Óleo!N:NA,27,FALSE) -> Normal | R5: =VLOOKUP(Tabela1[[#This Row],[WTG]],Óleo!N:BL,51,FALSE) -> 10
A6: Waiting report | B6: CAE-17 | D6: 3 | E6: Planetary Bearing Issue | F6: Gearbox | G6: Dados de CMS apresentam indícios de danos nos rolamentos dos planetas do estágio planetário da gearbox. Recomenda-se realizar uma boroscopia com foco no estágio planetário. | H6: 46273 | I6: SS00906 | J6: Solicitada a realização da inspeção boroscópica em até 2 meses | K6: =IF(OR(H6="",J6=""),"",IF(ISNUMBER(SEARCH("15*dias",J6)),H6+15,IF(ISNUMBER(SEARCH("1*mês",J6)),EDATE(H6,1),IF(ISNUMBER(SEARCH("2*meses",J6)),EDATE(H6,2),"Prazo não definido")))) -> 46334 | O6: =IFERROR(VLOOKUP(Tabela1[[#This Row],[WTG]],Boroscopias!B:C,2,FALSE),"") | Q6: =VLOOKUP(Tabela1[[#This Row],[WTG]],Óleo!N:NA,27,FALSE) -> Normal | R6: =VLOOKUP(Tabela1[[#This Row],[WTG]],Óleo!N:BL,51,FALSE) -> 23
A7: Waiting report | B7: SEP-10 | D7: 3 | E7: Intermediate Stage Bearing Issue | F7: Gearbox | G7: Dados de CMS apresentam indícios de danos nos rolamentos do HSIS da gearbox. Recomenda-se realizar uma boroscopia com foco nos rolamentos do HSIS. | H7: 46273 | I7: SS00907 | J7: Solicitada a realização da inspeção boroscópica em até 2 meses | K7: =IF(OR(H7="",J7=""),"",IF(ISNUMBER(SEARCH("15*dias",J7)),H7+15,IF(ISNUMBER(SEARCH("1*mês",J7)),EDATE(H7,1),IF(ISNUMBER(SEARCH("2*meses",J7)),EDATE(H7,2),"Prazo não definido")))) -> 46334 | O7: =IFERROR(VLOOKUP(Tabela1[[#This Row],[WTG]],Boroscopias!B:C,2,FALSE),"") | Q7: =VLOOKUP(Tabela1[[#This Row],[WTG]],Óleo!N:NA,27,FALSE) -> #N/A | R7: =VLOOKUP(Tabela1[[#This Row],[WTG]],Óleo!N:BL,51,FALSE) -> #N/A
A8: Cancelado | B8: CAE-05 | D8: N/A | E8: HSS Gear Issue | F8: Gearbox | G8: Dados de CMS apresentam indícios de danos no HSS da gearbox. Recomenda-se realizar uma inspeção visual do eixo, através da janela de inspeção. | H8: 46273 | I8: N/A | J8: Solicitada a realização da inspeção visual em até 2 meses | K8: =IF(OR(H8="",J8=""),"",IF(ISNUMBER(SEARCH("15*dias",J8)),H8+15,IF(ISNUMBER(SEARCH("1*mês",J8)),EDATE(H8,1),IF(ISNUMBER(SEARCH("2*meses",J8)),EDATE(H8,2),"Prazo não definido")))) -> 46334 | L8: - | M8: - | N8: HSS trocado em 14/01/2026. | O8: =IFERROR(VLOOKUP(Tabela1[[#This Row],[WTG]],Boroscopias!B:C,2,FALSE),"") | Q8: =VLOOKUP(Tabela1[[#This Row],[WTG]],Óleo!N:NA,27,FALSE) -> Normal | R8: =VLOOKUP(Tabela1[[#This Row],[WTG]],Óleo!N:BL,51,FALSE) -> 6
A9: Cancelado | B9: CAE-08 | D9: N/A | E9: Intermediate Stage Bearing Issue | F9: Gearbox | G9: Dados de CMS apresentam indícios de danos nos rolamentos do HSIS da gearbox. Recomenda-se realizar uma boroscopia com foco nos rolamentos do HSIS. | H9: 46273 | I9: N/A | J9: Solicitada a realização da inspeção boroscópica em até 2 meses | K9: =IF(OR(H9="",J9=""),"",IF(ISNUMBER(SEARCH("15*dias",J9)),H9+15,IF(ISNUMBER(SEARCH("1*mês",J9)),EDATE(H9,1),IF(ISNUMBER(SEARCH("2*meses",J9)),EDATE(H9,2),"Prazo não definido")))) -> 46334 | L9: - | M9: - | N9: Boroscopia já executada em 31/07/2026. Turbina limitada e danos principalmente no rolamento frontal do planeta 01. | O9: =IFERROR(VLOOKUP(Tabela1[[#This Row],[WTG]],Boroscopias!B:C,2,FALSE),"") -> CAT03 | Q9: =VLOOKUP(Tabela1[[#This Row],[WTG]],Óleo!N:NA,27,FALSE) -> Crítico | R9: =VLOOKUP(Tabela1[[#This Row],[WTG]],Óleo!N:BL,51,FALSE) -> 99
A10: Closed | B10: PIL-06 | D10: 2 | E10: Intermediate Stage Accelerometer Issue | F10: Gearbox | G10: Os acelerômetros do estágio intermediário estão indicando um curto-circuito; recomenda-se inspecionar a fiação e as conexões. Substitua o sensor, se necessário. | H10: 46238 | I10: SS00765 | J10: Recomenda-se inspecionar a fiação e as conexões. Substitua o sensor se necessário. | K10: =IF(OR(H10="",J10=""),"",IF(ISNUMBER(SEARCH("15*dias",J10)),H10+15,IF(ISNUMBER(SEARCH("1*mês",J10)),EDATE(H10,1),IF(ISNUMBER(SEARCH("2*meses",J10)),EDATE(H10,2),"Prazo não definido")))) -> Prazo não definido | M10: 46292 | O10: =IFERROR(VLOOKUP(Tabela1[[#This Row],[WTG]],Boroscopias!B:C,2,FALSE),"") | Q10: =VLOOKUP(Tabela1[[#This Row],[WTG]],Óleo!N:NA,27,FALSE) -> Anormal | R10: =VLOOKUP(Tabela1[[#This Row],[WTG]],Óleo!N:BL,51,FALSE) -> 15
A11: Waiting report | B11: MAR-01 | C11: - | D11: 3 | E11: Main Bearing ORBP | F11: Main Bearing | G11: Dados de CMS apresentam indícios de danos de pista externa do Main Bearing. Recomenda-se realizar uma boroscopia e uma purga de graxa. | H11: 46294 | I11: SS00959 | J11: Solicitada a realização da inspeção boroscópica em até 1 mês. | K11: =IF(OR(H11="",J11=""),"",IF(ISNUMBER(SEARCH("15*dias",J11)),H11+15,IF(ISNUMBER(SEARCH("1*mês",J11)),EDATE(H11,1),IF(ISNUMBER(SEARCH("2*meses",J11)),EDATE(H11,2),"Prazo não definido")))) -> 46324 | O11: =IFERROR(VLOOKUP(Tabela1[[#This Row],[WTG]],Boroscopias!B:C,2,FALSE),"") | Q11: =VLOOKUP(Tabela1[[#This Row],[WTG]],Óleo!N:NA,27,FALSE) -> Normal | R11: =VLOOKUP(Tabela1[[#This Row],[WTG]],Óleo!N:BL,51,FALSE) -> 15
A12: Monitor | B12: MAR-05 | D12: 4 | E12: Intermediate Stage Bearing Issue | F12: Gearbox | H12: 46294 | J12: Manter monitoramento. | K12: =IF(OR(H12="",J12=""),"",IF(ISNUMBER(SEARCH("15*dias",J12)),H12+15,IF(ISNUMBER(SEARCH("1*mês",J12)),EDATE(H12,1),IF(ISNUMBER(SEARCH("2*meses",J12)),EDATE(H12,2),"Prazo não definido")))) -> Prazo não definido | O12: =IFERROR(VLOOKUP(Tabela1[[#This Row],[WTG]],Boroscopias!B:C,2,FALSE),"") -> CAT02 | Q12: =VLOOKUP(Tabela1[[#This Row],[WTG]],Óleo!N:NA,27,FALSE) -> Normal | R12: =VLOOKUP(Tabela1[[#This Row],[WTG]],Óleo!N:BL,51,FALSE) -> 17
A13: Open | B13: MAR-06 | C13: 8/ | D13: 3 | E13: Generator Outborad Sensor Issue | F13: Generator | G13: Os acelerômetros do rolamento traseiro do gerador estão indicando um curto-circuito; recomenda-se inspecionar a fiação e as conexões. Substitua o sensor, se necessário. | H13: 46294 | I13: Pendência #04381 | J13: Recomenda-se inspecionar a fiação e as conexões. Substitua o sensor se necessário. | K13: =IF(OR(H13="",J13=""),"",IF(ISNUMBER(SEARCH("15*dias",J13)),H13+15,IF(ISNUMBER(SEARCH("1*mês",J13)),EDATE(H13,1),IF(ISNUMBER(SEARCH("2*meses",J13)),EDATE(H13,2),"Prazo não definido")))) -> Prazo não definido | O13: =IFERROR(VLOOKUP(Tabela1[[#This Row],[WTG]],Boroscopias!B:C,2,FALSE),"") | Q13: =VLOOKUP(Tabela1[[#This Row],[WTG]],Óleo!N:NA,27,FALSE) -> Normal | R13: =VLOOKUP(Tabela1[[#This Row],[WTG]],Óleo!N:BL,51,FALSE) -> 11
A14: Waiting report | B14: MAR-11 | C14: 46290 | D14: 3 | E14: Main Bearing ORBP | F14: Main Bearing | G14: Dados de CMS apresentam indícios de danos de pista externa do Main Bearing. Recomenda-se realizar uma boroscopia e uma purga de graxa. | H14: 46294 | I14: SS00958 | J14: Solicitada a realização da inspeção boroscópica em até 2 meses | K14: =IF(OR(H14="",J14=""),"",IF(ISNUMBER(SEARCH("15*dias",J14)),H14+15,IF(ISNUMBER(SEARCH("1*mês",J14)),EDATE(H14,1),IF(ISNUMBER(SEARCH("2*meses",J14)),EDATE(H14,2),"Prazo não definido")))) -> 46355 | O14: =IFERROR(VLOOKUP(Tabela1[[#This Row],[WTG]],Boroscopias!B:C,2,FALSE),"") -> CAT02 | Q14: =VLOOKUP(Tabela1[[#This Row],[WTG]],Óleo!N:NA,27,FALSE) -> Normal | R14: =VLOOKUP(Tabela1[[#This Row],[WTG]],Óleo!N:BL,51,FALSE) -> 10
A15: Monitor | B15: MAR-11 | C15: 46290 | D15: 4 | E15: Intermediate Stage Issue | F15: Gearbox | G15: Dados de CMS apresentam um aumento de energia no estágio intermediário. | H15: 46294 | J15: Manter monitoramento. | K15: =IF(OR(H15="",J15=""),"",IF(ISNUMBER(SEARCH("15*dias",J15)),H15+15,IF(ISNUMBER(SEARCH("1*mês",J15)),EDATE(H15,1),IF(ISNUMBER(SEARCH("2*meses",J15)),EDATE(H15,2),"Prazo não definido")))) -> Prazo não definido | O15: =IFERROR(VLOOKUP(Tabela1[[#This Row],[WTG]],Boroscopias!B:C,2,FALSE),"") -> CAT02 | Q15: =VLOOKUP(Tabela1[[#This Row],[WTG]],Óleo!N:NA,27,FALSE) -> Normal | R15: =VLOOKUP(Tabela1[[#This Row],[WTG]],Óleo!N:BL,51,FALSE) -> 10
A16: Open | B16: PIL-07 | C16: 46168 | D16: 3 | E16: HSS Pinion issue | F16: Gearbox | G16: Dados de CMS apresentam indícios de danos no HSS da gearbox. Recomenda-se realizar uma inspeção visual do eixo, através da janela de inspeção. | H16: 46294 | I16: SS00961 | J16: Solicitada a realização da inspeção visual em até 1 mês. | K16: =IF(OR(H16="",J16=""),"",IF(ISNUMBER(SEARCH("15*dias",J16)),H16+15,IF(ISNUMBER(SEARCH("1*mês",J16)),EDATE(H16,1),IF(ISNUMBER(SEARCH("2*meses",J16)),EDATE(H16,2),"Prazo não definido")))) -> 46324 | O16: =IFERROR(VLOOKUP(Tabela1[[#This Row],[WTG]],Boroscopias!B:C,2,FALSE),"") | Q16: =VLOOKUP(Tabela1[[#This Row],[WTG]],Óleo!N:NA,27,FALSE) -> Normal | R16: =VLOOKUP(Tabela1[[#This Row],[WTG]],Óleo!N:BL,51,FALSE) -> 25
A17: Monitor | B17: PIL-18 | C17: 46285 | D17: 4 | E17: Intermediate Stage Issue | F17: Gearbox | G17: Dados de CMS apresentam indícios de evolução gradual de energia no estágio intermediário após troca de main bearing. | H17: 46294 | J17: Manter monitoramento. | K17: =IF(OR(H17="",J17=""),"",IF(ISNUMBER(SEARCH("15*dias",J17)),H17+15,IF(ISNUMBER(SEARCH("1*mês",J17)),EDATE(H17,1),IF(ISNUMBER(SEARCH("2*meses",J17)),EDATE(H17,2),"Prazo não definido")))) -> Prazo não definido | O17: =IFERROR(VLOOKUP(Tabela1[[#This Row],[WTG]],Boroscopias!B:C,2,FALSE),"") -> CAT01 | Q17: =VLOOKUP(Tabela1[[#This Row],[WTG]],Óleo!N:NA,27,FALSE) -> Normal | R17: =VLOOKUP(Tabela1[[#This Row],[WTG]],Óleo!N:BL,51,FALSE) -> 5
A18: Open | B18: CAE-02 | C18: 46293 | D18: 3 | E18: Intermediate Stage Issue | F18: Gearbox | G18: Dados de CMS apresentam um aumento de energia no estágio intermediário. | H18: 46300 | I18: SS00976 | J18: Solicitada a realização da inspeção boroscópica em até 2 meses | K18: =IF(OR(H18="",J18=""),"",IF(ISNUMBER(SEARCH("15*dias",J18)),H18+15,IF(ISNUMBER(SEARCH("1*mês",J18)),EDATE(H18,1),IF(ISNUMBER(SEARCH("2*meses",J18)),EDATE(H18,2),"Prazo não definido")))) -> 46361 | O18: =IFERROR(VLOOKUP(Tabela1[[#This Row],[WTG]],Boroscopias!B:C,2,FALSE),"") | Q18: =VLOOKUP(Tabela1[[#This Row],[WTG]],Óleo!N:NA,27,FALSE) -> Normal | R18: =VLOOKUP(Tabela1[[#This Row],[WTG]],Óleo!N:BL,51,FALSE) -> 16
A19: Monitor | B19: CAE-03 | C19: 46283 | D19: 4 | E19: Intermediate Stage Issue | F19: Gearbox | G19: Monitoramento. Picos de energia sem tendência de alta. | H19: 46300 | J19: Manter monitoramento. | K19: =IF(OR(H19="",J19=""),"",IF(ISNUMBER(SEARCH("15*dias",J19)),H19+15,IF(ISNUMBER(SEARCH("1*mês",J19)),EDATE(H19,1),IF(ISNUMBER(SEARCH("2*meses",J19)),EDATE(H19,2),"Prazo não definido")))) -> Prazo não definido | O19: =IFERROR(VLOOKUP(Tabela1[[#This Row],[WTG]],Boroscopias!B:C,2,FALSE),"") | Q19: =VLOOKUP(Tabela1[[#This Row],[WTG]],Óleo!N:NA,27,FALSE) -> Anormal | R19: =VLOOKUP(Tabela1[[#This Row],[WTG]],Óleo!N:BL,51,FALSE) -> 26
A20: Open | B20: CAE-10 | C20: 46279 | D20: 3 | E20: HSIS DnWind Bearing Issue | F20: Gearbox | G20: Dados de CMS apresentam um aumento de energia no estágio intermediário. Com possível dano no rolamento DnWind Rear do HSIS. | H20: 46300 | I20: SS00977 | J20: Solicitada a realização da inspeção boroscópica em até 1 mês, com foco no estágio intermediário e inspeção do filtro de óleo, procurando por limalhas de ferro. | K20: =IF(OR(H20="",J20=""),"",IF(ISNUMBER(SEARCH("15*dias",J20)),H20+15,IF(ISNUMBER(SEARCH("1*mês",J20)),EDATE(H20,1),IF(ISNUMBER(SEARCH("2*meses",J20)),EDATE(H20,2),"Prazo não definido")))) -> 46331 | O20: =IFERROR(VLOOKUP(Tabela1[[#This Row],[WTG]],Boroscopias!B:C,2,FALSE),"") | Q20: =VLOOKUP(Tabela1[[#This Row],[WTG]],Óleo!N:NA,27,FALSE) -> Anormal | R20: =VLOOKUP(Tabela1[[#This Row],[WTG]],Óleo!N:BL,51,FALSE) -> 8
A21: Monitor | B21: DOU-07 | D21: 4 | E21: Planetary Bearing Issue | F21: Gearbox | G21: Monitoramento. Indicação de frequências de danos de rolamentos dos planetários. | H21: 46300 | J21: Manter monitoramento. | K21: =IF(OR(H21="",J21=""),"",IF(ISNUMBER(SEARCH("15*dias",J21)),H21+15,IF(ISNUMBER(SEARCH("1*mês",J21)),EDATE(H21,1),IF(ISNUMBER(SEARCH("2*meses",J21)),EDATE(H21,2),"Prazo não definido")))) -> Prazo não definido | O21: =IFERROR(VLOOKUP(Tabela1[[#This Row],[WTG]],Boroscopias!B:C,2,FALSE),"") | Q21: =VLOOKUP(Tabela1[[#This Row],[WTG]],Óleo!N:NA,27,FALSE) -> Normal | R21: =VLOOKUP(Tabela1[[#This Row],[WTG]],Óleo!N:BL,51,FALSE) -> 18
A22: Monitor | B22: MAR-02 | D22: 4 | E22: Intermediate Stage Issue | F22: Gearbox | G22: Monitoramento. | H22: 46300 | J22: Manter monitoramento. | K22: =IF(OR(H22="",J22=""),"",IF(ISNUMBER(SEARCH("15*dias",J22)),H22+15,IF(ISNUMBER(SEARCH("1*mês",J22)),EDATE(H22,1),IF(ISNUMBER(SEARCH("2*meses",J22)),EDATE(H22,2),"Prazo não definido")))) -> Prazo não definido | O22: =IFERROR(VLOOKUP(Tabela1[[#This Row],[WTG]],Boroscopias!B:C,2,FALSE),"") -> CAT01 | Q22: =VLOOKUP(Tabela1[[#This Row],[WTG]],Óleo!N:NA,27,FALSE) -> Normal | R22: =VLOOKUP(Tabela1[[#This Row],[WTG]],Óleo!N:BL,51,FALSE) -> 20
A23: Open | B23: BOR-08 | C23: 46253 | D23: 2 | E23: 1st Stage Accelerometer Issue | F23: Gearbox | G23: O acelerômetro do estágio planetário da gearbox está indicando um curto-circuito; recomenda-se inspecionar a fiação e as conexões. Substitua o sensor, se necessário. | H23: 46300 | I23: SS00978 | J23: O acelerômetro do estágio planetário da gearbox está indicando um curto-circuito; recomenda-se inspecionar a fiação e as conexões. Substitua o sensor, se necessário. | K23: =IF(OR(H23="",J23=""),"",IF(ISNUMBER(SEARCH("15*dias",J23)),H23+15,IF(ISNUMBER(SEARCH("1*mês",J23)),EDATE(H23,1),IF(ISNUMBER(SEARCH("2*meses",J23)),EDATE(H23,2),"Prazo não definido")))) -> Prazo não definido | O23: =IFERROR(VLOOKUP(Tabela1[[#This Row],[WTG]],Boroscopias!B:C,2,FALSE),"") | Q23: =VLOOKUP(Tabela1[[#This Row],[WTG]],Óleo!N:NA,27,FALSE) -> Normal | R23: =VLOOKUP(Tabela1[[#This Row],[WTG]],Óleo!N:BL,51,FALSE) -> 25
A24: Open | B24: PEL-02 | C24: 46284 | D24: 3 | E24: Intermediate Stage Issue | F24: Gearbox | G24: Dados de CMS indicam um aumento de energia globa em variável no estágio intermediário, com possíveis danos no rolamento DnWind rear do HSIS. | H24: 46300 | I24: SS00979 | J24: Solicitada a realização da inspeção boroscópica em até 2 meses | K24: =IF(OR(H24="",J24=""),"",IF(ISNUMBER(SEARCH("15*dias",J24)),H24+15,IF(ISNUMBER(SEARCH("1*mês",J24)),EDATE(H24,1),IF(ISNUMBER(SEARCH("2*meses",J24)),EDATE(H24,2),"Prazo não definido")))) -> 46361 | O24: =IFERROR(VLOOKUP(Tabela1[[#This Row],[WTG]],Boroscopias!B:C,2,FALSE),"") | Q24: =VLOOKUP(Tabela1[[#This Row],[WTG]],Óleo!N:NA,27,FALSE) -> Anormal | R24: =VLOOKUP(Tabela1[[#This Row],[WTG]],Óleo!N:BL,51,FALSE) -> 118
A25: Open | B25: PEL-05 | D25: 3 | E25: Main Bearing ORBP | F25: Main Bearing | G25: Dados de CMS apresentam indícios de danos de pista externa do Main Bearing. Recomenda-se realizar uma boroscopia e uma purga de graxa. | H25: 46300 | I25: SS00989 | J25: Solicitada a realização da inspeção boroscópica em até 2 meses | K25: =IF(OR(H25="",J25=""),"",IF(ISNUMBER(SEARCH("15*dias",J25)),H25+15,IF(ISNUMBER(SEARCH("1*mês",J25)),EDATE(H25,1),IF(ISNUMBER(SEARCH("2*meses",J25)),EDATE(H25,2),"Prazo não definido")))) -> 46361 | O25: =IFERROR(VLOOKUP(Tabela1[[#This Row],[WTG]],Boroscopias!B:C,2,FALSE),"") | Q25: =VLOOKUP(Tabela1[[#This Row],[WTG]],Óleo!N:NA,27,FALSE) -> Normal | R25: =VLOOKUP(Tabela1[[#This Row],[WTG]],Óleo!N:BL,51,FALSE) -> 16
A26: Monitor | B26: PEL-12 | D26: 4 | E26: LSIS Issue | F26: Gearbox | H26: 46300 | J26: Manter monitoramento. | K26: =IF(OR(H26="",J26=""),"",IF(ISNUMBER(SEARCH("15*dias",J26)),H26+15,IF(ISNUMBER(SEARCH("1*mês",J26)),EDATE(H26,1),IF(ISNUMBER(SEARCH("2*meses",J26)),EDATE(H26,2),"Prazo não definido")))) -> Prazo não definido | N26: Monitoramento. | O26: =IFERROR(VLOOKUP(Tabela1[[#This Row],[WTG]],Boroscopias!B:C,2,FALSE),"") | Q26: =VLOOKUP(Tabela1[[#This Row],[WTG]],Óleo!N:NA,27,FALSE) -> Normal | R26: =VLOOKUP(Tabela1[[#This Row],[WTG]],Óleo!N:BL,51,FALSE) -> 18
A27: Open | B27: PEL-13 | D27: 3 | E27: Planetary Bearing Issue | F27: Gearbox | G27: Dados de CMS indicam possíveis danos nos rolamentos do estágio planetário. | H27: 46300 | I27: SS00990 | J27: Solicitada a realização da inspeção boroscópica em até 2 meses | K27: =IF(OR(H27="",J27=""),"",IF(ISNUMBER(SEARCH("15*dias",J27)),H27+15,IF(ISNUMBER(SEARCH("1*mês",J27)),EDATE(H27,1),IF(ISNUMBER(SEARCH("2*meses",J27)),EDATE(H27,2),"Prazo não definido")))) -> 46361 | O27: =IFERROR(VLOOKUP(Tabela1[[#This Row],[WTG]],Boroscopias!B:C,2,FALSE),"") | Q27: =VLOOKUP(Tabela1[[#This Row],[WTG]],Óleo!N:NA,27,FALSE) -> Normal | R27: =VLOOKUP(Tabela1[[#This Row],[WTG]],Óleo!N:BL,51,FALSE) -> 37

Sheet Consulta Óleo
A1: PAINEL DE ANÁLISES DE ÓLEO | X1: Todos | Y1: Todos
X2: Alto Sertão II | Y2: Anormal
A3: Consulta rápida por complexo e condição da amostra | X3: Asa Branca | Y3: Atenção
X4: Caetés | Y4: Crítico
A5: COMPLEXO | D5: STATUS DA AMOSTRA | G5: REGISTROS ENCONTRADOS | J5: Atualize a microfiltragem na base Óleo (colunas BJI e BJJ) | X5: Chapada | Y5: Normal
A6: Todos | D6: Crítico | G6: =IF(A11="Nenhum registro encontrado",0,IFERROR(ROWS(_xlfn.ANCHORARRAY(A11)),0)) -> 518 | X6: Não mapeado
A9: RESULTADOS DA CONSULTA
A10: Data de coleta | B10: Tag / frota | C10: Compartimento | D10: Obra / unidade | E10: Complexo | F10: Status da amostra | G10: Avaliação | H10: Ações de inspeção | I10: Ferro (ppm) | J10: Realizada Microfiltragem | K10: Data da Microfiltragem
A11: {=_xlfn.LET(_xlpm.dt,Óleo!E2:E2113,_xlpm.tag,Óleo!N2:N2113,_xlpm.cp,Óleo!R2:R2113,_xlpm.ob,Óleo!AK2:AK2113,_xlpm.ss,Óleo!AN2:AN2113,_xlpm.av,Óleo!AO2:AO2113,_xlpm.ac,Óleo!AQ2:AQ2113,_xlpm.fe,Óleo!BL2:BL2113,_xlpm.mf,Óleo!BJI2:BJI2113,_xlpm.dm,Óleo!BJJ2:BJJ2113,_xlpm.cx,IF(ISNUMBER(SEARCH("CAETÉS",_xlpm.ob)),"Caetés",IF(LEFT(_xlpm.ob,10)="Asa Branca","Asa Branca",IF(((LEFT(_xlpm.ob,11)="Santa Joana")+(LEFT(_xlpm.ob,13)="Santo Augusto")+ISNUMBER(SEARCH("MARCOLANDIA",_xlpm.ob)))>0,"Chapada",IF(ISNUMBER(_xlfn.XMATCH(_xlpm.ob,{"Ametista","Borgo","Caetité","Dourados","Espigão","Maron","Pelourinho","Pilões","Serra do Espinhaço"})),"Alto Sertão II","Não mapeado")))),_xlpm.c,$A$6,_xlpm.st,$D$6,_xlpm.out,_xlfn.HSTACK(_xlpm.dt,IF(_xlpm.tag="","",_xlpm.tag),IF(_xlpm.cp="","",_xlpm.cp),IF(_xlpm.ob="","",_xlpm.ob),_xlpm.cx,IF(_xlpm.ss="","",_xlpm.ss),IF(_xlpm.av="","",_xlpm.av),IF(_xlpm.ac="","",_xlpm.ac),_xlpm.fe,IF(_xlpm.mf="","",_xlpm.mf),IF(_xlpm.dm="","",_xlpm.dm)),_xlfn._xlws.FILTER(_xlpm.out,((_xlpm.c="Todos")+(_xlpm.cx=_xlpm.c)>0)*((_xlpm.st="Todos")+(_xlpm.ss=_xlpm.st)>0),"Nenhum registro encontrado"))} -> 13/08/2026 | B11: JOA12-13 | C11: Gearbox | D11: Santa Joana XII | E11: Chapada | F11: Crítico | G11: Condição do Lubrificante: A amostra apresenta grande quantidade de partículas sólidas em suspensão não identificados como metais de desgaste sendo assim podem ser oriundas de fibras, resíduos de filtros e derivados do processo. Condição do equipamento: Não há indícios de desgaste. [Diagnóstico Realizado de acordo com o Parâmetro do Cliente] | H11: Recomendamos que seja efetuada a micro filtragem para redução dos contaminantes sólidos, verificar condição dos filtros, problemas relacionados a vedações, entrada de contaminantes e sempre efetuar a transferência através de filtragem. | I11: 42
A12: 30/07/2026 | B12: JOA16-09 | C12: Gearbox | D12: Santa Joana XVI | E12: Chapada | F12: Crítico | G12: Condição do Lubrificante: A amostra apresenta partículas sólidas em suspensão de diversas fontes. Condição do equipamento: Apresenta moderada concentração de Ferro, a qual indica desgaste nos componentes. [Diagnóstico Realizado de acordo com o Parâmetro do Cliente] | H12: Recomendamos que seja efetuada a micro filtragem para redução dos contaminantes sólidos, verificar condição dos filtros, problemas relacionados a vedações, entrada de contaminantes e sempre efetuar a transferência através de filtragem. Avaliar as condições dos componentes. Efetuar nova coleta após 30 dias para acompanhamento. | I12: 54
A13: 30/07/2026 | B13: JOA12-01 | C13: Gearbox | D13: Santa Joana XII | E13: Chapada | F13: Crítico | G13: Condição do Lubrificante: A amostra apresenta grande quantidade de partículas sólidas em suspensão não identificados como metais de desgaste sendo assim podem ser oriundas de fibras, resíduos de filtros e derivados do processo. Condição do equipamento: Não há indícios de desgaste. [Diagnóstico Realizado de acordo com o Parâmetro do Cliente] | H13: Recomendamos que seja efetuada a micro filtragem para redução dos contaminantes sólidos, verificar condição dos filtros, problemas relacionados a vedações, entrada de contaminantes e sempre efetuar a transferência através de filtragem. | I13: 27
A14: 13/08/2026 | B14: JOA10-04 | C14: Gearbox | D14: Santa Joana X | E14: Chapada | F14: Crítico | G14: Condição do Lubrificante: A amostra apresenta grande quantidade de partículas sólidas em suspensão não identificados como metais de desgaste sendo assim podem ser oriundas de fibras, resíduos de filtros e derivados do processo. Condição do equipamento: Não há indícios de desgaste. [Diagnóstico Realizado de acordo com o Parâmetro do Cliente] | H14: Recomendamos que seja efetuada a micro filtragem para redução dos contaminantes sólidos, verificar condição dos filtros, problemas relacionados a vedações, entrada de contaminantes e sempre efetuar a transferência através de filtragem. | I14: 33
A15: 17/08/2026 | B15: JOA10-01 | C15: Gearbox | D15: Santa Joana X | E15: Chapada | F15: Crítico | G15: Condição do Lubrificante: A amostra apresenta grande quantidade de partículas sólidas em suspensão não identificados como metais de desgaste sendo assim podem ser oriundas de fibras, resíduos de filtros e derivados do processo. Condição do equipamento: Não há indícios de desgaste. [Diagnóstico Realizado de acordo com o Parâmetro do Cliente] | H15: Recomendamos que seja efetuada a micro filtragem para redução dos contaminantes sólidos, verificar condição dos filtros, problemas relacionados a vedações, entrada de contaminantes e sempre efetuar a transferência através de filtragem. | I15: 15
A16: 10/08/2026 | B16: AUG03-04 | C16: Gearbox | D16: Santo Augusto III | E16: Chapada | F16: Crítico | G16: Condição do Lubrificante: A amostra apresenta grande quantidade de partículas sólidas de diversas fontes. Condição do equipamento: Apresenta moderada concentração de Ferro a qual indica um desgaste nos componentes. [Diagnóstico Realizado de acordo com o Parâmetro do Cliente] | H16: Recomendamos que seja efetuada a micro filtragem para redução dos contaminantes sólidos, verificar condição dos filtros, problemas relacionados a vedações, entrada de contaminantes e sempre efetuar a transferência através de filtragem. Efetuar nova coleta após 15 dias para acompanhamento. | I16: 54
A17: 06/08/2026 | B17: JOA16-08 | C17: Gearbox | D17: Santa Joana XVI | E17: Chapada | F17: Crítico | G17: Condição do Lubrificante: A amostra apresenta grande quantidade de partículas sólidas em suspensão não identificados como metais de desgaste sendo assim podem ser oriundas de fibras, resíduos de filtros e derivados do processo. Condição do equipamento: Não há indícios de desgaste. [Diagnóstico Realizado de acordo com o Parâmetro do Cliente] | H17: Recomendamos que seja efetuada a micro filtragem para redução dos contaminantes sólidos, verificar condição dos filtros, problemas relacionados a vedações, entrada de contaminantes e sempre efetuar a transferência através de filtragem. | I17: 38
A18: 13/08/2026 | B18: JOA11-01 | C18: Gearbox | D18: Santa Joana XI | E18: Chapada | F18: Crítico | G18: Condição do Lubrificante: A amostra apresenta grande quantidade de partículas sólidas em suspensão não identificados como metais de desgaste sendo assim podem ser oriundas de fibras, resíduos de filtros e derivados do processo. Condição do equipamento: Não há indícios de desgaste. [Diagnóstico Realizado de acordo com o Parâmetro do Cliente] | H18: Recomendamos que seja efetuada a micro filtragem para redução dos contaminantes sólidos, verificar condição dos filtros, problemas relacionados a vedações, entrada de contaminantes e sempre efetuar a transferência através de filtragem. | I18: 35
A19: 28/07/2026 | B19: JOA11-01 | C19: Gearbox | D19: Santa Joana XI | E19: Chapada | F19: Crítico | G19: Condição do Lubrificante: A amostra apresenta grande quantidade de partículas sólidas em suspensão não identificados como metais de desgaste sendo assim podem ser oriundas de fibras, resíduos de filtros e derivados do processo. Condição do equipamento: Não há indícios de desgaste. [Diagnóstico Realizado de acordo com o Parâmetro do Cliente] | H19: Recomendamos que seja efetuada a micro filtragem para redução dos contaminantes sólidos, verificar condição dos filtros, problemas relacionados a vedações, entrada de contaminantes e sempre efetuar a transferência através de filtragem. | I19: 24
A20: 06/08/2026 | B20: JOA03-04 | C20: Gearbox | D20: Santa Joana III | E20: Chapada | F20: Crítico | G20: Condição do Lubrificante: A amostra apresenta grande quantidade de partículas sólidas de diversas fontes. Condição do equipamento: Apresenta moderada concentração de Ferro a qual indica um desgaste nos componentes. [Diagnóstico Realizado de acordo com o Parâmetro do Cliente] | H20: Recomendamos que seja efetuada a micro filtragem para redução dos contaminantes sólidos, verificar condição dos filtros, problemas relacionados a vedações, entrada de contaminantes e sempre efetuar a transferência através de filtragem. Efetuar nova coleta após 15 dias para acompanhamento. | I20: 65
A21: 06/08/2026 | B21: JOA01-14 | C21: Gearbox | D21: Santa Joana I | E21: Chapada | F21: Crítico | G21: Condição do Lubrificante: A amostra apresenta grande quantidade de partículas sólidas em suspensão não identificados como metais de desgaste sendo assim podem ser oriundas de fibras, resíduos de filtros e derivados do processo. Condição do equipamento: Não há indícios de desgaste. [Diagnóstico Realizado de acordo com o Parâmetro do Cliente] | H21: Recomendamos que seja efetuada a micro filtragem para redução dos contaminantes sólidos, verificar condição dos filtros, problemas relacionados a vedações, entrada de contaminantes e sempre efetuar a transferência através de filtragem. | I21: 37
A22: 13/08/2026 | B22: AUG05-11 | C22: Gearbox | D22: Santo Augusto V | E22: Chapada | F22: Crítico | G22: Condição do Lubrificante: A amostra apresenta grande quantidade de partículas sólidas de diversas fontes. Condição do equipamento: Apresenta moderada concentração de Ferro a qual indica um desgaste nos componentes. [Diagnóstico Realizado de acordo com o Parâmetro do Cliente] | H22: Recomendamos que seja efetuada a micro filtragem para redução dos contaminantes sólidos, verificar condição dos filtros, problemas relacionados a vedações, entrada de contaminantes e sempre efetuar a transferência através de filtragem. Efetuar nova coleta após 15 dias para acompanhamento. | I22: 76
A23: 29/07/2026 | B23: AUG04-02 | C23: Gearbox | D23: Santo Augusto IV | E23: Chapada | F23: Crítico | G23: Condição do Lubrificante: A amostra apresenta grande quantidade de partículas sólidas de diversas fontes. Condição do equipamento: Apresenta moderada concentração de Ferro a qual indica um desgaste nos componentes. [Diagnóstico Realizado de acordo com o Parâmetro do Cliente] | H23: Recomendamos que seja efetuada a micro filtragem para redução dos contaminantes sólidos, verificar condição dos filtros, problemas relacionados a vedações, entrada de contaminantes e sempre efetuar a transferência através de filtragem. Efetuar nova coleta após 15 dias para acompanhamento. | I23: 60
... A121: 11/04/2025 | B121: JOA01-14 | C121: Gearbox | D121: Santa Joana I | E121: Chapada | F121: Crítico | G121: Condição do Lubrificante: A amostra apresenta grande quantidade de partículas sólidas em suspensão não identificados como metais de desgaste sendo assim podem ser oriundas de fibras, resíduos de filtros e derivados do processo. Condição do equipamento: Não há indícios de desgaste. | H121: Recomendamos que seja efetuada a micro filtragem para redução dos contaminantes sólidos, verificar condição dos filtros, problemas relacionados a vedações, entrada de contaminantes e sempre efetuar a transferência através de filtragem. Informar o tipo de óleo utilizado. | I121: 1
A122: 0 | B122: JOA11-13 | C122: Gearbox | D122: Santa Joana XI | E122: Chapada | F122: Crítico | G122: Condição do Lubrificante: A amostra apresenta grande quantidade de partículas sólidas em suspensão não identificados como metais de desgaste sendo assim podem ser oriundas de fibras, resíduos de filtros e derivados do processo. Condição do equipamento: Não há indícios de desgaste. | H122: Recomendamos que seja efetuada a micro filtragem para redução dos contaminantes sólidos, verificar condição dos filtros, problemas relacionados a vedações, entrada de contaminantes e sempre efetuar a transferência através de filtragem. Informar o tipo de óleo utilizado. | I122: 8
A123: 14/02/2025 | B123: JOA12-13 | C123: Gearbox | D123: Santa Joana XII | E123: Chapada | F123: Crítico | G123: Condição do Lubrificante: A amostra apresenta partículas sólidas em suspensão de diversas fontes. Condição do equipamento: Apresenta moderada concentração de Ferro, a qual indica desgaste nos componentes. | H123: Recomendamos que seja efetuada a micro filtragem para redução dos contaminantes sólidos, verificar condição dos filtros, problemas relacionados a vedações, entrada de contaminantes e sempre efetuar a transferência através de filtragem. Efetuar nova coleta após 30 dias para acompanhamento. Informar o tipo de óleo utilizado. | I123: 103
A124: 27/02/2025 | B124: JOA04-05 | C124: Gearbox | D124: Santa Joana IV | E124: Chapada | F124: Crítico | G124: Condição do Lubrificante: A amostra apresenta grande quantidade de partículas sólidas em suspensão não identificados como metais de desgaste sendo assim podem ser oriundas de fibras, resíduos de filtros e derivados do processo. Condição do equipamento: Não há indícios de desgaste. | H124: Recomendamos que seja efetuada a micro filtragem para redução dos contaminantes sólidos, verificar condição dos filtros, problemas relacionados a vedações, entrada de contaminantes e sempre efetuar a transferência através de filtragem. | I124: 39
