Workbook

Sheet CMS Sweeps
A1: Site: | B1: Owner | C1: Turbines | D1: MB Sweep | E1: Next MB Sweep | F1: S1 Sweep | G1: Next S1 Sweep | H1: S2 Sweep | I1: Next S2 Sweep | J1: S3 Sweep | K1: Next S3 Sweep | L1: Last Login | M1: Notes: | O1: Component: | P1: Frequency (Days):
A2: Asa Branca | B2: ESSEN | D2: 45992 | E2: =Table11[[#This Row],[MB Sweep]]+90 -> 46082 | F2: 46028 | G2: =Table11[[#This Row],[S1 Sweep]]+90 -> 46118 | H2: 45867 | I2: =Table11[[#This Row],[S2 Sweep]]+180 -> 46047 | K2: =Table11[[#This Row],[S2 Sweep]]+180 -> 46047 | L2: 46283 | O2: ZF S1+S2 | P2: 30
A3: Beech Ridge II | B3: A | C3: 20 | D3: 46233 | E3: =Table11[[#This Row],[MB Sweep]]+60 -> 46293 | F3: 46223 | G3: =Table11[[#This Row],[S1 Sweep]]+90 -> 46313 | H3: 46262 | I3: =Table11[[#This Row],[S2 Sweep]]+120 -> 46382 | J3: 46287 | K3: =Table11[[#This Row],[S3 Sweep]]+180 -> 46467 | L3: 46287 | O3: 1st Planetary Stage | P3: 90
A4: Bethel | B4: A | C4: 120 | D4: 46143 | E4: =Table11[[#This Row],[MB Sweep]]+60 -> 46203 | F4: 45902 | G4: =Table11[[#This Row],[S1 Sweep]]+90 -> 45992 | H4: 45873 | I4: =Table11[[#This Row],[S2 Sweep]]+120 -> 45993 | J4: 45859 | K4: =Table11[[#This Row],[S3 Sweep]]+180 -> 46039 | L4: 46287 | O4: 2nd Planetary Stage | P4: 120
A5: Bishop Hill III | B5: WEC | C5: 53 | D5: 45873 | F5: 45876 | H5: 45887 | J5: 45890 | L5: 45915 | O5: High Speed Stage | P5: 180
A6: Blooming Grove | B6: WEC | C6: 94 | D6: 45873 | F6: 45876 | H6: 45887 | J6: 45890 | L6: 45915 | O6: SKF + Timken MBs | P6: 7
A7: Chapada I | B7: ESSEN | E7: =Table11[[#This Row],[MB Sweep]]+90 -> 90 | F7: 45867 | G7: =Table11[[#This Row],[S1 Sweep]]+90 -> 45957 | I7: =Table11[[#This Row],[S2 Sweep]]+180 -> 180 | K7: =Table11[[#This Row],[S2 Sweep]]+180 -> 180 | L7: 46283 | O7: MB | P7: Varies
A8: Chapada II+III | B8: ESSEN | E8: =Table11[[#This Row],[MB Sweep]]+90 -> 90 | G8: =Table11[[#This Row],[S1 Sweep]]+90 -> 90 | I8: =Table11[[#This Row],[S2 Sweep]]+180 -> 180 | K8: =Table11[[#This Row],[S2 Sweep]]+180 -> 180 | L8: 46251 | O8: CMS Server Login | P8: 3
A9: Chickasaw | B9: A | C9: 58 | L9: 46276
A10: Coyote | B10: WEC | C10: 39 | D10: 45873 | F10: 45870 | H10: 45887 | J10: 45891 | L10: 45915
A11: Deuel Harvest | B11: A | C11: 109 | D11: 46188 | E11: =Table11[[#This Row],[MB Sweep]]+30 -> 46218 | F11: 46223 | G11: =Table11[[#This Row],[S1 Sweep]]+90 -> 46313 | H11: 46287 | I11: =Table11[[#This Row],[S2 Sweep]]+120 -> 46407 | J11: 46192 | K11: =Table11[[#This Row],[S3 Sweep]]+180 -> 46372 | L11: 46287
A12: Diversion | B12: AEP | C12: 59 | L12: 46276
A13: Gordon Butte | B13: A | C13: 9 | D13: 46233 | E13: =Table11[[#This Row],[MB Sweep]]+30 -> 46263 | F13: 46223 | G13: =Table11[[#This Row],[S1 Sweep]]+90 -> 46313 | H13: 46287 | I13: =Table11[[#This Row],[S2 Sweep]]+120 -> 46407 | J13: 46209 | K13: =Table11[[#This Row],[S3 Sweep]]+180 -> 46389 | L13: 46287
A14: Jayhawk | B14: WEC | C14: 70 | D14: 45873 | F14: 45876 | H14: 45887 | J14: 45891 | L14: 45915
A15: Number Three (GE) | B15: WEC | C15: 5 | D15: 46265 | E15: =Table11[[#This Row],[MB Sweep]]+30 -> 46295 | F15: 46237 | G15: =Table11[[#This Row],[S1 Sweep]]+90 -> 46327 | H15: 46287 | I15: =Table11[[#This Row],[S2 Sweep]]+120 -> 46407 | J15: 46251 | K15: =Table11[[#This Row],[S3 Sweep]]+180 -> 46431 | L15: 46287
A16: Plymouth | B16: A | C16: 73 | L16: 46287
A17: Red Barn | B17: WEC | C17: 28 | L17: 46287
A18: Rock Creek | B18: A | C18: 32 | L18: 46276
A19: Santa Rita East | B19: A | C19: ` | D19: 45982 | F19: 45992 | I19: 45992 | K19: 45992 | L19: 46020
A20: Tatanka | B20: WEC | C20: 56 | D20: 45874 | F20: 45877 | H20: 45887 | J20: 45891 | L20: 45915
A21: Thunderhead | B21: WEC | C21: 108 | D21: 45874 | F21: 45877 | H21: 45887 | J21: 45891 | L21: 45915
A22: Upstream | B22: WEC | C22: 82 | D22: 45874 | F22: 45877 | H22: 45887 | J22: 45891 | L22: 45915
O1014: 3041238

Sheet Events
A1: Site | B1: Case Status | C1: WTG | D1: Case Title | E1: Event | F1: Location | G1: Event Date | H1: Follow Up Date | I1: Priority | J1: Disposition | K1: Action | L1: WO Tracking2 | M1: EAM WO Status | N1: WO Status | O1: Estimated Replacement Date: | P1: Date Resolved | Q1: Notes | R1: Notes Archive | S1: Case outcome | T1: Detection Time:
A2: Bethel | B2: Resolved | C2: 1 | D2: Gen Bearing Damage | E2: Alarm | F2: Generator Outboard | G2: 45033 | I2: 3 | J2: Add grease to both gen bearings, increasing trend | K2: Monitor | L2: 3113598 | M2: =_xlfn.IFNA(VLOOKUP(L2,ALL_CMS_WOs!C$1:F$6984,4,FALSE),"") -> Closed | N2: Closed | P2: 45177 | S2: Defect Confirmed - Repair Complete | T2: =Events[[#This Row],[Date Resolved]]-Events[[#This Row],[Event Date]] -> 144
A3: Plymouth | B3: Resolved | C3: 1 | D3: Keyphasor Issue | E3: Instrumentation | F3: Keyphasor | G3: 45026 | I3: 3 | J3: Please inspect keyphasor system using attached guide. Reach out to abarndt@invenergy.com for support. | K3: CMSTRBLSHOOT | L3: 3110510 | M3: =_xlfn.IFNA(VLOOKUP(L3,ALL_CMS_WOs!C$1:F$6984,4,FALSE),"") -> Closed | N3: Closed | P3: 45115 | S3: Defect Confirmed - Repair Complete | T3: =Events[[#This Row],[Date Resolved]]-Events[[#This Row],[Event Date]] -> 89
A4: Plymouth | B4: Active | C4: 1 | D4: Timken Main Bearing BS2X Issue | E4: Warning | F4: Main Bearing | G4: 45545 | I4: 2 | J4: 9/26/24 - Turbine derated to 50%. 9/10/24 - Recommend borescoping this main bearing within 2 weeks from 9/10/24 with focus on outer race and rollers. | K4: Repair Pending | L4: 3420487 | M4: =_xlfn.IFNA(VLOOKUP(L4,ALL_CMS_WOs!C$1:F$6984,4,FALSE),"") -> Closed | N4: Closed | S4: Defect Confirmed - Awaiting Repair | T4: =Events[[#This Row],[Date Resolved]]-Events[[#This Row],[Event Date]] -> -45545
A5: Plymouth | B5: Resolved | C5: 1 | E5: Instrumentation | F5: CMS Monitor | G5: 44715 | J5: Replace 60M100 monitor | K5: CMSTRBLSHOOT | L5: 2941638 | M5: =_xlfn.IFNA(VLOOKUP(L5,ALL_CMS_WOs!C$1:F$6984,4,FALSE),"") -> Cancelled | N5: Cancelled | P5: 44802 | Q5: 8/29 - do not replace monitor if 319 event left state | T5: =Events[[#This Row],[Date Resolved]]-Events[[#This Row],[Event Date]] -> 87
A6: Santa Rita East | B6: Resolved | C6: 1 | E6: Particle Count | F6: 1st Planetary Stage | G6: 44636 | I6: 5 | K6: Particle Counter | M6: =_xlfn.IFNA(VLOOKUP(L6,ALL_CMS_WOs!C$1:F$6984,4,FALSE),"") | Q6: 3/16 - looking back at particle counter data shows rapid increase in non-ferrous debris July-October 2021, plateaued since. No notable signs of gearbox damage in CMS, potential oil contamination or housing damage? Monitor for signs of damage in CMS, 4/4 - non ferrous counts continue to increase, 6/3 - no smoking gun in CMS, Stage 3 FFT shows pinion fault sidebands, no progression, 8/8 - non ferrous debris counts continue to increase, gearbox borescoped 5/20/22 with no damage found, monitor for continued debris generation, 11/3 - reduce to cat 1, limited debris generation | S6: Case In Progress | T6: =Events[[#This Row],[Date Resolved]]-Events[[#This Row],[Event Date]] -> -44636
A7: Santa Rita East | B7: Resolved | C7: 1 | E7: Alarm | F7: Generator Inboard | G7: 44565 | I7: 6 | K7: Monitor | M7: =_xlfn.IFNA(VLOOKUP(L7,ALL_CMS_WOs!C$1:F$6984,4,FALSE),"") | Q7: 1/12 - Sudden spike to alarm thresholds on 1/4, return to apparently normal operation. CMS Gen Bearing check if alarm is hit again. Monitor for failure 1/31 - signal has reduced to below alarm levels, FFT shows signs of damage to both inner and outer races, 4/25 - reduce to cat 2, 6/3 - no progression, 9/19 - recent progression, 11/3 - limited progression, reduce to cat 1 | S7: Case In Progress | T7: =Events[[#This Row],[Date Resolved]]-Events[[#This Row],[Event Date]] -> -44565
A8: Maverick | B8: Active | C8: 1 | D8: Potential Main Bearing Issue | E8: Sweep | F8: Main Bearing | G8: 45202 | I8: 1 | J8: 2/22/24 - Turbine to be DNR'd and reborescoped before repair. 1/9/24 - Derated to 60%. 10/27/24 - Derated to 50%. 10/6/23 - Borescope found excessive damage found on rolling elements and aggressive wear seen on cage fingers. 10/2/23 - Recommend thrust derating and performing a borescope of the main bearing at the next possible opportunity. | K8: Final Report Needed | L8: 3303924 | M8: =_xlfn.IFNA(VLOOKUP(L8,ALL_CMS_WOs!C$1:F$6984,4,FALSE),"") -> Closed | N8: Closed | S8: Defect Confirmed - Awaiting Repair | T8: =Events[[#This Row],[Date Resolved]]-Events[[#This Row],[Event Date]] -> -45202
A9: Upstream | B9: Active | C9: 1 | D9: S1 PS BRG Damage | E9: Warning | F9: 1st Planetary Stage | G9: 44542 | I9: 1 | J9: CMS indicated damage to S1 Planetary. Continue to monitor via CMS and particle counter | K9: Longterm Watchlist | L9: 2928225 | M9: =_xlfn.IFNA(VLOOKUP(L9,ALL_CMS_WOs!C$1:F$6984,4,FALSE),"") -> Closed | N9: Closed | O9: Q4 2024 | Q9: 6/17 - borescope found corrosion and micropitting on S1 PS BRG RS, indents on S1 PC BRGs, projected failure Q1/Q2 2023, planning to move particle counter from 16 to 1 after 16 is replaced, CMS indicates damage to stage 2 as well, 7/5 - additional Ring Fault alarm on 6/26, indicating progression, waiting on particle counter install, 9/6 - particle counter installed, 0-100 micron debris generation, monitor larger bins, 9/29 - S1 Direct now below the warning setpoint, 10/19 - 43mg debris detected, limited progression, 12/19 - 69mg detected, 1/10 - progression has slowed, | R9: 12/29 - potential issue with stage 1 carrier bearing, monitor, 3/25 - progression in stage 1 direct, FFT shows GS carrier faults, 4/6 - Nanjing retro, monitor for progression, 5/5 - progression continues, FFT shows strong 3X harmonics throughout the spectrum, indicating damage to stage 1 carriers and ring gear, | S9: Defect Confirmed - Awaiting Repair | T9: =Events[[#This Row],[Date Resolved]]-Events[[#This Row],[Event Date]] -> -44542
A10: Sundance | B10: Resolved | C10: 2 | D10: IONet Issue | E10: Instrumentation | F10: CMS Monitor | G10: 45132 | I10: 5 | J10: ​CMS monitor not receiving power signal, please perform toolbox download to CBM card. Contact abarndt@invenergy.com for support. | K10: CMSTRBLSHOOT | L10: 3161674 | M10: =_xlfn.IFNA(VLOOKUP(L10,ALL_CMS_WOs!C$1:F$6984,4,FALSE),"") -> Closed | N10: Closed | P10: 45169 | S10: Defect Confirmed - Repair Complete | T10: =Events[[#This Row],[Date Resolved]]-Events[[#This Row],[Event Date]] -> 37
A11: Bethel | B11: Resolved | C11: 2 | E11: Alarm | F11: Helical High Speed Stage | G11: 44558 | I11: 3 | K11: Borescope | L11: Create WO | M11: =_xlfn.IFNA(VLOOKUP(L11,ALL_CMS_WOs!C$1:F$6984,4,FALSE),"") | N11: #N/A | P11: 44951 | Q11: 1/31 - stage 3 direct peaked above the alarm setpoint in early January, FFT shows peak at HSS DnWind Rear ORBP, recommending Borescope inspection focusing on HSS DnWind Rear bearing | S11: Case In Progress | T11: =Events[[#This Row],[Date Resolved]]-Events[[#This Row],[Event Date]] -> 393
A12: Upstream | B12: Resolved | C12: 2 | E12: Instrumentation | F12: Generator Outboard | G12: 44664 | J12: Verify power supply and reboot | K12: CMSTRBLSHOOT | L12: 2920032 | M12: =_xlfn.IFNA(VLOOKUP(L12,ALL_CMS_WOs!C$1:F$6984,4,FALSE),"") -> Closed | N12: Closed | P12: 44818 | R12: 7/5 - bad harness from sensor to TT OL, Dan is working on it? | T12: =Events[[#This Row],[Date Resolved]]-Events[[#This Row],[Event Date]] -> 154
A13: Bethel | B13: Resolved | C13: 2 | D13: HSS Bearing Damage | E13: Case Tracking | F13: Helical High Speed Stage | G13: 44952 | I13: 3 | J13: Check HSS bearing for damage | K13: CMSHSS | M13: =_xlfn.IFNA(VLOOKUP(L13,ALL_CMS_WOs!C$1:F$6984,4,FALSE),"") | S13: Case In Progress | T13: =Events[[#This Row],[Date Resolved]]-Events[[#This Row],[Event Date]] -> -44952
A14: Plymouth | B14: Resolved | C14: 2 | D14: 1st Planetary Stage Accelerometer Issue | E14: Instrumentation | F14: 1st Planetary Stage | G14: 45481 | I14: 4 | J14: 7/8/24 - Please investigate 1st planetary stage sensor wiring and connections, replace sensor if needed. | K14: CMSTRBLSHOOT | L14: 3380402 | M14: =_xlfn.IFNA(VLOOKUP(L14,ALL_CMS_WOs!C$1:F$6984,4,FALSE),"") -> Closed | N14: Ready to Schedule | P14: 45489 | S14: Defect Confirmed - Repair Complete | T14: =Events[[#This Row],[Date Resolved]]-Events[[#This Row],[Event Date]] -> 8
A15: Deuel Harvest | B15: Active | C15: 2 | D15: Main Bearing BS2X, Rolling Element Issue | E15: Sweep | F15: Main Bearing | G15: 45406 | I15: 2 | J15: 5/28/24 - Borescope shows moderate amount of indentstions with DLC delamination to the rollers. Main bearing can continue to operste as scope does not show evidence of imminent failure, and grease shows minmal wear metal, added to weekly monitoring. 4/24/24 - CMS indicates damage to rolling elements. Please perform main bearing borescope/inspection, take a grease sample, check vibration/sensors are tightly mounted. | K15: Repair Pending | L15: 3337119 | M15: =_xlfn.IFNA(VLOOKUP(L15,ALL_CMS_WOs!C$1:F$6984,4,FALSE),"") -> Closed | N15: Closed | S15: Defect Confirmed - Awaiting Repair | T15: =Events[[#This Row],[Date Resolved]]-Events[[#This Row],[Event Date]] -> -45406
A16: Plymouth | B16: Active | C16: 2 | D16: Timken Main Bearing Rolling Element Issue | E16: Warning | F16: Main Bearing | G16: 45566 | I16: 2 | J16: 10/1/24 - Recommend borescoping this main bearing within 2 weeks from 10/1/24 with focus on outer race and rollers. Also recommending a 50% derate on this turbine to prolong bearing life. | K16: Repair Pending | L16: 3440359 | M16: =_xlfn.IFNA(VLOOKUP(L16,ALL_CMS_WOs!C$1:F$6984,4,FALSE),"") -> Closed | N16: Ready to Schedule | S16: Case In Progress | T16: =Events[[#This Row],[Date Resolved]]-Events[[#This Row],[Event Date]] -> -45566
A17: Sundance | B17: Active | C17: 2 | D17: Potential NTN Main Bearing Outer Race/Rolling Element Issue | E17: Sweep | F17: Main Bearing | G17: 45370 | I17: 2 | J17: 5/6/24 - Turbine derated to 50%. 3/19/24 - Recommend main bearing borescope + grease purge with 2 weeks from 3/19/24. | K17: Final Report Needed | L17: 3319476 | M17: =_xlfn.IFNA(VLOOKUP(L17,ALL_CMS_WOs!C$1:F$6984,4,FALSE),"") -> Closed | N17: Closed | P17: 45410 | S17: Defect Confirmed - Repair Complete | T17: =Events[[#This Row],[Date Resolved]]-Events[[#This Row],[Event Date]] -> 40
A18: Upstream | B18: Resolved | C18: 2 | D18: Generator Outboard ORBP | E18: Alarm | F18: Generator Outboard | G18: 45230 | H18: 45402 | I18: 3 | J18: 3/19/24 - Component replaced as result of gen bearing campaign, CMS data received. 10/31/2023 - shows signature of gen outboard orbp issue continue to monitor via cms and particle counters, 11/1/23 - Please perform an auditory and visual inspection of the generator bearings: EAM - Found grease zerk was off, reconnected, is making an auditable noise when rotating, sensor is good, grease looks normal. - record audio of both bearings, take note if anything sounds off - check quantity and quality of grease in the traps - check slip ring assembly - check gen brush assembly - check vibration sensor mounting and circuit for looseness and open/shorted wiring. Add grease to both bearings Please create an inspection report in HUVR, including all photos and videos taken during inspection | K18: Final Report Needed | L18: 3217119 | M18: =_xlfn.IFNA(VLOOKUP(L18,ALL_CMS_WOs!C$1:F$6984,4,FALSE),"") -> Closed | N18: Closed | S18: Defect Confirmed - Repair Complete | T18: =Events[[#This Row],[Date Resolved]]-Events[[#This Row],[Event Date]] -> -45230
A19: Santa Rita East | B19: Resolved | C19: 3 | E19: Alarm | F19: Helical High Speed Stage | G19: 44481 | I19: 5 | K19: Monitor | L19: 2616804 | M19: =_xlfn.IFNA(VLOOKUP(L19,ALL_CMS_WOs!C$1:F$6984,4,FALSE),"") -> Closed | N19: Closed | R19: Alarms in stage 2 and 3 indicate damage that started on 9/30 in stage 2&3, 12/28 - waiting for inspection images in HUVR, several new events for both stage 2 and stage 3 planet and pinion faults, | S19: Case In Progress | T19: =Events[[#This Row],[Date Resolved]]-Events[[#This Row],[Event Date]] -> -44481
A20: Bethel | B20: Resolved | C20: 3 | D20: HSS Bearing Damage | E20: Case Tracking | F20: Helical High Speed Stage | G20: 44966 | I20: 3 | J20: Check HSS Bearings for damage | K20: Monitor | M20: =_xlfn.IFNA(VLOOKUP(L20,ALL_CMS_WOs!C$1:F$6984,4,FALSE),"") | S20: Case In Progress | T20: =Events[[#This Row],[Date Resolved]]-Events[[#This Row],[Event Date]] -> -44966
A21: Deuel Harvest | B21: Resolved | C21: 3 | E21: EOW | F21: 1st Planetary Stage | G21: 44847 | I21: 1 | K21: EOW Claim | M21: =_xlfn.IFNA(VLOOKUP(L21,ALL_CMS_WOs!C$1:F$6984,4,FALSE),"") | T21: =Events[[#This Row],[Date Resolved]]-Events[[#This Row],[Event Date]] -> -44847
A22: Deuel Harvest | B22: Resolved | C22: 3 | E22: EOW | F22: Main Bearing | G22: 44847 | I22: 1 | K22: EOW Claim | M22: =_xlfn.IFNA(VLOOKUP(L22,ALL_CMS_WOs!C$1:F$6984,4,FALSE),"") | T22: =Events[[#This Row],[Date Resolved]]-Events[[#This Row],[Event Date]] -> -44847
A23: Bethel | B23: Active | C23: 3 | D23: Main Bearing raceway damage | E23: Case Tracking | F23: Main Bearing | G23: 44951 | I23: 1 | J23: (DNR) Main Bearing raceway damage, 50% power derate to extend life, scope confirmed failure, shutdown | K23: Final Report Needed | L23: 3096734 | M23: =_xlfn.IFNA(VLOOKUP(L23,ALL_CMS_WOs!C$1:F$6984,4,FALSE),"") -> Closed | N23: Closed | Q23: CMSMB | S23: Defect Confirmed - Awaiting Repair | T23: =Events[[#This Row],[Date Resolved]]-Events[[#This Row],[Event Date]] -> -44951
A24: Maverick | B24: Resolved | C24: 3 | E24: Instrumentation | F24: CMS Monitor | G24: 44648 | J24: Check CMS PLC monitor, may need replacement | K24: CMSTRBLSHOOT | L24: 2892344 | M24: =_xlfn.IFNA(VLOOKUP(L24,ALL_CMS_WOs!C$1:F$6984,4,FALSE),"") | N24: Cancelled | P24: 44690 | T24: =Events[[#This Row],[Date Resolved]]-Events[[#This Row],[Event Date]] -> 42
A25: Upstream | B25: Resolved | C25: 3 | E25: Warning | F25: Generator Outboard | G25: 44424 | I25: 2 | K25: Pending Replacement | L25: 2575724 | M25: =_xlfn.IFNA(VLOOKUP(L25,ALL_CMS_WOs!C$1:F$6984,4,FALSE),"") -> Closed | N25: Closed | Q25: 44645 | S25: True Positive | T25: =Events[[#This Row],[Date Resolved]]-Events[[#This Row],[Event Date]] -> -44424
A26: Plymouth | B26: Resolved | C26: 3 | D26: Keyphasor Issue | E26: Instrumentation | F26: Keyphasor | G26: 44784 | J26: Troubleshoot keyphasor per attached guide | K26: CMSTRBLSHOOT | L26: 2988827 | M26: =_xlfn.IFNA(VLOOKUP(L26,ALL_CMS_WOs!C$1:F$6984,4,FALSE),"") -> Cancelled | N26: Cancelled | T26: =Events[[#This Row],[Date Resolved]]-Events[[#This Row],[Event Date]] -> -44784
A27: Plymouth | B27: Resolved | C27: 3 | D27: CMS Monitor Netcom/Keyphasor Issue | E27: Instrumentation | F27: CMS Monitor | G27: 45509 | I27: 3 | J27: 8/5/24 - Not receiving data via Onyx Insight, please investigate if monitor is netcom or not receiving a speed signal. Contact abarndt@invenergy.com for support. | K27: CMSTRBLSHOOT | L27: 3397301 | M27: =_xlfn.IFNA(VLOOKUP(L27,ALL_CMS_WOs!C$1:F$6984,4,FALSE),"") -> Closed | N27: Closed | P27: 45540 | S27: Defect Confirmed - Repair Complete | T27: =Events[[#This Row],[Date Resolved]]-Events[[#This Row],[Event Date]] -> 31
A28: Bethel | B28: Active | C28: 3 | D28: Generator Outboard IRBP | E28: Warning | F28: Generator Outboard | G28: 45299 | I28: 6 | J28: 1/8/24 - Monitoring For direct increase. | K28: Monitor | M28: =_xlfn.IFNA(VLOOKUP(L28,ALL_CMS_WOs!C$1:F$6984,4,FALSE),"") | S28: Case In Progress | T28: =Events[[#This Row],[Date Resolved]]-Events[[#This Row],[Event Date]] -> -45299
A29: Upstream | B29: Active | C29: 3 | D29: CMS troubleshoot data issue | E29: Instrumentation | F29: CMS Monitor | G29: 45504 | I29: 5 | J29: 7/31/24 - CMS data not properly populating request for controller download | K29: CMSTRBLSHOOT | L29: 3395605 | M29: =_xlfn.IFNA(VLOOKUP(L29,ALL_CMS_WOs!C$1:F$6984,4,FALSE),"") -> Closed | N29: Closed | S29: Case In Progress
A30: Sundance | B30: Active | C30: 3 | D30: Main Bearing ORBP | E30: Sweep | F30: Main Bearing | G30: 45275 | I30: 2 | J30: 3/28/24 - Turbine has been placed on DNR list. 1/17/24 - Secondary borescope scheduled to determine derate effectivness. 12/20/23 - Turbine continues to show large impacting during turbine startup and temps have degun to deviate, turbine derated to 35%. 12/15/2023 - Spectrum data shows main bearing outer race signature with direct increasing. Recommended action is to thrust derate, and inpection/borescope this main bearing | K30: Final Report Needed | L30: 3255284 | M30: =_xlfn.IFNA(VLOOKUP(L30,ALL_CMS_WOs!C$1:F$6984,4,FALSE),"") -> Closed | N30: Closed | S30: Defect Confirmed - Awaiting Repair | T30: =Events[[#This Row],[Date Resolved]]-Events[[#This Row],[Event Date]] -> -45275
A31: Maverick | B31: Active | C31: 3 | D31: Main Bearing BS2X | E31: Sweep | F31: Main Bearing | G31: 45194 | I31: 6 | J31: 9/25/23 - Long standing BS2X signature, continue to monitor for progression. | K31: Monitor | M31: =_xlfn.IFNA(VLOOKUP(L31,ALL_CMS_WOs!C$1:F$6984,4,FALSE),"") | S31: Case In Progress | T31: =Events[[#This Row],[Date Resolved]]-Events[[#This Row],[Event Date]] -> -45194
A32: Upstream | B32: Resolved | C32: 3 | D32: S2 PC + PS BRG Damage | E32: Warning | F32: 1st Planetary Stage | G32: 45075 | H32: 45631 | I32: 3 | J32: 11/19/24 - Recently replaced. Currently down due to split. 9/20/24 - potential S2 gearing failure indicated by CMS gearbox borescope requested. 6/30/23 - Early damage to the 2nd planetary stage bearings, debris counts are consistently increasing since the installation of the particle counters. Recommending scheduling gearbox replacement in ~Q3-4 of 2024. Placed on the MCFL. | K32: Longterm Watchlist | L32: 3434572 | M32: =_xlfn.IFNA(VLOOKUP(L32,ALL_CMS_WOs!C$1:F$6984,4,FALSE),"") -> Closed | N32: Closed | O32: Q4 2024 | R32: 7/5 - CMS does not have data past 6/21 but turbine is online - reboot, send configuration? | S32: Defect Confirmed - Awaiting Repair | T32: =Events[[#This Row],[Date Resolved]]-Events[[#This Row],[Event Date]] -> -45075
A33: Deuel Harvest | B33: Resolved | C33: 4 | E33: Warning | F33: 2nd Planetary Stage | G33: 44551 | I33: 1 | K33: Monitor | M33: =_xlfn.IFNA(VLOOKUP(L33,ALL_CMS_WOs!C$1:F$6984,4,FALSE),"") | S33: Case In Progress | T33: =Events[[#This Row],[Date Resolved]]-Events[[#This Row],[Event Date]] -> -44551
A34: Plymouth | B34: Active | C34: 4 | D34: Timken Main Bearing Rolling Element Issue | E34: Warning | F34: Main Bearing | G34: 45404 | I34: 3 | J34: 7/10/24 - Turbine DNRd. 5/16/24 - Borescope shows some signs of roller element damage and DLC delamination. 4/22/24 - Recommend main bearing borescope + grease purge within 2 weeks from 4/22/24. Derated to 50% | K34: Final Report Needed | L34: 3336463 | M34: =_xlfn.IFNA(VLOOKUP(L34,ALL_CMS_WOs!C$1:F$6984,4,FALSE),"") -> Closed | N34: Closed | P34: 45495 | S34: Defect Confirmed - Repair Complete | T34: =Events[[#This Row],[Date Resolved]]-Events[[#This Row],[Event Date]] -> 91
A35: Upstream | B35: Active | C35: 4 | D35: ZF Flash S2 Carrier Bearing Issue | E35: Sweep | F35: 2nd Planetary Stage | G35: 45177 | I35: 3 | J35: Currently derated. 11/3/23 - minor spalling found in S2 planetary stage continue to monitor via CMS and oil particle data. Put on MCFL recommended replacement in Q3-4, 2024. 9/8/23 - Recommend gearbox borescope with focus on 2nd planetary stage within 3 months from 9/8/23. | K35: Longterm Watchlist | L35: 3187800 | M35: =_xlfn.IFNA(VLOOKUP(L35,ALL_CMS_WOs!C$1:F$6984,4,FALSE),"") -> Closed | N35: Closed | O35: Q4 2024 | Q35: 11/3/2023 - borescope shows spalling on 2PC BRG GS | S35: Case In Progress | T35: =Events[[#This Row],[Date Resolved]]-Events[[#This Row],[Event Date]] -> -45177
A36: Maverick | B36: Resolved | C36: 4 | E36: Instrumentation | F36: Helical High Speed Stage | G36: 44470 | L36: 2606970 | M36: =_xlfn.IFNA(VLOOKUP(L36,ALL_CMS_WOs!C$1:F$6984,4,FALSE),"") | N36: Closed | P36: 44543 | Q36: Check sensor and wirings, sensor may need to be replaced | T36: =Events[[#This Row],[Date Resolved]]-Events[[#This Row],[Event Date]] -> 73
A37: Bethel | B37: Resolved | C37: 5 | E37: Warning | F37: Helical High Speed Stage | G37: 44482 | I37: 3 | K37: Borescope | L37: Create WO | M37: =_xlfn.IFNA(VLOOKUP(L37,ALL_CMS_WOs!C$1:F$6984,4,FALSE),"") | N37: #N/A | P37: 44951 | Q37: 1/31 - Timeseries shows stage 3 direct has remained at the alarm setpoint throughout 2021, recently trending down, indicating damage has already been sustained to the HSS DnWind Rear bearing in stage 3, 0.4g peak at ORBP | S37: Case In Progress | T37: =Events[[#This Row],[Date Resolved]]-Events[[#This Row],[Event Date]] -> 469
A38: Sundance | B38: Resolved | C38: 5 | E38: Instrumentation | F38: CMS Monitor | G38: 44693 | J38: Replace 60M100 Monitor - file warranty claim for replacement | K38: CMSTRBLSHOOT | L38: 2930916 | M38: =_xlfn.IFNA(VLOOKUP(L38,ALL_CMS_WOs!C$1:F$6984,4,FALSE),"") -> Closed | N38: Closed | P38: 44796 | Q38: 8/23 - left condition, no replacement needed | T38: =Events[[#This Row],[Date Resolved]]-Events[[#This Row],[Event Date]] -> 103
A39: Upstream | B39: Active | C39: 5 | D39: Stage 2 ORBP/IRBP Issue | E39: Sweep | F39: 2nd Planetary Stage | G39: 45442 | H39: 45724 | I39: 2 | J39: 10/30/24 - Request made for borescope due to CMS S2 Planetary ORBP/IRBP defect siganture. 5/30/24 - Particle counter data shows slight increase in accumulation. S1 IRBP signature also seems to be present however could just be parking marks as it has been on the spectrum foran extended period of time. Stage 2 spectrum shows IRBP/ORBP defect signature. | K39: CMSGBXBORE | L39: 3453801 | M39: =_xlfn.IFNA(VLOOKUP(L39,ALL_CMS_WOs!C$1:F$6984,4,FALSE),"") | S39: Defect Confirmed - Awaiting Repair | T39: =Events[[#This Row],[Date Resolved]]-Events[[#This Row],[Event Date]] -> -45442
A40: Upstream | B40: Active | C40: 5 | D40: secondary stage ORBP issue | E40: Alarm | F40: 2nd Planetary Stage | G40: 45569 | I40: 2 | J40: 10/4/24 - CMS indicates second planetary ORBP issue | K40: CMSGBXBORE | L40: 3442169 | M40: =_xlfn.IFNA(VLOOKUP(L40,ALL_CMS_WOs!C$1:F$6984,4,FALSE),"") -> Closed | N40: Closed | S40: Defect Confirmed - Awaiting Repair | T40: =Events[[#This Row],[Date Resolved]]-Events[[#This Row],[Event Date]] -> -45569
...

Sheet Sites
B1: Site | C1: X | D1: XXX | E1: Owner | F1: Operation Status | G1: Master Access? | H1: Platform | I1: WTG Count | J1: CMS Monitoring | K1: State | L1: Region | M1: Site Lead | N1: AE | O1: Gearbox | P1: Asset Manager (01/16/23) | Q1: Notes
B2: Beech Ridge II | C2: 91 | E2: Southern | F2: Out of Warranty | G2: Yes | H2: 2.x | I2: 20 | J2: Yes | K2: WV | L2: East | N2: Sam | O2: William | P2: Annie
B3: Bethel | C3: 116 | D3: BTH | E3: Southern | F3: Out of Warranty - Left rFSA, CMS TBD | G3: Yes | H3: 2.x | I3: 120 | J3: Yes | K3: TX | L3: Texas 2 | M3: Erick Avila | N3: Sam | O3: Alex | P3: Annie
B4: Bishop Hill III | C4: 66 | D4: BH3 | E4: WEC | F4: Out of Warranty | G4: Yes | H4: 2.x | I4: 53 | J4: Yes | K4: IL | L4: Midwest | M4: Michael Belcher | N4: Milene | O4: William | P4: Tommy
B5: Blooming Grove | C5: 68 | D5: BLG | E5: WEC | F5: Out of Warranty | G5: Yes | H5: 2.x | I5: 94 | J5: Yes | K5: IL | L5: Midwest | M5: Grant Lengfelder | N5: Milene | O5: William | P5: Tommy
B6: Chicksaw | E6: MEC | H6: Siemens+GE | I6: 58 | J6: Yes | N6: Sam | O6: Alex | P6: Abbey
B7: Coyote Ridge | C7: 138 | D7: CYR | E7: WEC | F7: Out of Warranty | G7: NO | H7: 2.x | I7: 39 | J7: Yes | K7: SD | L7: Northern Plains | N7: Milene | O7: Alex | P7: Teresa | Q7: get approval from WEC, RCS case, SCADA implement thrust derate
B8: Desert Sky | C8: 10.165.14.200 | E8: Invenergy | F8: Out of Warranty | H8: 1.X | J8: No | K8: TX | N8: Justin | P8: Frances
B9: Deuel Harvest | C9: 69 | D9: DUL | E9: Southern | F9: Out of Warranty | G9: Yes | H9: 2.x | I9: 109 | J9: Yes | K9: SD | L9: Northern Plains | M9: Cody Kraus | N9: Sam | O9: William | P9: Annie Wyman
B10: Diversion | E10: AEP | F10: In Warranty | H10: Sierra | J10: Yes | N10: Sam | O10: Alex
B11: Goldthwaite | C11: 94 | E11: Invenergy | F11: rFSA | G11: NO | H11: 1.x-100, 2.5 | I11: 86 | J11: No | K11: TX | L11: Texas 2 | N11: Max | O11: William
B12: Gordon Butte | C12: 49 | E12: GB Wind | F12: Out of Warranty | G12: YES | H12: SLE, 2.x | I12: 9 | J12: Yes | K12: MT | L12: West | N12: Sam | O12: William | P12: Jack?
B13: Jayhawk | C13: 146 | D13: JAY | E13: WEC | F13: Out of Warranty | G13: Yes | H13: 2.82-127 | I13: 70 | J13: Yes | K13: KS | L13: Central Plains | M13: Dave Anderson | N13: Milene | O13: Alex | P13: Tommy?
B14: Marsh Hill | C14: 105 | E14: Invenergy | F14: rFSA | G14: Yes | H14: 1.x-100 | I14: 10 | J14: No | K14: NY | L14: East | N14: Max | O14: Alex
B15: Maverick | C15: 134 | D15: MAV | E15: AEP | F15: Out of Warranty | G15: Yes | H15: 2.x | I15: 103 | J15: Yes | K15: OK | L15: Oklahoma | M15: Barry Wasson | N15: Ashley | O15: William | P15: Sally
B16: Miami | C16: 102 | E16: Invenergy | F16: rFSA | G16: Yes | H16: 1.x-100 | I16: 156 | J16: No | K16: TX | L16: Central Plains | N16: Max | O16: William
B17: Number 3 (GE) | D17: N3 | E17: Invenergy | F17: Vestas - FSA, COD ? | G17: ?? | I17: 5 | J17: Yes | K17: NY | L17: East | N17: Chloe | O17: Alex | P17: Maggie | Q17: 5 GE safe harbor, rest are Vestas FSA
B18: Number 3 (Vestas) | I18: 26 | J18: No | N18: Chloe | O18: Alex
B19: Orangeville | C19: 93 | E19: Invenergy | F19: rFSA | G19: NO | H19: 1.x-100 | I19: 58 | J19: No | K19: NY | L19: East | N19: Max | O19: William
B20: Plymouth | C20: 72 | E20: MidAmerican | F20: Out of Warranty | G20: NO | H20: 2.x | I20: 73 | J20: Yes | K20: IA | L20: Northern Plains | M20: Todd Westerdahl | N20: Sam | O20: Alex | P20: Abbey | Q20: ONYX Pilot, Keyphasor issue | V20: Southern | W20: 249
B21: Red Barn | C21: WIMONREDBCM01 | E21: WEC | F21: In Warranty | G21: ?? | I21: 28 | J21: Yes | K21: WI | L21: Midwest | M21: Greg Peterson | N21: Milene | O21: William | Q21: Connect to WEC Customer Server from 10,10.10.11, then to CMS server | V21: WEC | W21: 593 | X21: CMS 1
B22: Rock Creek | E22: Pacificorp | J22: Yes | N22: Sam | O22: Alex | P22: Abbey
B23: Santa Rita East | C23: 123 | D23: SRE | E23: Invenergy | F23: Out of Warranty | G23: Yes | H23: 2.x | I23: 120 | J23: Yes | K23: TX | L23: Texas 2 | M23: Josh Wilson | N23: Max | O23: William | P23: Cody Boebel | V23: GB | W23: 9
B24: Sapphire Sky | E24: WEC | F24: Vestas - FSA, COD 12/1/22 | G24: ?? | H24: V150-4.2 + V136-3.6 | I24: 64 | J24: Yes | K24: IL | L24: Midwest | N24: Milene | O24: William | P24: Tommy | Q24: Vestas | V24: AEP | W24: 651
B25: Spring Canyon Exp. | E25: Clearway | F25: Out of Warranty | J25: No | P25: Kevin Burdeck | Q25: Onyx Monitoring | V25: MidAm | W25: 73
B26: Sundance | C26: 70 | D26: SND | E26: AEP | F26: Out of Warranty | G26: Yes | H26: 2.x | I26: 72 | J26: Yes | K26: OK | L26: Oklahoma | M26: Jeremy Ross | N26: Ashley | O26: William | P26: Sally | Q26: Need AEP permissions for derates + parameter changes
B27: Tatanka Ridge | C27: 63 | D27: TTR | E27: WEC | F27: Out of Warranty | G27: NO | H27: 2.x | I27: 56 | J27: Yes | K27: SD | L27: Northern Plains | N27: Milene | O27: Alex | P27: Teresa | V27: INV | W27: 129
B28: Trent Mesa | C28: 10.167.14.200
B29: Thunderhead | C29: 108 | D29: THD | E29: WEC | F29: Out of Warranty | G29: Yes | H29: 2.x-127 | I29: 108 | J29: Yes | K29: NE | L29: Northern Plains | M29: Nicholas Heithoff | N29: Milene | O29: Alex | P29: Teresa | W29: =SUM(W20:W27) -> 1704
B30: Tophat | F30: Vestas - FSA, COD ? | G30: ?? | I30: 67? | J30: No | Q30: Vestas
B31: Traverse 1 | C31: 135 | D31: TV1 | E31: AEP | F31: Out of Warranty | G31: Yes | H31: 2.x | I31: 142 | J31: Yes | K31: OK | L31: Oklahoma | N31: Remo | O31: William | P31: Sally
B32: Traverse 2 | C32: 136 | D32: TV2 | E32: AEP | F32: Out of Warranty | G32: Yes | H32: 2.x | I32: 142 | J32: Yes | K32: OK | L32: Oklahoma | M32: Jeremy Cartwright | N32: Remo | O32: William | P32: Sally
B33: Traverse 3 | C33: 137 | D33: TV3 | E33: AEP | F33: Out of Warranty | G33: Yes | H33: 2.x | I33: 72 | J33: Yes | K33: OK | L33: Oklahoma | N33: Remo | O33: William | P33: Sally
B34: Trent Mesa | E34: Invenergy | F34: Out of Warranty | J34: No | K34: TX | N34: Justin | P34: Frances
B35: Upstream | C35: 122 | D35: UPS | E35: WEC | F35: Out of Warranty | G35: Yes | H35: 2.5-116 | I35: 82 | J35: Yes | K35: NE | L35: Northern Plains | M35: Dan Tillis | N35: Milene | O35: Alex | P35: Teresa | Q35: Vibrations for T20 show up for T57 bc 57 was removed
B37: IP Structure: | C37: 10.X.14.200 | F37: Case Studies
B38: Hostname Structure | C38: XXX-SGESCMS1.INVSCADA.LOCAL | P38: Priority | Q38: Description
P39: 1 | Q39: Immediate Action Needed
B40: Data Validation Tables | P40: 2 | Q40: Action Needed Soon
P41: 3 | Q41: Action within 2 months
...

Sheet Part Numbers
A1: Component Name | B1: Alternate Name(s) | C1: GE PN | D1: EAM PN | E1: EAM Historic PN
A2: Keyphasor (2.x) PEM | B2: Pulse Extender, Tachometer | C2: 109W2582P001 | D2: NT00-0272A | E2: 946300007193
A3: Keyphasor (1.5) | B3: Pulse Extender, Tachometer, Generator | C3: 108W6630P001
A4: 60M100 Monitor | B4: Bently Nevada PLC | C4: 104W9823P002 | D4: NALC-0016A | E4: 946300007055
A5: Accelerometer | B5: CMS Sensor, Transducer | C5: 108W9046P001 | D5: ND00-1062A | E5: 946300007056
A6: Sensor Cable, Straight Connector | B6: Wiring connector | C6: 104W9931P010 | D6: ND00-1852A
A7: Sensor Cable, Right Angle Connector | B7: =B6 -> Wiring connector | C7: 104W9931P011 | D7: ND00-2078A
A8: CMS Module Adapter Plate | B8: Adapts 60M100 to 3701 | C8: 444W2207P001 | D8: NALC-0024A
A9: CMS Kit, 60M100, CMS, Din Rail Mount with plate | C9: 104W9823D002 | D9: WTG0-0649A | E9: 946300007182
D28: =45.92+9.18 -> 55.1
D29: =78.92+15.78 -> 94.7

Sheet Fault Frequencies
A1: Component | B1: Make | C1: Ratio/Model | D1: Subcomponent | E1: Order | F1: Input RPM | G1: Hz
A2: Main Bearing | B2: All | C2: 240/750 | D2: IRBP | E2: 16.5 | G2: =(E2*F2)/60 -> 0
A3: Main Bearing | B3: All | C3: 240/750 | D3: ORBP | E3: 13.25 | G3: =(E3*F3)/60 -> 0
A4: Main Bearing | B4: NTN | C4: 240/750 | D4: ORBP | E4: 12.75 | G4: =(E4*F4)/60 -> 0
A5: Main Bearing | B5: SKF | C5: 240/750 | D5: Ball Spin | E5: 4.875 | F5: 13.29 | G5: =(E5*F5)/60 -> 1.0798125
A6: Main Bearing | B6: SKF | C6: 240/750 | D6: ORBP | E6: 13 | F6: 13.29 | G6: =(E6*F6)/60 -> 2.8795
A7: Main Bearing | B7: Timken | C7: 240/750 | D7: Ball Spin | E7: 10.384 | G7: =(E7*F7)/60 -> 0
A8: Main Bearing | B8: Timken | C8: 240/750 | D8: IRBP | E8: 15.862 | G8: =(E8*F8)/60 -> 0
A9: Main Bearing | B9: Timken | C9: 240/750 | D9: ORBP | E9: 13.138 | G9: =(E9*F9)/60 -> 0
A10: Gearbox | B10: Nanjing | C10: FDM2C | D10: S1 PC BRG ORBP | E10: 33.5 | G10: =(E10*F10)/60 -> 0
A11: Gearbox | B11: Nanjing | C11: FDM2C | D11: S1 PC BRG RS | E11: 31 | G11: =(E11*F11)/60 -> 0
A12: Gearbox | B12: Nanjing | C12: FDM2F | D12: S2 PC BRG | E12: 19.25 | G12: =(E12*F12)/60 -> 0
A13: Gearbox | B13: ZF | C13: EH811A | D13: S1 PS BRG IRBP | E13: 26.5 | G13: =(E13*F13)/60 -> 0
A14: Gearbox | B14: ZF | C14: EH811A | D14: S1 PS BRG ORBP | E14: 22.5 | G14: =(E14*F14)/60 -> 0
A15: Gearbox | B15: ZF | C15: EH811A | D15: S2 PC BRG ORBP | E15: 28.5 | G15: =(E15*F15)/60 -> 0
A16: Gearbox | B16: Winergy | C16: 111.9/PZAB 3505 | G16: =(E16*F16)/60 -> 0
A17: Gearbox | B17: Winergy | G17: =(E17*F17)/60 -> 0
B18: Winergy | G18: =(E18*F18)/60 -> 0
B19: Winergy | G19: =(E19*F19)/60 -> 0
B20: Winergy | G20: =(E20*F20)/60 -> 0
B21: Winergy | G21: =(E21*F21)/60 -> 0
J27: =2*(13/60) -> 0.43333333 | K27: =(J27*60)/13 -> 2
D29: 2.492 | E29: =D29*60 -> 149.52 | F29: =E29/13.29 -> 11.250564
D30: 2.4252 | E30: =D30*60 -> 145.512 | F30: =E30/13 -> 11.193231
C32: IR | D32: 15.862 | E32: =D32*13 -> 206.206 | F32: =E32/60 -> 3.4367667
C33: OR | D33: 13.128 | E33: =D33*13 -> 170.664 | F33: =E33/60 -> 2.8444
C34: Cage | D34: 0.547 | E34: =D34*13 -> 7.111 | F34: =E34/60 -> 0.11851667
C35: Roller | D35: 5.192 | E35: =D35*13 -> 67.496 | F35: =E35/60 -> 1.1249333 | G35: =F35*2 -> 2.2498667

Sheet Miss Tracker
A1: Turbine: | B1: Description of Incident: | C1: How Found?: | D1: CMS Failure: | E1: Corrective Actions:
A2: Bethel 82 | B2: Turbine was found on to have experienced a thermal event, possibly in part caused by a failure of the main bearing that wasn't detected by CMS. | C2: Site found turbine after the thermal event had occurred. | D2: Turbine had a long overdue WO to fix the main bearing circuit, CMS likely could have caught indcident before catastrophic failure had occurred | E2: • Possibly send sites an email of long overdue EAM WOs on a consistent basis Come up with a standard of when case is overdue
A3: Sundance 49 | B3: Customer relayed that they were seeing issues with the turbine via CMS and temp data. Turbine was then DNRd and inspected, severe outer race damage was found. | C3: Customer notification | D3: Turbine could've been caught weeks earlier if we had access to CMS spectrum data. With just measurement trend data, we could've caught it much earlier as well. | E3: Working on getting CMS data into internal databases to run calculations off of and have alerting outside of the CMS server in place.
A4: Bethel 96

Sheet Site Specific Credentials
B1: XXX-SGESCMS1.INVSCADA.LOCAL
B2: Site | C2: Column1 | D2: XXX
B3: Maverick | C3: 134 | D3: MAV
B4: Sundance | C4: 70 | D4: SND
B5: Santa Rita East | C5: 123 | D5: SRE
B6: Traverse 1 | C6: 135 | D6: TV1
B7: Traverse 2 | C7: 136 | D7: TV2 | M7: =6550/30 -> 218.33333
B8: Traverse 3 | C8: 137 | D8: TV3 | M8: =M7*88 -> 19213.333
B9: Gordon Butte | C9: 49 | D9: see snip | M9: =M7*167 -> 36461.667
B10: Miami | C10: 102
B11: Marsh Hill | C11: 105
B12: Orangeville | C12: 93
B13: Goldthwaite | C13: 94
B14: Beech Ridge II | C14: 91
B15: Deuel Harvest | C15: 69 | D15: DUL
B16: Bethel | C16: 116
B17: Bishop Hill III | C17: 66
B18: Blooming Grove | C18: 68
B19: Coyote Ridge | C19: --
B20: Tatanka Ridge | C20: --
B21: Upstream | C21: 122
B22: Jayhawk | C22: 146 | D22: JAY
B23: Thunderhead | C23: 127 | D23: THD
F26: i+pZ,'Fq8jdW
B30: Uppercase Z F W
B34: Red Barn: | C34: WIRED\Abarndt | D34: Password1234!
B36: Maverick | C36: 134 | D36: MAV | E36: AEP | F36: None - warranty until 6/2023 | G36: 2.x | H36: 103
B37: Sundance | C37: 70 | D37: SND | E37: AEP | F37: None - warranty until 4/2023 | G37: 2.x | H37: 72
B38: Santa Rita East | C38: 123 | D38: SRE | E38: AEP | F38: None | G38: 2.x | H38: 120
B39: Traverse 1 | C39: 135 | D39: TV1 | E39: AEP | F39: None - warranty until 6/2024 | G39: 2.x | H39: 88
B40: Traverse 2 | C40: 136 | D40: TV2 | E40: AEP | F40: None - warranty until 6/2024 | G40: 2.x | H40: 142
B41: Traverse 3 | C41: 137 | D41: TV3 | E41: AEP | F41: None - warranty until 6/2024 | G41: 2.x | H41: 72
B42: Gordon Butte | C42: 49 | E42: GB Wind | F42: None | G42: SLE, 2.x | H42: 9
B43: Miami | C43: 102 | E43: Invenergy | F43: rFSA | G43: 1.x-100
B44: Marsh Hill | C44: 105 | E44: Invenergy | F44: rFSA | G44: 1.x-100
B45: Orangeville | C45: 93 | E45: Invenergy | F45: rFSA | G45: 1.x-100
B46: Goldthwaite | C46: 94 | E46: Invenergy | F46: rFSA | G46: 1.x-100, 2.5
B47: Number 3 | E47: Invenergy | F47: COD 7/1/22
B48: Plymouth | C48: ONYX | E48: MidAmerican | F48: COD 2/1/22 | H48: 73
B49: Beech Ridge II | C49: 91 | E49: Southern | F49: None - warranty until 3/2022 | G49: 2.x | H49: 20
...

Sheet EDUP Query
A1: Site | B1: WTG | C1: SystemNumber | D1: Main Bearing | E1: Gearbox
A2: Buffalo Mountain | B2: 1 | C2: 19371 | E2: Hansen
A3: Buffalo Mountain | B3: 2 | C3: 19372 | E3: Hansen
A4: Buffalo Mountain | B4: 3 | C4: 19373 | E4: Hansen
A5: Buffalo Mountain | B5: 4 | C5: 19374 | E5: L&S (Bosh)
A6: Buffalo Mountain | B6: 5 | C6: 19375 | E6: Moventas
A7: Buffalo Mountain | B7: 6 | C7: 19376 | E7: Winergy
A8: Buffalo Mountain | B8: 7 | C8: 19377 | E8: Moventas
A9: Buffalo Mountain | B9: 8 | C9: 19378 | E9: Moventas
A10: Buffalo Mountain | B10: 9 | C10: 19379 | E10: hansen
A11: Buffalo Mountain | B11: 10 | C11: 19380 | E11: Moventas
A12: Buffalo Mountain | B12: 11 | C12: 19381 | E12: Moventas
A13: Buffalo Mountain | B13: 12 | C13: 19382 | E13: Hansen
... A41: Tymien | B41: 25 | C41: 21272 | E41: Hansen
A42: Number Three | B42: 106 | C42: 104782 | D42: VESTAS | E42: ZF
A43: Number Three | B43: 107 | C43: 104783 | D43: VESTAS | E43: ZF
A44: Number Three | B44: 108 | C44: 104784 | D44: VESTAS | E44: ZF
A45: Number Three | B45: 109 | C45: 104785 | D45: VESTAS | E45: ZF
A46: Number Three | B46: 110 | C46: 104786 | D46: VESTAS | E46: ZF
A47: Number Three | B47: 111 | C47: 104787 | D47: VESTAS | E47: ZF
A48: Number Three | B48: 112 | C48: 104788 | D48: VESTAS | E48: ZF
A49: Number Three | B49: 113 | C49: 104789 | D49: VESTAS | E49: ZF
A50: Number Three | B50: 114 | C50: 104790 | D50: VESTAS | E50: ZF
A51: Number Three | B51: 115 | C51: 104791 | D51: VESTAS | E51: ZF
A52: Number Three | B52: 116 | C52: 104792 | D52: VESTAS | E52: ZF
A53: Number Three | B53: 117 | C53: 104793 | D53: VESTAS | E53: ZF
... A63: Number Three | B63: 127 | C63: 104803 | D63: VESTAS | E63: ZF
A64: Campo Palomas | B64: 1 | C64: 211006 | E64: Winergy
A65: Campo Palomas | B65: 2 | C65: 211007 | E65: Winergy
A66: Campo Palomas | B66: 3 | C66: 211008 | E66: Winergy
A67: Campo Palomas | B67: 4 | C67: 211009 | D67: SKF | E67: Winergy
A68: Campo Palomas | B68: 5 | C68: 211010 | E68: Winergy
A69: Campo Palomas | B69: 6 | C69: 211011 | E69: Winergy
A70: Campo Palomas | B70: 7 | C70: 211012 | E70: Winergy
A71: Campo Palomas | B71: 8 | C71: 211013 | E71: Winergy
A72: Campo Palomas | B72: 9 | C72: 211014 | E72: Winergy
A73: Campo Palomas | B73: 10 | C73: 211015 | E73: Winergy
A74: Campo Palomas | B74: 11 | C74: 211016 | E74: Winergy
A75: Campo Palomas | B75: 12 | C75: 211017 | E75: Winergy
A76: Campo Palomas | B76: 13 | C76: 211018 | E76: Winergy
...

Sheet ALL_CMS_WOs
A1: Priority | B1: Equipment | C1: Work Order | D1: Description | E1: Date Created | F1: Status | G1: Problem Code | H1: Standard WO | I1: Organization | J1: Created By | K1: Duration | L1: Date Completed
A2: 1 | B2: WTG-0059-0000 | C2: 1657997 | D2: GEARBOX OIL, Replace oil cooler fan/motor/pump | E2: 42747.312 | F2: Closed | G2: GBXOIL | H2: GBXOILCOOL | I2: BETHEL | J2: DWOOD | L2: 42750.675
A3: 5 | B3: WTG-0004-N000-0000 | C3: 1825317 | D3: Secondary filter cut-out contactor installation | E3: 43115.66 | F3: Closed | G3: GBXOIL | H3: GBXFILTINS | I3: JUDITH GAP | J3: JUDITHGAP | L3: 43158.353
A4: 1 | B4: WTG-0042-0000 | C4: 1345287 | D4: Change gearbox inlet hose | E4: 42566.471 | F4: Closed | G4: GBXOIL | H4: GBXOILLEAK | I4: CAL RIDGE | J4: JLAPPIN | L4: 42586.629
A5: 1 | B5: WTG-0023-NDGP-0000 | C5: 1273269 | D5: GEARBOX OIL, Replace oil cooler fan/motor/pump | E5: 42509.619 | F5: Closed | G5: GBXOIL | H5: GBXOILCOOL | I5: SPRING CANYON | J5: STAYLOR | L5: 42510.653
A6: 1 | B6: WTG-0062-NDGP-0000 | C6: 1622604 | D6: GEARBOX OIL, Fix oil leak | E6: 42709.541 | F6: Closed | G6: GBXOIL | H6: GBXOILLEAK | I6: MIAMI 1 | J6: MIAMI | L6: 42723.306
A7: 1 | B7: WTG-0061-0000 | C7: 1250401 | D7: No Errors | E7: 42432.581 | F7: Closed | G7: GBXOIL | H7: GBXOILSAMP | I7: JUDITH GAP | J7: TBRISCOE | L7: 42433.258
A8: 2 | B8: WTG-0084-NDGP-0000 | C8: 1241708 | D8: GEARBOX OIL, Particle counter installation | E8: 42410.647 | F8: Closed | G8: GBXOIL | H8: GBXPARTINS | I8: TURKEY TRACK | J8: MSNOW | L8: 42411.487
A9: 1 | B9: WTG-0012-0000 | C9: 1344039 | D9: Install secondary filtration system on gearbox oil | E9: 42563.401 | F9: Closed | G9: GBXOIL | H9: GBXFILTINS | I9: WOLVERINE CREEK | J9: DSTEO | K9: 1 | L9: 42570.377
A10: 5 | B10: WTG-0036-NDG0-0000 | C10: 1249178 | D10: Oil filter housing replacement | E10: 42430.572 | F10: Closed | G10: GBXOIL | H10: GBXOILLEAK | I10: GOLDTHWAITE | J10: CRWADE | L10: 42433.44
A11: 1 | B11: WTG-0020-NDG0-0000 | C11: 1255635 | D11: GEARBOX OIL, Particle counter installation (Troubleshoot) | E11: 42458.415 | F11: Closed | G11: GBXOIL | H11: GBXPARTINS | I11: TURKEY TRACK | J11: TURKEY TRACK | L11: 42459.651
A12: 2 | B12: WTG-0025-NDGP-0000 | C12: 1280063 | D12: Oil Pump Inversion | E12: 42524.52 | F12: Closed | G12: GBXOIL | H12: GBXOILCOOL | I12: WOLVERINE CREEK | J12: AMARTORANA | L12: 42524.584
A13: 4 | B13: WTG-0022-NDGP-0000 | C13: 1591668 | D13: Gear oil pump replacement | E13: 42664.419 | F13: Closed | G13: GBXOIL | H13: GBXOILCOOL | I13: FORWARD | J13: FORWARD | L13: 42667.643
A14: 5 | B14: WTG-0050-0000 | C14: 1270519 | D14: GEARBOX OIL, Oil Sample | E14: 42500.451 | F14: Closed | G14: GBXOIL | H14: GBXOILSAMP | I14: RATTLESNAKE 1 | J14: NFALASZ | L14: 42524.63
A15: 5 | B15: WTG-0061-0000 | C15: 1270520 | D15: GEARBOX OIL, Oil Sample | E15: 42500.451 | F15: Closed | G15: GBXOIL | H15: GBXOILSAMP | I15: RATTLESNAKE 1 | J15: NFALASZ | L15: 42549.358
A16: 2 | B16: WTG-0005-NDGP-0000 | C16: 1270424 | D16: Oil Pump Motor Inversion | E16: 42499.585 | F16: Closed | G16: GBXOIL | H16: GBXOILLEAK | I16: WOLVERINE CREEK | J16: DSTEO | L16: 42503.393
A17: 2 | B17: WTG-0072-0000 | C17: 1586267 | D17: GEARBOX OIL, Fix oil leak | E17: 42655.535 | F17: Closed | G17: GBXOIL | H17: GBXOILLEAK | I17: BUCKEYE | J17: BUCKEYE | L17: 42684.709
A18: 1 | B18: WTG-0128-NDGP-0000 | C18: 1359217 | D18: EM: Gearbox oil pessure too low | E18: 42585.637 | F18: Closed | G18: GBXOIL | H18: EM52 | I18: WAKE 1 | J18: JDEWEESE | L18: 42594.604
A19: 1 | B19: WTG-0065-NDG0-0000 | C19: 1359218 | D19: GEARBOX OIL, Fix oil leak | E19: 42585.606 | F19: Closed | G19: GBXOIL | H19: GBXOILLEAK | I19: MCADOO | J19: DHALE | L19: 42586.355
A20: 4.2 | B20: WTG-0009-0000 | C20: 1401332 | D20: gearbox oil sample and Post oil change Oil sample | E20: 42594.6 | F20: Cancelled | G20: GBXOIL | H20: GBXOILSAMP | I20: GUNSIGHT | J20: CMORRIS | L20: 42599.681
A21: 4.2 | B21: WTG-0010-0000 | C21: 1401333 | D21: gearbox oil sample and Post oil change Oil sample | E21: 42594.6 | F21: Cancelled | G21: GBXOIL | H21: GBXOILSAMP | I21: GUNSIGHT | J21: CMORRIS | L21: 42599.682
... A52: 4.2 | B52: WTG-0006-NDG0-0000 | C52: 1668751 | D52: GEARBOX OIL, Add/Top-Off | E52: 42768.638 | F52: Closed | G52: GBXOIL | H52: GBXOILADD | I52: WOLVERINE CREEK | J52: DSTEO | L52: 42795.347
A53: 9 | B53: WTG-0075-0000 | C53: 1663560 | D53: Hose Leak Found on Radiator after Nanjing Bolt retro | E53: 42761.37 | F53: Closed | G53: GBXOIL | H53: GBXOILLEAK | I53: GOLDTHWAITE | J53: DDIAZ | K53: 30 | L53: 42762.675
A54: 9 | B54: WTG-0085-0000 | C54: 1663561 | D54: Hose Leak Found on Radiator after Nanjing Bolt retro | E54: 42761.37 | F54: Closed | G54: GBXOIL | H54: GBXOILLEAK | I54: GOLDTHWAITE | J54: DDIAZ | K54: 30 | L54: 42762.675
A55: 1 | B55: TTEC-WTG-062 | C55: 1253941 | D55: EM: Gearbox oil level too low | E55: 42452.776 | F55: Closed | G55: GBXOIL | H55: EM51 | I55: TURKEY TRACK | J55: SREYNOLDS | L55: 42453.34
A56: 1 | B56: MIA1 | C56: 1595420 | D56: GEARBOX OIL, Fix oil leak | E56: 42671.733 | F56: Closed | G56: GBXOIL | H56: GBXOILLEAK | I56: MIAMI 1 | J56: JHAVENS | L56: 42674.313
A57: 1 | B57: WTG-0137-NDG0-0000 | C57: 1595392 | D57: EM: Shaft bearing overtemperature | E57: 42671.674 | F57: Closed | G57: GBXOIL | H57: EM81 | I57: WAKE 1 | J57: IMORALES | L57: 42681.678
A58: 5 | B58: WTG-0014-NDGP-0000 | C58: 1602564 | D58: GEARBOX OIL, Secondary filter system element change | E58: 42690.608 | F58: Closed | G58: GBXOIL | H58: GBXFILTELEM | I58: WOLVERINE CREEK | J58: AMARTORANA | L58: 42692.61
A59: 2 | B59: WTG-0002C-NDGP-0000 | C59: 1259849 | D59: GEARBOX OIL, Replace oil cooler fan motor | E59: 42465.709 | F59: Closed | G59: GBXOIL | H59: GBXOILCOOL | I59: FORWARD | J59: GOTKIN | L59: 42473.588
A60: 1 | B60: WTG-0076-NDGP-0000 | C60: 1267388 | D60: GEARBOX OIL, Secondary filter system element change | E60: 42492.399 | F60: Closed | G60: GBXOIL | H60: GBXFILTELEM | I60: GREXP | J60: MSNOW | L60: 42726.37
A61: 1 | B61: WTG-0085-NDGP-0000 | C61: 1267389 | D61: GEARBOX OIL, Secondary filter system element change | E61: 42492.399 | F61: Closed | G61: GBXOIL | H61: GBXFILTELEM | I61: GREXP | J61: MSNOW | L61: 42514.304
A62: 1 | B62: WTG-0102-NDGP-0000 | C62: 1267390 | D62: GEARBOX OIL, Secondary filter system element change | E62: 42492.399 | F62: Closed | G62: GBXOIL | H62: GBXFILTELEM | I62: GREXP | J62: MSNOW | L62: 42656.354
A63: 1 | B63: WTG-0111-NDGP-0000 | C63: 1267391 | D63: GEARBOX OIL, Secondary filter system element change | E63: 42492.4 | F63: Closed | G63: GBXOIL | H63: GBXFILTELEM | I63: GREXP | J63: MSNOW | L63: 43083.696
A64: 1 | B64: WTG-0004-NDGP-0000 | C64: 1267393 | D64: GEARBOX OIL, Secondary filter system element change | E64: 42492.359 | F64: Closed | G64: GBXOIL | H64: GBXFILTELEM | I64: JUDITH GAP | J64: MSNOW | L64: 42523.266
A65: 1 | B65: WTG-0040-NDGP-0000 | C65: 1267376 | D65: GEARBOX OIL, Secondary filter system element change | E65: 42492.397 | F65: Closed | G65: GBXOIL | H65: GBXFILTELEM | I65: GRAND RIDGE | J65: MSNOW | L65: 42853.495
A66: 1 | B66: WTG-0043-NDGP-0000 | C66: 1267377 | D66: GEARBOX OIL, Secondary filter system element change | E66: 42492.398 | F66: Closed | G66: GBXOIL | H66: GBXFILTELEM | I66: GRAND RIDGE | J66: MSNOW | L66: 43048.328
... A136: 1 | B136: WTG-0103-0000 | C136: 1518136 | D136: GEARBOX OIL, Fix oil leak | E136: 42628.669 | F136: Closed | G136: GBXOIL | H136: GBXOILLEAK | I136: CAL RIDGE | J136: BDAILY | L136: 42632.327
A137: 9 | B137: WTG-0045-0000 | C137: 1613901 | D137: Hose Leak Found on Radiator after Nanjing Bolt retro | E137: 42704.657 | F137: Closed | G137: GBXOIL | H137: GBXOILLEAK | I137: GOLDTHWAITE | J137: KIRBY | K137: 30 | L137: 42762.675
A138: 1 | B138: WTG-0144-0000 | C138: 1570303 | D138: GEARBOX OIL, Replace oil cooler hose | E138: 42642.391 | F138: Closed | G138: GBXOIL | H138: GBXOILLEAK | I138: MIAMI 1 | J138: JHAVENS | L138: 42643.316
A139: 2 | B139: WTG-0120-NDG0-0000 | C139: 1600178 | D139: GEARBOX OIL, Add/Top-Off | E139: 42678.671 | F139: Closed | G139: GBXOIL | H139: GBXOILADD | I139: MIAMI 1 | J139: JFREEMAN | L139: 42681.419
...
