Workbook
Name SegmentaçãodeDados_Site: #N/A
Name SegmentaçãodeDados_Site1: #N/A

Sheet Relatório Executivo
B2: RELATÓRIO EXECUTIVO - TURBINAS PARADAS ≥7 DIAS | N2: DADOS AUXILIARES - GRÁFICO
B3: ="Consolidado Essentia + Auren | Data: "&DAY(TODAY())&"/"&MONTH(TODAY())&"/"&YEAR(TODAY()) -> Consolidado Essentia + Auren | Data: 25/9/2026 | N3: Semana | O3: Ano | P3: 2025 | Q3: 2026 | R3: Variação
N4: W21 | O4: 21 | P4: =IFERROR(INDEX(Historic!$H:$H,MATCH("2025W"&TEXT(O4,"00"),Historic!$A:$A,0)),0) -> 11 | Q4: =IFERROR(INDEX(Historic!$H:$H,MATCH("2026W"&TEXT(O4,"00"),Historic!$A:$A,0)),0) -> 6 | R4: =IFERROR(Q4-P4,0) -> -5
B5: RESUMO EXECUTIVO | N5: W22 | O5: 22 | P5: =IFERROR(INDEX(Historic!$H:$H,MATCH("2025W"&TEXT(O5,"00"),Historic!$A:$A,0)),0) -> 12 | Q5: =IFERROR(INDEX(Historic!$H:$H,MATCH("2026W"&TEXT(O5,"00"),Historic!$A:$A,0)),0) -> 2 | R5: =IFERROR(Q5-P5,0) -> -10
N6: W23 | O6: 23 | P6: =IFERROR(INDEX(Historic!$H:$H,MATCH("2025W"&TEXT(O6,"00"),Historic!$A:$A,0)),0) -> 11 | Q6: =IFERROR(INDEX(Historic!$H:$H,MATCH("2026W"&TEXT(O6,"00"),Historic!$A:$A,0)),0) -> 4 | R6: =IFERROR(Q6-P6,0) -> -7
B7: Indicador | C7: Essentia | D7: Auren | E7: Total | G7: ANÁLISE POR COMPONENTE | N7: W24 | O7: 24 | P7: =IFERROR(INDEX(Historic!$H:$H,MATCH("2025W"&TEXT(O7,"00"),Historic!$A:$A,0)),0) -> 11 | Q7: =IFERROR(INDEX(Historic!$H:$H,MATCH("2026W"&TEXT(O7,"00"),Historic!$A:$A,0)),0) -> 3 | R7: =IFERROR(Q7-P7,0) -> -8
B8: Turbinas Paradas ≥7 dias | C8: =COUNTIFS('Fonte de Dados - Essentia'!$E$4:$E$222,"Parada",'Fonte de Dados - Essentia'!$F$4:$F$222,">=7") -> 1 | D8: =COUNTIFS('Fonte de Dados - Auren'!$E$6:$E$50,"Parada",'Fonte de Dados - Auren'!$F$6:$F$50,">=7") -> 3 | E8: =C8+D8 -> 4 | G8: Gerador | H8: =COUNTIFS('Fonte de Dados - Essentia'!$E$4:$E$222,"Parada",'Fonte de Dados - Essentia'!$F$4:$F$222,">=7",'Fonte de Dados - Essentia'!$I$4:$I$222,"*Gerador*")+COUNTIFS('Fonte de Dados - Auren'!$E$6:$E$50,"Parada",'Fonte de Dados - Auren'!$F$6:$F$50,">=7",'Fonte de Dados - Auren'!$I$6:$I$50,"*Gerador*") -> 0 | N8: W25 | O8: 25 | P8: =IFERROR(INDEX(Historic!$H:$H,MATCH("2025W"&TEXT(O8,"00"),Historic!$A:$A,0)),0) -> 17 | Q8: =IFERROR(INDEX(Historic!$H:$H,MATCH("2026W"&TEXT(O8,"00"),Historic!$A:$A,0)),0) -> 4 | R8: =IFERROR(Q8-P8,0) -> -13
B9: Média Dias Parada | C9: =IFERROR(AVERAGEIFS('Fonte de Dados - Essentia'!$F$4:$F$222,'Fonte de Dados - Essentia'!$E$4:$E$222,"Parada",'Fonte de Dados - Essentia'!$F$4:$F$222,">=7"),0) -> 78 | D9: =IFERROR(AVERAGEIFS('Fonte de Dados - Auren'!$F$6:$F$50,'Fonte de Dados - Auren'!$E$6:$E$50,"Parada",'Fonte de Dados - Auren'!$F$6:$F$50,">=7"),0) -> 62 | E9: =IFERROR((C9*C8+D9*D8)/E8,0) -> 66 | G9: Pitch Bearing | H9: =COUNTIFS('Fonte de Dados - Essentia'!$E$4:$E$222,"Parada",'Fonte de Dados - Essentia'!$F$4:$F$222,">=7",'Fonte de Dados - Essentia'!$I$4:$I$222,"*Pitch Bearing*")+COUNTIFS('Fonte de Dados - Auren'!$E$6:$E$50,"Parada",'Fonte de Dados - Auren'!$F$6:$F$50,">=7",'Fonte de Dados - Auren'!$I$6:$I$50,"*Pitch Bearing*") -> 1 | N9: W26 | O9: 26 | P9: =IFERROR(INDEX(Historic!$H:$H,MATCH("2025W"&TEXT(O9,"00"),Historic!$A:$A,0)),0) -> 18 | Q9: =IFERROR(INDEX(Historic!$H:$H,MATCH("2026W"&TEXT(O9,"00"),Historic!$A:$A,0)),0) -> 3 | R9: =IFERROR(Q9-P9,0) -> -15
G10: Blade | H10: =COUNTIFS('Fonte de Dados - Essentia'!$E$4:$E$222,"Parada",'Fonte de Dados - Essentia'!$F$4:$F$222,">=7",'Fonte de Dados - Essentia'!$I$4:$I$222,"*Blade*")+COUNTIFS('Fonte de Dados - Auren'!$E$6:$E$50,"Parada",'Fonte de Dados - Auren'!$F$6:$F$50,">=7",'Fonte de Dados - Auren'!$I$6:$I$50,"*Blade*") -> 2 | N10: W27 | O10: 27 | P10: =IFERROR(INDEX(Historic!$H:$H,MATCH("2025W"&TEXT(O10,"00"),Historic!$A:$A,0)),0) -> 18 | Q10: =IFERROR(INDEX(Historic!$H:$H,MATCH("2026W"&TEXT(O10,"00"),Historic!$A:$A,0)),0) -> 2 | R10: =IFERROR(Q10-P10,0) -> -16
G11: Main Bearing | H11: =COUNTIFS('Fonte de Dados - Essentia'!$E$4:$E$222,"Parada",'Fonte de Dados - Essentia'!$F$4:$F$222,">=7",'Fonte de Dados - Essentia'!$I$4:$I$222,"*Main Bearing*")+COUNTIFS('Fonte de Dados - Auren'!$E$6:$E$50,"Parada",'Fonte de Dados - Auren'!$F$6:$F$50,">=7",'Fonte de Dados - Auren'!$I$6:$I$50,"*Main Bearing*") -> 0 | N11: W28 | O11: 28 | P11: =IFERROR(INDEX(Historic!$H:$H,MATCH("2025W"&TEXT(O11,"00"),Historic!$A:$A,0)),0) -> 16 | Q11: =IFERROR(INDEX(Historic!$H:$H,MATCH("2026W"&TEXT(O11,"00"),Historic!$A:$A,0)),0) -> 2 | R11: =IFERROR(Q11-P11,0) -> -14
G12: Yaw Drive | H12: =COUNTIFS('Fonte de Dados - Essentia'!$E$4:$E$222,"Parada",'Fonte de Dados - Essentia'!$F$4:$F$222,">=7",'Fonte de Dados - Essentia'!$I$4:$I$222,"*Yaw Drive*")+COUNTIFS('Fonte de Dados - Auren'!$E$6:$E$50,"Parada",'Fonte de Dados - Auren'!$F$6:$F$50,">=7",'Fonte de Dados - Auren'!$I$6:$I$50,"*Yaw Drive*") -> 0 | N12: W29 | O12: 29 | P12: =IFERROR(INDEX(Historic!$H:$H,MATCH("2025W"&TEXT(O12,"00"),Historic!$A:$A,0)),0) -> 12 | Q12: =IFERROR(INDEX(Historic!$H:$H,MATCH("2026W"&TEXT(O12,"00"),Historic!$A:$A,0)),0) -> 4 | R12: =IFERROR(Q12-P12,0) -> -8
G13: Gearbox | H13: =COUNTIFS('Fonte de Dados - Essentia'!$E$4:$E$222,"Parada",'Fonte de Dados - Essentia'!$F$4:$F$222,">=7",'Fonte de Dados - Essentia'!$I$4:$I$222,"*Gearbox*")+COUNTIFS('Fonte de Dados - Auren'!$E$6:$E$50,"Parada",'Fonte de Dados - Auren'!$F$6:$F$50,">=7",'Fonte de Dados - Auren'!$I$6:$I$50,"*Gearbox*") -> 1 | N13: W30 | O13: 30 | P13: =IFERROR(INDEX(Historic!$H:$H,MATCH("2025W"&TEXT(O13,"00"),Historic!$A:$A,0)),0) -> 10 | Q13: =IFERROR(INDEX(Historic!$H:$H,MATCH("2026W"&TEXT(O13,"00"),Historic!$A:$A,0)),0) -> 4 | R13: =IFERROR(Q13-P13,0) -> -6
N14: W31 | O14: 31 | P14: =IFERROR(INDEX(Historic!$H:$H,MATCH("2025W"&TEXT(O14,"00"),Historic!$A:$A,0)),0) -> 7 | Q14: =IFERROR(INDEX(Historic!$H:$H,MATCH("2026W"&TEXT(O14,"00"),Historic!$A:$A,0)),0) -> 3 | R14: =IFERROR(Q14-P14,0) -> -4
B15: EVOLUÇÃO SEMANAL - COMPARATIVO ANUAL | N15: W32 | O15: 32 | P15: =IFERROR(INDEX(Historic!$H:$H,MATCH("2025W"&TEXT(O15,"00"),Historic!$A:$A,0)),0) -> 8 | Q15: =IFERROR(INDEX(Historic!$H:$H,MATCH("2026W"&TEXT(O15,"00"),Historic!$A:$A,0)),0) -> 6 | R15: =IFERROR(Q15-P15,0) -> -2
I17: TOP 5 - MAIOR CRITICIDADE
I18: WTG | J18: Site | K18: Dias | L18: Componente
I19: {=IFERROR(_xlfn.TAKE(_xlfn._xlws.SORT(_xlfn.VSTACK(_xlfn._xlws.FILTER(CHOOSE({1,2,3,4},'Fonte de Dados - Essentia'!$B$4:$B$222,'Fonte de Dados - Essentia'!$A$4:$A$222,'Fonte de Dados - Essentia'!$F$4:$F$222,'Fonte de Dados - Essentia'!$I$4:$I$222),('Fonte de Dados - Essentia'!$E$4:$E$222="Parada")*('Fonte de Dados - Essentia'!$F$4:$F$222>=7)),_xlfn._xlws.FILTER(CHOOSE({1,2,3,4},'Fonte de Dados - Auren'!$B$6:$B$50,'Fonte de Dados - Auren'!$A$6:$A$50,'Fonte de Dados - Auren'!$F$6:$F$50,'Fonte de Dados - Auren'!$I$6:$I$50),('Fonte de Dados - Auren'!$E$6:$E$50="Parada")*('Fonte de Dados - Auren'!$F$6:$F$50>=7))),3,-1),5),"—")} -> EBR07-12 | J19: Caetés | K19: 101 | L19: Blade
I20: JOA12-03 | J20: Chapada I | K20: 78 | L20: Blade
I21: EBR06-08 | J21: Caetés | K21: 63 | L21: Pitch Bearing
I22: EBR05-13 | J22: Caetés | K22: 22 | L22: Gearbox
B32: TURBINAS PARADAS ≥7 DIAS - ESSENTIA
B33: ="(" & C8 & " unidades)" -> (1 unidades)
B35: Site | C35: WTG | D35: Dias Parada | E35: Componente | F35: Brief Description | G35: Ação Pendente
B36: {=IFERROR(_xlfn._xlws.SORT(_xlfn._xlws.FILTER(CHOOSE({1,2,3,4,5,6},'Fonte de Dados - Essentia'!$A$4:$A$222,'Fonte de Dados - Essentia'!$B$4:$B$222,'Fonte de Dados - Essentia'!$F$4:$F$222,'Fonte de Dados - Essentia'!$I$4:$I$222,'Fonte de Dados - Essentia'!$J$4:$J$222,'Fonte de Dados - Essentia'!$K$4:$K$222),('Fonte de Dados - Essentia'!$E$4:$E$222="Parada")*('Fonte de Dados - Essentia'!$F$4:$F$222>=7)),3,-1),"Nenhuma turbina parada ≥7 dias")} -> Chapada I | C36: JOA12-03 | D36: 78 | E36: Blade | F36: MCE | G36: Nenhuma turbina parada ≥7 dias
B48: TURBINAS PARADAS ≥7 DIAS - AUREN
B49: ="(" & D8 & " unidades)" -> (3 unidades)
B51: Site | C51: WTG | D51: Dias Parada | E51: Componente | F51: Brief Description | G51: Ação Pendente
B52: {=IFERROR(_xlfn._xlws.SORT(_xlfn._xlws.FILTER(CHOOSE({1,2,3,4,5,6},'Fonte de Dados - Auren'!$A$6:$A$50,'Fonte de Dados - Auren'!$B$6:$B$50,'Fonte de Dados - Auren'!$F$6:$F$50,'Fonte de Dados - Auren'!$I$6:$I$50,'Fonte de Dados - Auren'!$J$6:$J$50,'Fonte de Dados - Auren'!$K$6:$K$50),('Fonte de Dados - Auren'!$E$6:$E$50="Parada")*('Fonte de Dados - Auren'!$F$6:$F$50>=7)),3,-1),"Nenhuma turbina parada ≥7 dias")} -> Caetés | C52: EBR07-12 | D52: 101 | E52: Blade | F52: UPTOWER REPAIR | G52: 16/07: Máquina parada para reparo de blades. Responsabilidade Auren. 23/07: Reparo em andamento. 30/07: Sem previsão de retorno ainda. 10/09: Auren finalizando o reparo.
B53: Caetés | C53: EBR06-08 | D53: 63 | E53: Pitch Bearing | F53: MCE | G53: 30/07: Falha no pitch bearing devido a danos internos. Previsão de retorno no início de set/26. 13/08: Auren se planejando para realização da troca. 10/09: Troca será feita com o time de Field Services.
B54: Caetés | C54: EBR05-13 | D54: 22 | E54: Gearbox | F54: MCE | G54: 10/09: Houve o colapso da gearbox. 17/09: Auren mobilizando para troca. Previsão de finalização da atividade na semana que vem. Atividade será realizada com Liftra.
B67: Relatório gerado automaticamente | Dados atualizados em tempo real | Para uso interno

Sheet Dashboard
A1: STOPPED TURBINES - DASHBOARD
D4: Site | E4: Asa Branca
D6: WTG | E6: Data da parada | F6: Previsão de Retorno | G6: Dias parada | H6: Motivo | I6: Componente/Subsistema | J6: Ação Pendente
D7: AB 05-13 | E7: 45609 | F7: 45610 | G7: 1 | H7: Turbina não passa no teste de baterias do sistema de pitch. | I7: Pitch Battery | J7: Troubleshooting da falha.
D8: AB 06-06 | E8: 45606 | F8: 45610 | G8: 4 | H8: Turbina não passa no teste de baterias do sistema de pitch. | I8: Pitch Battery | J8: Troubleshooting da falha com suporte da engenharia.
D9: AB 06-08 | E9: 45607 | F9: 45623 | G9: 3 | H9: Danos no gerador, curto no wye ring. | I9: Gerador | J9: Aguardando deslocamento de um time de Chapada para realizar o reparo.
D10: AB 07-11 | E10: 45601 | F10: 45630 | G10: 9 | H10: Danos no gerador, curto no wye ring. | I10: Gerador | J10: Aguardando deslocamento de um time de Chapada para realizar o reparo.

Sheet Dashboard_Essentia
I1: Stopped Turbines +7 days - Essentia
J34: Quantidade de turbinas paradas - Essentia | AJ34: Status | AK34: Parada | AP34: Status | AQ34: Parada
I35: Quantidade de turbinas paradas | J35: =COUNTIFS('Fonte de Dados - Essentia'!E:E,"Parada",'Fonte de Dados - Essentia'!F:F,">=7") -> 4 | AJ35: Dias parada | AK35: - | AP35: Dias parada | AQ35: (Vários itens)
I36: % da frota | J36: =J35/347 -> 0.011527378 | AJ36: Site | AK36: Asa Branca | AP36: Site | AQ36: (Vários itens)
J38: ASA BRANCA | L38: CHAPADA | AJ38: Contagem de WTG | AK38: Rótulos de Coluna | AP38: Contagem de WTG | AQ38: Rótulos de Coluna
I39: Quantidade de turbinas paradas | J39: =COUNTIFS('Fonte de Dados - Essentia'!A:A,"Asa Branca",'Fonte de Dados - Essentia'!E:E,"Parada",'Fonte de Dados - Essentia'!F:F,">=7") -> 0 | L39: =COUNTIFS('Fonte de Dados - Essentia'!E:E,"Parada",'Fonte de Dados - Essentia'!A:A,"Chapada I",'Fonte de Dados - Essentia'!F:F,">=7")+COUNTIFS('Fonte de Dados - Essentia'!E:E,"Parada",'Fonte de Dados - Essentia'!A:A,"Chapada II",'Fonte de Dados - Essentia'!F:F,">=7")+COUNTIFS('Fonte de Dados - Essentia'!E:E,"Parada",'Fonte de Dados - Essentia'!A:A,"Chapada III",'Fonte de Dados - Essentia'!F:F,">=7") -> 4 | AJ39: Rótulos de Linha | AK39: Total Geral | AP39: Rótulos de Linha | AQ39: MCE | AR39: Total Geral
I40: % da frota | J40: =J39/100 -> 0 | L40: =L39/247 -> 0.016194332 | AJ40: Total Geral | AP40: Blade | AQ40: 1 | AR40: 1
AP41: Gearbox | AQ41: 2 | AR41: 2
AP42: Gerador | AQ42: 1 | AR42: 1
AP43: Total Geral | AQ43: 4 | AR43: 4

Sheet Horas DTs
A1: Status | B1: Parada
A3: Rótulos de Linha | B3: Soma de Horas paradas
A4: Asa Branca | B4: 0
A5: Chapada I | B5: 1440
A6: Chapada II | B6: 1704
A7: Chapada III | B7: 1080
A8: Total Geral | B8: 4224

Sheet Disp. YTD
A1: Status | B1: Parada
A3: Rótulos de Linha | B3: Soma de Indisponibilidade TB
A4: Asa Branca | B4: 0
A5: Chapada I | B5: 0.0060667341
A6: Chapada II | B6: 0.008255814
A7: Chapada III | B7: 0.016351744
A8: Total Geral | B8: 0.030674292

Sheet WTGs paradas
A1: Status | B1: Parada
A3: Rótulos de Linha | B3: Contagem de WTG
A4: Asa Branca | B4: 2
A5: Chapada I | B5: 9
A6: Chapada II | B6: 2
A7: Chapada III | B7: 1
A8: Total Geral | B8: 14

Sheet Historic
A1: YEAR+WEEK | B1: Year | C1: Week | D1: Domingo | E1: Sábado | F1: ASA | G1: CHA | H1: Total | I1: Turbinas afetadas | J1: SOMA | K1: MÉDIA ACUMULADA | L1: MÉDIA ANUAL | M1: # | N1: Média WindSpeed
A2: 2024W39 | B2: =LEFT(A2,4) -> 2024 | C2: =RIGHT(A2,2) -> 39 | D2: 45558 | E2: =D2+6 -> 45564 | F2: 0 | G2: 8 | H2: =F2+G2 -> 8 | I2: =COUNTIF('Fonte de Dados - Essentia'!C4:C46,"<=45564") -> 0 | J2: =SUM(F2:G2) -> 8 | K2: =SUM(F2:G2)/M2 -> 8 | L2: =AVERAGE(H2) -> 8 | M2: 1 | N2: Registro de turbinas com mais de 7 dias paradas
A3: 2024W40 | B3: =LEFT(A3,4) -> 2024 | C3: =RIGHT(A3,2) -> 40 | D3: =D2+7 -> 45565 | E3: =D3+6 -> 45571 | F3: 0 | G3: 8 | H3: =F3+G3 -> 8 | I3: =COUNTIF('Fonte de Dados - Essentia'!C:C,"<=45571") -> 8 | J3: =SUM(F3:G3) -> 8 | K3: =SUM(F2:G3)/M3 -> 8 | L3: =AVERAGE($H$2:H3) -> 8 | M3: 2
A4: 2024W41 | B4: =LEFT(A4,4) -> 2024 | C4: =RIGHT(A4,2) -> 41 | D4: =D3+7 -> 45572 | E4: =D4+6 -> 45578 | F4: 0 | G4: 9 | H4: =F4+G4 -> 9 | I4: =COUNTIF('Fonte de Dados - Essentia'!C:C,"<=45578") -> 8 | J4: =SUM(F4:G4) -> 9 | K4: =SUM(F2:G4)/M4 -> 8.3333333 | L4: =AVERAGE($H$2:H4) -> 8.3333333 | M4: 3
A5: 2024W42 | B5: =LEFT(A5,4) -> 2024 | C5: =RIGHT(A5,2) -> 42 | D5: =D4+7 -> 45579 | E5: =D5+6 -> 45585 | F5: 0 | G5: 9 | H5: =F5+G5 -> 9 | I5: =COUNTIF('Fonte de Dados - Essentia'!C:C,"<=45585") -> 9 | J5: =SUM(F5:G5) -> 9 | K5: =SUM(F2:G5)/M5 -> 8.5 | L5: =AVERAGE($H$2:H5) -> 8.5 | M5: 4
A6: 2024W43 | B6: =LEFT(A6,4) -> 2024 | C6: =RIGHT(A6,2) -> 43 | D6: =D5+7 -> 45586 | E6: =D6+6 -> 45592 | F6: 0 | G6: 10 | H6: =F6+G6 -> 10 | I6: =COUNTIF('Fonte de Dados - Essentia'!C:C,"<=45592") -> 9 | J6: =SUM(F6:G6) -> 10 | K6: =SUM(F2:G6)/M6 -> 8.8 | L6: =AVERAGE($H$2:H6) -> 8.8 | M6: 5
A7: 2024W44 | B7: =LEFT(A7,4) -> 2024 | C7: =RIGHT(A7,2) -> 44 | D7: =D6+7 -> 45593 | E7: =D7+6 -> 45599 | F7: 1 | G7: 12 | H7: =F7+G7 -> 13 | I7: =COUNTIF('Fonte de Dados - Essentia'!C:C,"<=45599") -> 10 | J7: =SUM(F7:G7) -> 13 | K7: =SUM(F2:G7)/M7 -> 9.5 | L7: =AVERAGE($H$2:H7) -> 9.5 | M7: 6
A8: 2024W45 | B8: =LEFT(A8,4) -> 2024 | C8: =RIGHT(A8,2) -> 45 | D8: =D7+7 -> 45600 | E8: =D8+6 -> 45606 | F8: 3 | G8: 15 | H8: =F8+G8 -> 18 | I8: =COUNTIF('Fonte de Dados - Essentia'!C:C,"<=45606") -> 14 | J8: =SUM(F8:G8) -> 18 | K8: =SUM(F2:G8)/M8 -> 10.714286 | L8: =AVERAGE($H$2:H8) -> 10.714286 | M8: 7
A9: 2024W46 | B9: =LEFT(A9,4) -> 2024 | C9: =RIGHT(A9,2) -> 46 | D9: =D8+7 -> 45607 | E9: =D9+6 -> 45613 | F9: 3 | G9: 15 | H9: =F9+G9 -> 18 | I9: =COUNTIF('Fonte de Dados - Essentia'!C:C,"<=45613") -> 20 | J9: =SUM(F9:G9) -> 18 | K9: =SUM(F2:G9)/M9 -> 11.625 | L9: =AVERAGE($H$2:H9) -> 11.625 | M9: 8
A10: 2024W47 | B10: =LEFT(A10,4) -> 2024 | C10: =RIGHT(A10,2) -> 47 | D10: =D9+7 -> 45614 | E10: =D10+6 -> 45620 | F10: 2 | G10: 13 | H10: =F10+G10 -> 15 | I10: =COUNTIF('Fonte de Dados - Essentia'!C:C,"<=45620") -> 23 | J10: =SUM(F10:G10) -> 15 | K10: =SUM(F2:G10)/M10 -> 12 | L10: =AVERAGE($H$2:H10) -> 12 | M10: 9
A11: 2024W48 | B11: =LEFT(A11,4) -> 2024 | C11: =RIGHT(A11,2) -> 48 | D11: =D10+7 -> 45621 | E11: =D11+6 -> 45627 | F11: 2 | G11: 14 | H11: =F11+G11 -> 16 | I11: =COUNTIF('Fonte de Dados - Essentia'!C:C,"<=45627") -> 24 | J11: =SUM(F11:G11) -> 16 | K11: =SUM(F2:G11)/M11 -> 12.4 | L11: =AVERAGE($H$2:H11) -> 12.4 | M11: 10
A12: 2024W49 | B12: =LEFT(A12,4) -> 2024 | C12: =RIGHT(A12,2) -> 49 | D12: =D11+7 -> 45628 | E12: =D12+6 -> 45634 | F12: 1 | G12: 13 | H12: =F12+G12 -> 14 | I12: =COUNTIF('Fonte de Dados - Essentia'!C:C,"<=45634") -> 26 | J12: =SUM(F12:G12) -> 14 | K12: =SUM(F2:G12)/M12 -> 12.545455 | L12: =AVERAGE($H$2:H12) -> 12.545455 | M12: 11
A13: 2024W50 | B13: =LEFT(A13,4) -> 2024 | C13: =RIGHT(A13,2) -> 50 | D13: =D12+7 -> 45635 | E13: =D13+6 -> 45641 | F13: 1 | G13: 13 | H13: =F13+G13 -> 14 | I13: =COUNTIF('Fonte de Dados - Essentia'!C:C,"<=45641") -> 26 | J13: =SUM(F13:G13) -> 14 | K13: =SUM(F2:G13)/M13 -> 12.666667 | L13: =AVERAGE($H$2:H13) -> 12.666667 | M13: 12
A14: 2024W51 | B14: =LEFT(A14,4) -> 2024 | C14: =RIGHT(A14,2) -> 51 | D14: =D13+7 -> 45642 | E14: =D14+6 -> 45648 | F14: 1 | G14: 12 | H14: =F14+G14 -> 13 | I14: =COUNTIF('Fonte de Dados - Essentia'!C:C,"<=45648") -> 27 | J14: =SUM(F14:G14) -> 13 | K14: =SUM(F2:G14)/M14 -> 12.692308 | L14: =AVERAGE($H$2:H14) -> 12.692308 | M14: 13
A15: 2024W52 | B15: =LEFT(A15,4) -> 2024 | C15: =RIGHT(A15,2) -> 52 | D15: =D14+7 -> 45649 | E15: =D15+6 -> 45655 | F15: 1 | G15: 11 | H15: =F15+G15 -> 12 | I15: =COUNTIF('Fonte de Dados - Essentia'!C:C,"<=45655") -> 30 | J15: =SUM(F15:G15) -> 12 | K15: =SUM(F2:G15)/M15 -> 12.642857 | L15: =AVERAGE($H$2:H15) -> 12.642857 | M15: 14
A16: 2025W01 | B16: =LEFT(A16,4) -> 2025 | C16: =RIGHT(A16,2) -> 01 | D16: =D15+7 -> 45656 | E16: =D16+6 -> 45662 | F16: 2 | G16: 10 | H16: =F16+G16 -> 12 | I16: =COUNTIF('Fonte de Dados - Essentia'!C:C,"<=45662") -> 32 | J16: =SUM(F16:G16) -> 12 | K16: =SUM(F2:G16)/M16 -> 12.6 | L16: =AVERAGE(H16) -> 12 | M16: 15
A17: 2025W02 | B17: =LEFT(A17,4) -> 2025 | C17: =RIGHT(A17,2) -> 02 | D17: =D16+7 -> 45663 | E17: =D17+6 -> 45669 | F17: 2 | G17: 9 | H17: =F17+G17 -> 11 | I17: =COUNTIF('Fonte de Dados - Essentia'!C:C,"<=45669") -> 33 | J17: =SUM(F17:G17) -> 11 | K17: =SUM(F2:G17)/M17 -> 12.5 | L17: =AVERAGE($H$16:H17) -> 11.5 | M17: 16
A18: 2025W03 | B18: =LEFT(A18,4) -> 2025 | C18: =RIGHT(A18,2) -> 03 | D18: =D17+7 -> 45670 | E18: =D18+6 -> 45676 | F18: 2 | G18: 11 | H18: =F18+G18 -> 13 | I18: =COUNTIF('Fonte de Dados - Essentia'!C:C,"<=45676") -> 34 | J18: =SUM(F18:G18) -> 13 | K18: =SUM(F2:G18)/M18 -> 12.529412 | L18: =AVERAGE($H$16:H18) -> 12 | M18: 17
A19: 2025W04 | B19: =LEFT(A19,4) -> 2025 | C19: =RIGHT(A19,2) -> 04 | D19: =D18+7 -> 45677 | E19: =D19+6 -> 45683 | F19: 3 | G19: 12 | H19: =F19+G19 -> 15 | I19: =COUNTIF('Fonte de Dados - Essentia'!C:C,"<=45683") -> 35 | J19: =SUM(F19:G19) -> 15 | K19: =SUM(F2:G19)/M19 -> 12.666667 | L19: =AVERAGE($H$16:H19) -> 12.75 | M19: 18
A20: 2025W05 | B20: =LEFT(A20,4) -> 2025 | C20: =RIGHT(A20,2) -> 05 | D20: =D19+7 -> 45684 | E20: =D20+6 -> 45690 | F20: 3 | G20: 12 | H20: =F20+G20 -> 15 | I20: =COUNTIF('Fonte de Dados - Essentia'!C:C,"<=45690") -> 36 | J20: =SUM(F20:G20) -> 15 | K20: =SUM(F2:G20)/M20 -> 12.789474 | L20: =AVERAGE($H$16:H20) -> 13.2 | M20: 19
A21: 2025W06 | B21: =LEFT(A21,4) -> 2025 | C21: =RIGHT(A21,2) -> 06 | D21: =D20+7 -> 45691 | E21: =D21+6 -> 45697 | F21: 3 | G21: 10 | H21: =F21+G21 -> 13 | I21: =COUNTIF('Fonte de Dados - Essentia'!C:C,"<=45697") -> 43 | J21: =SUM(F21:G21) -> 13 | K21: =SUM(F2:G21)/M21 -> 12.8 | L21: =AVERAGE($H$16:H21) -> 13.166667 | M21: 20
A22: 2025W07 | B22: =LEFT(A22,4) -> 2025 | C22: =RIGHT(A22,2) -> 07 | D22: =D21+7 -> 45698 | E22: =D22+6 -> 45704 | F22: 3 | G22: 15 | H22: =F22+G22 -> 18 | I22: =COUNTIF('Fonte de Dados - Essentia'!C:C,"<=45704") -> 44 | J22: =SUM(F22:G22) -> 18 | K22: =SUM(F2:G22)/M22 -> 13.047619 | L22: =AVERAGE($H$16:H22) -> 13.857143 | M22: 21
A23: 2025W08 | B23: =LEFT(A23,4) -> 2025 | C23: =RIGHT(A23,2) -> 08 | D23: =D22+7 -> 45705 | E23: =D23+6 -> 45711 | F23: 2 | G23: 13 | H23: =F23+G23 -> 15 | I23: =COUNTIF('Fonte de Dados - Essentia'!C:C,"<=45711") -> 49 | J23: =SUM(F23:G23) -> 15 | K23: =SUM(F2:G23)/M23 -> 13.136364 | L23: =AVERAGE($H$16:H23) -> 14 | M23: 22
A24: 2025W09 | B24: =LEFT(A24,4) -> 2025 | C24: =RIGHT(A24,2) -> 09 | D24: =D23+7 -> 45712 | E24: =D24+6 -> 45718 | F24: 2 | G24: 12 | H24: =F24+G24 -> 14 | I24: =COUNTIF('Fonte de Dados - Essentia'!C:C,"<=45718") -> 53 | J24: =SUM(F24:G24) -> 14 | K24: =SUM(F2:G24)/M24 -> 13.173913 | L24: =AVERAGE($H$16:H24) -> 14 | M24: 23
A25: 2025W10 | B25: =LEFT(A25,4) -> 2025 | C25: =RIGHT(A25,2) -> 10 | D25: =D24+7 -> 45719 | E25: =D25+6 -> 45725 | F25: 2 | G25: 11 | H25: =F25+G25 -> 13 | I25: =COUNTIF('Fonte de Dados - Essentia'!C:C,"<=45725") -> 55 | J25: =SUM(F25:G25) -> 13 | K25: =SUM(F2:G25)/M25 -> 13.166667 | L25: =AVERAGE($H$16:H25) -> 13.9 | M25: 24
A26: 2025W11 | B26: =LEFT(A26,4) -> 2025 | C26: =RIGHT(A26,2) -> 11 | D26: =D25+7 -> 45726 | E26: =D26+6 -> 45732 | F26: 2 | G26: 10 | H26: =F26+G26 -> 12 | I26: =COUNTIF('Fonte de Dados - Essentia'!C:C,"<=45732") -> 57 | J26: =SUM(F26:G26) -> 12 | K26: =SUM(F2:G26)/M26 -> 13.12 | L26: =AVERAGE($H$16:H26) -> 13.727273 | M26: 25
A27: 2025W12 | B27: =LEFT(A27,4) -> 2025 | C27: =RIGHT(A27,2) -> 12 | D27: =D26+7 -> 45733 | E27: =D27+6 -> 45739 | F27: 2 | G27: 12 | H27: =F27+G27 -> 14 | I27: =COUNTIF('Fonte de Dados - Essentia'!C:C,"<=45739") -> 60 | J27: =SUM(F27:G27) -> 14 | K27: =SUM(F2:G27)/M27 -> 13.153846 | L27: =AVERAGE($H$16:H27) -> 13.75 | M27: 26
A28: 2025W13 | B28: =LEFT(A28,4) -> 2025 | C28: =RIGHT(A28,2) -> 13 | D28: =D27+7 -> 45740 | E28: =D28+6 -> 45746 | F28: 2 | G28: 11 | H28: =F28+G28 -> 13 | I28: =COUNTIF('Fonte de Dados - Essentia'!C:C,"<=45746") -> 61 | J28: =SUM(F28:G28) -> 13 | K28: =SUM(F2:G28)/M28 -> 13.148148 | L28: =AVERAGE($H$16:H28) -> 13.692308 | M28: 27
A29: 2025W14 | B29: =LEFT(A29,4) -> 2025 | C29: =RIGHT(A29,2) -> 14 | D29: =D28+7 -> 45747 | E29: =D29+6 -> 45753 | F29: 2 | G29: 10 | H29: =F29+G29 -> 12 | I29: =COUNTIF('Fonte de Dados - Essentia'!C:C,"<=45753") -> 62 | J29: =SUM(F29:G29) -> 12 | K29: =SUM(F2:G29)/M29 -> 13.107143 | L29: =AVERAGE($H$16:H29) -> 13.571429 | M29: 28
A30: 2025W15 | B30: =LEFT(A30,4) -> 2025 | C30: =RIGHT(A30,2) -> 15 | D30: =D29+7 -> 45754 | E30: =D30+6 -> 45760 | F30: 2 | G30: 11 | H30: =F30+G30 -> 13 | I30: =COUNTIF('Fonte de Dados - Essentia'!C:C,"<=45760") -> 65 | J30: =SUM(F30:G30) -> 13 | K30: =SUM(F2:G30)/M30 -> 13.103448 | L30: =AVERAGE($H$16:H30) -> 13.533333 | M30: 29
A31: 2025W16 | B31: =LEFT(A31,4) -> 2025 | C31: =RIGHT(A31,2) -> 16 | D31: =D30+7 -> 45761 | E31: =D31+6 -> 45767 | F31: 2 | G31: 12 | H31: =F31+G31 -> 14 | I31: =COUNTIF('Fonte de Dados - Essentia'!C:C,"<=45767") -> 69 | J31: =SUM(F31:G31) -> 14 | K31: =SUM(F2:G31)/M31 -> 13.133333 | L31: =AVERAGE($H$16:H31) -> 13.5625 | M31: 30
A32: 2025W17 | B32: =LEFT(A32,4) -> 2025 | C32: =RIGHT(A32,2) -> 17 | D32: =D31+7 -> 45768 | E32: =D32+6 -> 45774 | F32: 1 | G32: 15 | H32: =F32+G32 -> 16 | I32: =COUNTIF('Fonte de Dados - Essentia'!C:C,"<=45774") -> 69 | J32: =SUM(F32:G32) -> 16 | K32: =SUM(F2:G32)/M32 -> 13.225806 | L32: =AVERAGE($H$16:H32) -> 13.705882 | M32: 31
A33: 2025W18 | B33: =LEFT(A33,4) -> 2025 | C33: =RIGHT(A33,2) -> 18 | D33: =D32+7 -> 45775 | E33: =D33+6 -> 45781 | F33: 1 | G33: 13 | H33: =F33+G33 -> 14 | I33: =COUNTIF('Fonte de Dados - Essentia'!C:C,"<=45781") -> 70 | J33: =SUM(F33:G33) -> 14 | K33: =SUM(F2:G33)/M33 -> 13.25 | L33: =AVERAGE($H$16:H33) -> 13.722222 | M33: 32
A34: 2025W19 | B34: =LEFT(A34,4) -> 2025 | C34: =RIGHT(A34,2) -> 19 | D34: =D33+7 -> 45782 | E34: =D34+6 -> 45788 | F34: 1 | G34: 13 | H34: =F34+G34 -> 14 | I34: =COUNTIF('Fonte de Dados - Essentia'!C:C,"<=45788") -> 72 | J34: =SUM(F34:G34) -> 14 | K34: =SUM(F3:G34)/M34 -> 13.030303 | L34: =AVERAGE($H$16:H34) -> 13.736842 | M34: 33
A35: 2025W20 | B35: =LEFT(A35,4) -> 2025 | C35: =RIGHT(A35,2) -> 20 | D35: =D34+7 -> 45789 | E35: =D35+6 -> 45795 | F35: 0 | G35: 9 | H35: =F35+G35 -> 9 | I35: =COUNTIF('Fonte de Dados - Essentia'!C:C,"<=45795") -> 74 | J35: =SUM(F35:G35) -> 9 | K35: =SUM(F2:G35)/M35 -> 13.147059 | L35: =AVERAGE($H$16:H35) -> 13.5 | M35: 34
A36: 2025W21 | B36: =LEFT(A36,4) -> 2025 | C36: =RIGHT(A36,2) -> 21 | D36: =D35+7 -> 45796 | E36: =D36+6 -> 45802 | F36: 1 | G36: 10 | H36: =F36+G36 -> 11 | I36: =COUNTIF('Fonte de Dados - Essentia'!C:C,"<=45802") -> 76 | J36: =SUM(F36:G36) -> 11 | K36: =SUM(F2:G36)/M36 -> 13.085714 | L36: =AVERAGE($H$16:H36) -> 13.380952 | M36: 35
A37: 2025W22 | B37: =LEFT(A37,4) -> 2025 | C37: =RIGHT(A37,2) -> 22 | D37: =D36+7 -> 45803 | E37: =D37+6 -> 45809 | F37: 1 | G37: 11 | H37: =F37+G37 -> 12 | I37: =COUNTIF('Fonte de Dados - Essentia'!C:C,"<=45809") -> 76 | J37: =SUM(F37:G37) -> 12 | K37: =SUM(F2:G37)/M37 -> 13.055556 | L37: =AVERAGE($H$16:H37) -> 13.318182 | M37: 36
A38: 2025W23 | B38: =LEFT(A38,4) -> 2025 | C38: =RIGHT(A38,2) -> 23 | D38: =D37+7 -> 45810 | E38: =D38+6 -> 45816 | F38: 2 | G38: 9 | H38: =F38+G38 -> 11 | I38: =COUNTIF('Fonte de Dados - Essentia'!C:C,"<=45816") -> 78 | J38: =SUM(F38:G38) -> 11 | K38: =SUM(F2:G38)/M38 -> 13 | L38: =AVERAGE($H$16:H38) -> 13.217391 | M38: 37
A39: 2025W24 | B39: =LEFT(A39,4) -> 2025 | C39: =RIGHT(A39,2) -> 24 | D39: =D38+7 -> 45817 | E39: =D39+6 -> 45823 | F39: 1 | G39: 10 | H39: =F39+G39 -> 11 | I39: =COUNTIF('Fonte de Dados - Essentia'!C:C,"<=45823") -> 87 | J39: =SUM(F39:G39) -> 11 | K39: =SUM(F2:G39)/M39 -> 12.947368 | L39: =AVERAGE($H$16:H39) -> 13.125 | M39: 38
A40: 2025W25 | B40: =LEFT(A40,4) -> 2025 | C40: =RIGHT(A40,2) -> 25 | D40: =D39+7 -> 45824 | E40: =D40+6 -> 45830 | F40: 1 | G40: 16 | H40: =F40+G40 -> 17 | I40: =COUNTIF('Fonte de Dados - Essentia'!C:C,"<=45830") -> 87 | J40: =SUM(F40:G40) -> 17 | K40: =SUM(F2:G40)/M40 -> 13.051282 | L40: =AVERAGE($H$16:H40) -> 13.28 | M40: 39
...

Sheet Fonte de Dados - Essentia
H1: Stopped Turbines +7 days - Essentia
C2: Data hoje | F2: =TODAY() -> 46290
A3: Site | B3: WTG | C3: Data da parada | D3: Data de retorno | E3: Status | F3: Dias parada | G3: Previsão de Retorno | H3: Motivo | I3: Componente/Subsistema | J3: Brief Description | K3: Ação Pendente / Comentários | L3: %MCE | M3: Responsável pelas Ações | N3: Responsável | O3: Responsável pela Disponibilidade | P3: Horas paradas | Q3: Indisponibilidade TB | R3: 45292
A4: Chapada I | B4: JOA13-15 | C4: 45610 | D4: 45610 | E4: Rodando | F4: =IF(D4="",TODAY()-C4,"-") -> - | G4: 45610 | H4: Falha de safety chain. | I4: Troubleshooting | J4: Troubleshooting | K4: Troubleshooting da falha. | M4: Operations - O&M | N4: Warton e Anderson | O4: Invenergy | P4: =IF(O4="Invenergy",IF(F4="-",(D4-C4)*24,F4*24),0) -> 0 | Q4: =P4/VLOOKUP(A4,'YTD Hours'!$A$2:$D$5,4,0) -> 0 | R4: =(C4-$R$3)/7 -> 45.428571 | S4: =IF(D4=0,"",(D4-$R$3)/7) -> 45.428571 | T4: 1
A5: Asa Branca | B5: AB05-13 | C5: 45609 | D5: 45611 | E5: Rodando | F5: =IF(D5="",TODAY()-C5,"-") -> - | G5: 45611 | H5: Turbina não passa no teste de baterias do sistema de pitch. | I5: Pitch Battery | J5: Troubleshooting | K5: Troubleshooting da falha e suporte da engenharia. | M5: Engenharia | N5: Daniel | O5: Invenergy | P5: =IF(O5="Invenergy",IF(F5="-",(D5-C5)*24,F5*24),0) -> 48 | Q5: =P5/VLOOKUP(A5,'YTD Hours'!$A$2:$D$5,4,0) -> 2.7624309e-05 | R5: =(C5-$R$3)/7 -> 45.285714 | S5: =IF(D5=0,"",(D5-$R$3)/7) -> 45.571429 | T5: 1
A6: Chapada II | B6: JOA01-12 | C6: 45607 | D6: 45612 | E6: Rodando | F6: =IF(D6="",TODAY()-C6,"-") -> - | G6: 45610 | H6: Falha de baterias na axis 1. WEPA da axis 1 está danificada. Estamos utilizando WEPAs reparadas e baterias novas. | I6: Pitch Battery | J6: UPTOWER REPAIR | K6: Troca da WEPA. | M6: Operations - O&M | N6: Warton e Anderson | O6: Invenergy | P6: =IF(O6="Invenergy",IF(F6="-",(D6-C6)*24,F6*24),0) -> 120 | Q6: =P6/VLOOKUP(A6,'YTD Hours'!$A$2:$D$5,4,0) -> 6.9060773e-05 | R6: =(C6-$R$3)/7 -> 45 | S6: =IF(D6=0,"",(D6-$R$3)/7) -> 45.714286 | T6: 1
A7: Asa Branca | B7: AB06-06 | C7: 45606 | D7: 45613 | E7: Rodando | F7: =IF(D7="",TODAY()-C7,"-") -> - | G7: 45610 | H7: Turbina não passa no teste de baterias do sistema de pitch. | I7: Pitch Battery | J7: Troubleshooting | K7: Troubleshooting da falha com suporte da engenharia. | M7: Engenharia | N7: Victor e Daniel | O7: Invenergy | P7: =IF(O7="Invenergy",IF(F7="-",(D7-C7)*24,F7*24),0) -> 168 | Q7: =P7/VLOOKUP(A7,'YTD Hours'!$A$2:$D$5,4,0) -> 9.6685083e-05 | R7: =(C7-$R$3)/7 -> 44.857143 | S7: =IF(D7=0,"",(D7-$R$3)/7) -> 45.857143 | T7: 1
A8: Chapada II | B8: JOA04-14 | C8: 45600 | D8: 45616 | E8: Rodando | F8: =IF(D8="",TODAY()-C8,"-") -> - | G8: 45615 | H8: Danos no gerador, curto no wye ring. | I8: Gerador | J8: UPTOWER REPAIR | K8: Reparo do gerador em andamento. | M8: Operations - O&M | N8: Warton e Anderson | O8: Essentia | P8: =IF(O8="Invenergy",IF(F8="-",(D8-C8)*24,F8*24),0) -> 0 | Q8: =P8/VLOOKUP(A8,'YTD Hours'!$A$2:$D$5,4,0) -> 0 | R8: =(C8-$R$3)/7 -> 44 | S8: =IF(D8=0,"",(D8-$R$3)/7) -> 46.285714 | T8: 1
A9: Chapada II | B9: JOA03-06 | C9: 45615 | D9: 45618 | E9: Rodando | F9: =IF(D9="",TODAY()-C9,"-") -> - | G9: 45618 | H9: Quebra da barra de suporte da axis box. | I9: Pitch Axis Box | J9: UPTOWER REPAIR | K9: Sendo realizada a ação corretiva sugerida pela Essentia. Não temos disponível a peça sugerida para a correção, iremos canibalizar outra turbina (AUG 05-13) para reparar a barra danificada com o novo coxim. SS aberta para suporte da engenharia para entendendermos a causa raiz da falha. | M9: Operations - O&M / Engenharia | O9: Invenergy | P9: =IF(O9="Invenergy",IF(F9="-",(D9-C9)*24,F9*24),0) -> 72 | Q9: =P9/VLOOKUP(A9,'YTD Hours'!$A$2:$D$5,4,0) -> 4.1436464e-05 | R9: =(C9-$R$3)/7 -> 46.142857 | S9: =IF(D9=0,"",(D9-$R$3)/7) -> 46.571429 | T9: 1
A10: Chapada I | B10: JOA11-10 | C10: 45566 | D10: 45622 | E10: Rodando | F10: =IF(D10="",TODAY()-C10,"-") -> - | G10: 45607 | H10: Troca de Gearbox. | I10: Gearbox | J10: MCE | K10: Aguardando MCE. | M10: Operations - FSO | N10: Essentia | O10: Essentia | P10: =IF(O10="Invenergy",IF(F10="-",(D10-C10)*24,F10*24),0) -> 0 | Q10: =P10/VLOOKUP(A10,'YTD Hours'!$A$2:$D$5,4,0) -> 0 | R10: =(C10-$R$3)/7 -> 39.142857 | S10: =IF(D10=0,"",(D10-$R$3)/7) -> 47.142857 | T10: 1
A11: Chapada I | B11: JOA11-14 | C11: 45566 | D11: 45622 | E11: Rodando | F11: =IF(D11="",TODAY()-C11,"-") -> - | G11: 45618 | H11: Troca de Gerador. | I11: Gerador | K11: Aguardando MCE. | M11: Operations - FSO | N11: Essentia | O11: Essentia | P11: =IF(O11="Invenergy",IF(F11="-",(D11-C11)*24,F11*24),0) -> 0 | Q11: =P11/VLOOKUP(A11,'YTD Hours'!$A$2:$D$5,4,0) -> 0 | R11: =(C11-$R$3)/7 -> 39.142857 | S11: =IF(D11=0,"",(D11-$R$3)/7) -> 47.142857 | T11: 1
A12: Chapada III | B12: AUG05-12 | C12: 45601 | D12: 45624 | E12: Rodando | F12: =IF(D12="",TODAY()-C12,"-") -> - | G12: 45625 | H12: Pitch controller colective fault. | I12: Pitch System | J12: Troubleshooting | K12: Troubleshooting da falha. Motivos de força maior impactaram no atendimento da turbina. Já foi tentando várias soluções e não deram certo. Foi feita a troca do cabo de controle da axis cabinet. Está sendo feita a verificação do sistema de freios das axis hoje (21/11). SS aberta (18/11) solicitando suporte da Engenharia. Sendo realizada a formatação e upload do parâmetros na UCSA. Troca dos componentes não teriam sido necessárias se tivéssemos os privilégios master de acesso ao SCADA. | M12: Operations - O&M / Engenharia | N12: Warton e Anderson | O12: Invenergy | P12: =IF(O12="Invenergy",IF(F12="-",(D12-C12)*24,F12*24),0) -> 552 | Q12: =P12/VLOOKUP(A12,'YTD Hours'!$A$2:$D$5,4,0) -> 0.00099274862 | R12: =(C12-$R$3)/7 -> 44.142857 | S12: =IF(D12=0,"",(D12-$R$3)/7) -> 47.428571 | T12: 1
A13: Chapada I | B13: JOA12-17 | C13: 45567 | D13: 45625 | E13: Rodando | F13: =IF(D13="",TODAY()-C13,"-") -> - | G13: 45625 | H13: Reparo executado no wye ring do gerador, porém, apresentou falha de fuga de corrente no terra. | I13: Gerador | J13: UPTOWER REPAIR | K13: Trenders foram coletados e analisados. Foram realizadas novas medições, as quais não mostraram anomalias, então o gerador foi reaberto e identificado danos no wye ring. Reparo já está sendo feito (solda do ponto, limpeza entre espiras e reparo do isolamento. | M13: Operations - O&M | N13: Victor, Warton e Anderson | O13: Essentia | P13: =IF(O13="Invenergy",IF(F13="-",(D13-C13)*24,F13*24),0) -> 0 | Q13: =P13/VLOOKUP(A13,'YTD Hours'!$A$2:$D$5,4,0) -> 0 | R13: =(C13-$R$3)/7 -> 39.285714 | S13: =IF(D13=0,"",(D13-$R$3)/7) -> 47.571429 | T13: 1
A14: Chapada I | B14: JOA12-04 | C14: 45566 | D14: 45632 | E14: Rodando | F14: =IF(D14="",TODAY()-C14,"-") -> - | G14: 45625 | H14: Troca de Gerador. Aguardando MCE. | I14: Gerador | K14: Aguardando MCE. | M14: Operations - FSO | N14: Essentia | O14: Essentia | P14: =IF(O14="Invenergy",IF(F14="-",(D14-C14)*24,F14*24),0) -> 0 | Q14: =P14/VLOOKUP(A14,'YTD Hours'!$A$2:$D$5,4,0) -> 0 | R14: =(C14-$R$3)/7 -> 39.142857 | S14: =IF(D14=0,"",(D14-$R$3)/7) -> 48.571429 | T14: 1
A15: Chapada II | B15: JOA07-06 | C15: 45566 | D15: 45637 | E15: Rodando | F15: =IF(D15="",TODAY()-C15,"-") -> - | G15: 45632 | H15: Danos no gerador, curto no wye ring. | I15: Gerador | K15: Reparo do wye ring sendo executado. Previsão de finalização 06/12. Alertas de raios impactando a execução do reparo. Reparo só iniciado com a chegada no material no almoxarifado (conjunto de barras das fases do rotor). Reparo iniciou no dia 02/12 após a finalização de outro reparo em outra turbina. | M15: Operations - O&M | N15: Essentia | O15: Essentia | P15: =IF(O15="Invenergy",IF(F15="-",(D15-C15)*24,F15*24),0) -> 0 | Q15: =P15/VLOOKUP(A15,'YTD Hours'!$A$2:$D$5,4,0) -> 0 | R15: =(C15-$R$3)/7 -> 39.142857 | S15: =IF(D15=0,"",(D15-$R$3)/7) -> 49.285714 | T15: 1
A16: Asa Branca | B16: AB06-08 | C16: 45607 | D16: 45637 | E16: Rodando | F16: =IF(D16="",TODAY()-C16,"-") -> - | G16: 45637 | H16: Danos no gerador, curto no wye ring. | I16: Gerador | J16: UPTOWER REPAIR | K16: Executando reparo do wye ring. | M16: Operations - O&M | N16: Marcelo Lins | O16: Essentia | P16: =IF(O16="Invenergy",IF(F16="-",(D16-C16)*24,F16*24),0) -> 0 | Q16: =P16/VLOOKUP(A16,'YTD Hours'!$A$2:$D$5,4,0) -> 0 | R16: =(C16-$R$3)/7 -> 45 | S16: =IF(D16=0,"",(D16-$R$3)/7) -> 49.285714 | T16: 1
A17: Chapada I | B17: JOA12-16 | C17: 45614 | D17: 45645 | E17: Rodando | F17: =IF(D17="",TODAY()-C17,"-") -> - | G17: 45646 | H17: Gerador com curto de corrente para o terra. Aguardando MCE. | I17: Gerador | J17: MCE | K17: Aguardando MCE. Identificar a causa raiz da falha (se falha de rolamento ou não). | M17: Operations - FSO / Engenharia | O17: Invenergy | P17: =IF(O17="Invenergy",IF(F17="-",(D17-C17)*24,F17*24),0) -> 744 | Q17: =P17/VLOOKUP(A17,'YTD Hours'!$A$2:$D$5,4,0) -> 0.00037232765 | R17: =(C17-$R$3)/7 -> 46 | S17: =IF(D17=0,"",(D17-$R$3)/7) -> 50.428571 | T17: 1
A18: Chapada I | B18: JOA12-11 | C18: 45595 | D18: 45646 | E18: Rodando | F18: =IF(D18="",TODAY()-C18,"-") -> - | G18: 45646 | H18: MCE concluída. Corretiva pendente | I18: Pitch Bearing | J18: Troubleshooting | K18: Corretiva sendo executada de calibração de pá. | M18: Operations - O&M | N18: Samir e FSO/Essentia | O18: Invenergy | P18: =IF(O18="Invenergy",IF(F18="-",(D18-C18)*24,F18*24),0) -> 1224 | Q18: =P18/VLOOKUP(A18,'YTD Hours'!$A$2:$D$5,4,0) -> 0.00061253903 | R18: =(C18-$R$3)/7 -> 43.285714 | S18: =IF(D18=0,"",(D18-$R$3)/7) -> 50.571429 | T18: 1
A19: Chapada II | B19: JOA05-05 | C19: 45581 | D19: 45652 | E19: Rodando | F19: =IF(D19="",TODAY()-C19,"-") -> - | G19: 45652 | H19: MCE concluída. Corretivas pendentes. | I19: Top Box | J19: UPTOWER REPAIR | K19: Corretiva sendo executada hoje. Houveram danos nos IGBTs de linha e de rotor, falha na unidade hidráulica de freio, ligação do cabo de fase estava para o terra, motores de yaw fora da posição e baixo nível de óleo na gearbox. | M19: Operations - O&M | N19: Samir e FSO | O19: Invenergy | P19: =IF(O19="Invenergy",IF(F19="-",(D19-C19)*24,F19*24),0) -> 1704 | Q19: =P19/VLOOKUP(A19,'YTD Hours'!$A$2:$D$5,4,0) -> 0.00098066298 | R19: =(C19-$R$3)/7 -> 41.285714 | S19: =IF(D19=0,"",(D19-$R$3)/7) -> 51.428571 | T19: 1
A20: Chapada I | B20: JOA11-12 | C20: 45643 | D20: 45659 | E20: Rodando | F20: =IF(D20="",TODAY()-C20,"-") -> - | G20: 45660 | H20: Dano no wye ring. | I20: Gerador | J20: UPTOWER REPAIR | K20: Reparo do wye ring sendo executado. | M20: Essentia | N20: Essentia | O20: Essentia | P20: =IF(O20="Invenergy",IF(F20="-",(D20-C20)*24,F20*24),0) -> 0 | Q20: =P20/VLOOKUP(A20,'YTD Hours'!$A$2:$D$5,4,0) -> 0 | R20: =(C20-$R$3)/7 -> 50.142857 | S20: =IF(D20=0,"",(D20-$R$3)/7) -> 52.428571 | T20: 1
A21: Chapada I | B21: JOA10-04 | C21: 45633 | D21: 45665 | E21: Rodando | F21: =IF(D21="",TODAY()-C21,"-") -> - | G21: 45660 | H21: Danos no gerador, curto no wye ring e cabo de releed. | I21: Gerador | J21: UPTOWER REPAIR | K21: Reparo do gerador finalizado. Corretiva em execução. Surge test já realizado. Cabos sendo desinvertivos e irá retornar 03/01. | M21: Operations - O&M | O21: Essentia | P21: =IF(O21="Invenergy",IF(F21="-",(D21-C21)*24,F21*24),0) -> 0 | Q21: =P21/VLOOKUP(A21,'YTD Hours'!$A$2:$D$5,4,0) -> 0 | R21: =(C21-$R$3)/7 -> 48.714286 | S21: =IF(D21=0,"",(D21-$R$3)/7) -> 53.285714 | T21: 1
A22: Chapada I | B22: JOA11-11 | C22: 45652 | D22: 45665 | E22: Rodando | F22: =IF(D22="",TODAY()-C22,"-") -> - | H22: Falhas nas baterias de pitch devido à danos no rolamento. | I22: Pitch Bearing | J22: UPTOWER REPAIR | K22: Emissão de disposição da engenharia. Aguardando atividade em campo. Atividade executada e trocado o freio do motor de pitch. | M22: Engenharia | O22: Invenergy | P22: =IF(O22="Invenergy",IF(F22="-",(D22-C22)*24,F22*24),0) -> 312 | Q22: =P22/VLOOKUP(A22,'YTD Hours'!$A$2:$D$5,4,0) -> 0.0001561374 | R22: =(C22-$R$3)/7 -> 51.428571 | S22: =IF(D22=0,"",(D22-$R$3)/7) -> 53.285714 | T22: 1
A23: Chapada II | B23: JOA04-03 | C23: 45659 | D23: 45666 | E23: Rodando | F23: =IF(D23="",TODAY()-C23,"-") -> - | H23: 2 Yaw drives danificados (Nanjing). | I23: Yaw Drive | J23: UPTOWER REPAIR | K23: Reparo sendo feito. Foi danificado o 1º e o 2º estágio dos yaw drives (um dente quebrado em cada estágio). | M23: Operations - O&M | O23: Invenergy | P23: =IF(O23="Invenergy",IF(F23="-",(D23-C23)*24,F23*24),0) -> 168 | Q23: =P23/VLOOKUP(A23,'YTD Hours'!$A$2:$D$5,4,0) -> 9.6685083e-05 | R23: =(C23-$R$3)/7 -> 52.428571 | S23: =IF(D23=0,"",(D23-$R$3)/7) -> 53.428571 | T23: 1
A24: Chapada III | B24: AUG05-14 | C24: 45678 | D24: 45685 | E24: Rodando | F24: =IF(D24="",TODAY()-C24,"-") -> - | H24: Falha no conversor. | I24: Gerador | J24: UPTOWER REPAIR | K24: Falha no conversor. Foi trocado a WECA, porém, a turbina não startou. Time desconfiando de dano no gerador. Troubleshooting da falha pendente. Atendimento está sendo impactado pela incidência frequente de L2. | M24: Operations - O&M | O24: Invenergy | P24: =IF(O24="Invenergy",IF(F24="-",(D24-C24)*24,F24*24),0) -> 168 | Q24: =P24/VLOOKUP(A24,'YTD Hours'!$A$2:$D$5,4,0) -> 0.00030214088 | R24: =(C24-$R$3)/7 -> 55.142857 | S24: =IF(D24=0,"",(D24-$R$3)/7) -> 56.142857 | T24: 1
A25: Chapada I | B25: JOA15-16 | C25: 45664 | D25: 45687 | E25: Rodando | F25: =IF(D25="",TODAY()-C25,"-") -> - | H25: Dano no pitch bearing. Realizando MCE. | I25: Pitch Bearing | J25: MCE | K25: Parada para troca do Pitch Bearing. Pós work em andamento. | M25: Operations - FSO | O25: Invenergy | P25: =IF(O25="Invenergy",IF(F25="-",(D25-C25)*24,F25*24),0) -> 552 | Q25: =P25/VLOOKUP(A25,'YTD Hours'!$A$2:$D$5,4,0) -> 0.00027624309 | R25: =(C25-$R$3)/7 -> 53.142857 | S25: =IF(D25=0,"",(D25-$R$3)/7) -> 56.428571 | T25: 1
A26: Chapada I | B26: JOA15-01 | C26: 45618 | D26: 45693 | E26: Rodando | F26: =IF(D26="",TODAY()-C26,"-") -> - | H26: Danos na gearbox. Aguardando MCE. | I26: Gearbox | J26: MCE | K26: Engenharia enviou a disposição solicitando a parada da turbina e troca da gearbox. | M26: Operations - FSO | O26: Invenergy | P26: =IF(O26="Invenergy",IF(F26="-",(D26-C26)*24,F26*24),0) -> 1800 | Q26: =P26/VLOOKUP(A26,'YTD Hours'!$A$2:$D$5,4,0) -> 0.0009007927 | R26: =(C26-$R$3)/7 -> 46.571429 | S26: =IF(D26=0,"",(D26-$R$3)/7) -> 57.285714 | T26: 1
A27: Asa Branca | B27: AB08-05 | C27: 45672 | D27: 45700 | E27: Rodando | F27: =IF(D27="",TODAY()-C27,"-") -> - | G27: 45708 | H27: Incidência de raio na blade. | I27: Blade | J27: UPTOWER REPAIR | K27: Reparo já foi concluído. Porém, time da Essentia segue trabalhando nela para voltar a operação. | M27: Essentia | O27: Essentia | P27: =IF(O27="Invenergy",IF(F27="-",(D27-C27)*24,F27*24),0) -> 0 | Q27: =P27/VLOOKUP(A27,'YTD Hours'!$A$2:$D$5,4,0) -> 0 | R27: =(C27-$R$3)/7 -> 54.285714 | S27: =IF(D27=0,"",(D27-$R$3)/7) -> 58.285714 | T27: 1
A28: Chapada I | B28: JOA15-15 | C28: 45630 | D28: 45701 | E28: Rodando | F28: =IF(D28="",TODAY()-C28,"-") -> - | H28: 2 Yaw drives danificados. | I28: Yaw Drive | J28: UPTOWER REPAIR | K28: Aguardando disponibilidade do yaw drive. Invenergy em contato com a DriveMec para alinhamento da melhor estratégia (gostaríamos de só fornecimento do porta planetas). 13/02: Previsão de retorno fim do dia de hoje. Foi instalado o 4º estágio nos dois 2 yaw drives danificados. 1 deles advindo da 16-06 e outro estava em estoque. | M28: Essentia | O28: Essentia | P28: =IF(O28="Invenergy",IF(F28="-",(D28-C28)*24,F28*24),0) -> 0 | Q28: =P28/VLOOKUP(A28,'YTD Hours'!$A$2:$D$5,4,0) -> 0 | R28: =(C28-$R$3)/7 -> 48.285714 | T28: 1
A29: Chapada I | B29: JOA16-09 | C29: 45626 | D29: 45702 | E29: Rodando | F29: =IF(D29="",TODAY()-C29,"-") -> - | H29: Danos na gearbox. Aguardando MCE. | I29: Gearbox | J29: MCE | K29: Aguardando MCE. MCE em andamento - atividade 80% concluída. | M29: Operations - FSO | O29: Invenergy | P29: =IF(O29="Invenergy",IF(F29="-",(D29-C29)*24,F29*24),0) -> 1824 | Q29: =P29/VLOOKUP(A29,'YTD Hours'!$A$2:$D$5,4,0) -> 0.00091280327 | R29: =(C29-$R$3)/7 -> 47.714286 | S29: =IF(D29=0,"",(D29-$R$3)/7) -> 58.571429 | T29: 1
A30: Chapada I | B30: JOA15-12 | C30: 45566 | D30: 45708 | E30: Rodando | F30: =IF(D30="",TODAY()-C30,"-") -> - | H30: Danos na gearbox e pitch bearing. Pendente MCE. | I30: Pitch Bearing | J30: MCE | K30: Atividade MCE concluída. Necessitará de corretiva após a finalização da troca do PB. Previsão de retorno hoje (20/02). | M30: Operations - FSO | N30: Essentia | O30: Essentia | P30: =IF(O30="Invenergy",IF(F30="-",(D30-C30)*24,F30*24),0) -> 0 | Q30: =P30/VLOOKUP(A30,'YTD Hours'!$A$2:$D$5,4,0) -> 0 | R30: =(C30-$R$3)/7 -> 39.142857 | S30: =IF(D30=0,"",(D30-$R$3)/7) -> 59.428571 | T30: 1
A31: Chapada I | B31: JOA12-12 | C31: 45660 | D31: 45708 | E31: Rodando | F31: =IF(D31="",TODAY()-C31,"-") -> - | H31: Gearbox colapsada. Aguardando MCE. | I31: Gearbox | J31: MCE | K31: Aguardando MCE. 90% de evolução. Pendente corretiva. | M31: Operations - FSO | N31: Invenergy | O31: Invenergy | P31: =IF(O31="Invenergy",IF(F31="-",(D31-C31)*24,F31*24),0) -> 1152 | Q31: =P31/VLOOKUP(A31,'YTD Hours'!$A$2:$D$5,4,0) -> 0.00057650733 | R31: =(C31-$R$3)/7 -> 52.571429 | S31: =IF(D31=0,"",(D31-$R$3)/7) -> 59.428571 | T31: 1
A32: Chapada I | B32: JOA12-08 | C32: 45566 | D32: 45714 | E32: Rodando | F32: =IF(D32="",TODAY()-C32,"-") -> - | H32: Reparo de pá feito. Aguardando MCE. | I32: Blade | J32: MCE | K32: Aguardando MCE. Reparo de blade concluído. Troca de pitch bearing concluída. Pós work em andamento. Será necessário passar por preventiva e por inspeções específicas para RTS pós longo tempo parada. Retornou a operação ontem 26/02. Será necessário inspeções a cada 3 dias (recomendação de engenharia). | M32: Operations - FSO | N32: Essentia | O32: Essentia | P32: =IF(O32="Invenergy",IF(F32="-",(D32-C32)*24,F32*24),0) -> 0 | Q32: =P32/VLOOKUP(A32,'YTD Hours'!$A$2:$D$5,4,0) -> 0 | R32: =(C32-$R$3)/7 -> 39.142857 | T32: 1
A33: Chapada I | B33: JOA15-10 | C33: 45710 | D33: 45716 | E33: Rodando | F33: =IF(D33="",TODAY()-C33,"-") -> - | H33: Vazamento de óleo da gearbox | I33: Gearbox | J33: UPTOWER REPAIR | K33: Máquina parou no final de semana por vazamento de óleo de 70% da gearbox. Sendo feito o atendimento à turbina para flushing e troca para o Amsoil. | M33: Operations - O&M | O33: Invenergy | P33: =IF(O33="Invenergy",IF(F33="-",(D33-C33)*24,F33*24),0) -> 144 | Q33: =P33/VLOOKUP(A33,'YTD Hours'!$A$2:$D$5,4,0) -> 7.2063416e-05 | R33: =(C33-$R$3)/7 -> 59.714286 | T33: 1
A34: Chapada III | B34: AUG03-15 | C34: 45714 | D34: 45717 | E34: Rodando | F34: =IF(D34="",TODAY()-C34,"-") -> - | H34: Vazamento de óleo da gearbox | I34: Gearbox | J34: UPTOWER REPAIR | K34: Máquina em atendimento, parou durante a madrugada. Troubleshooting. Sendo analisado se é possível a "transfusão do óleo", visto que não temos óleo Castrol em estoque. | M34: Operations - O&M / Engenharia | O34: Invenergy | P34: =IF(O34="Invenergy",IF(F34="-",(D34-C34)*24,F34*24),0) -> 72 | Q34: =P34/VLOOKUP(A34,'YTD Hours'!$A$2:$D$5,4,0) -> 0.00012948895 | R34: =(C34-$R$3)/7 -> 60.285714 | T34: 1
A35: Chapada I | B35: JOA11-07 | C35: 45686 | D35: 45721 | E35: Rodando | F35: =IF(D35="",TODAY()-C35,"-") -> - | H35: Danos da gearbox. Aguardando MCE. | I35: Gearbox | J35: MCE | K35: Aguardando MCE. 80% de evolução. | M35: Operations - FSO | O35: Essentia | P35: =IF(O35="Invenergy",IF(F35="-",(D35-C35)*24,F35*24),0) -> 0 | Q35: =P35/VLOOKUP(A35,'YTD Hours'!$A$2:$D$5,4,0) -> 0 | R35: =(C35-$R$3)/7 -> 56.285714 | T35: 1
A36: Chapada I | B36: JOA15-01 | C36: 45714 | D36: 45722 | E36: Rodando | F36: =IF(D36="",TODAY()-C36,"-") -> - | H36: Colapso do acoplamento flexível | I36: Flex coupling | J36: UPTOWER REPAIR | K36: Troca do acoplamento e slip de comunicação. Engenharia irá analisar se será necessário uma investigação mais profunda. 06/03: Troca do acoplamento completo quase finalizada. Previsão de retorno 06/03. | L36: - | M36: Operations - O&M / Engenharia | O36: Invenergy | P36: =IF(O36="Invenergy",IF(F36="-",(D36-C36)*24,F36*24),0) -> 192 | Q36: =P36/VLOOKUP(A36,'YTD Hours'!$A$2:$D$5,4,0) -> 9.6084554e-05 | R36: =(C36-$R$3)/7 -> 60.285714 | T36: 1
A37: Chapada II | B37: JOA01-13 | C37: 45708 | D37: 45727 | E37: Rodando | F37: =IF(D37="",TODAY()-C37,"-") -> - | H37: MCE programado. Pitch Bearing. Aguardando MCE | I37: Pitch Bearing | J37: MCE | K37: 80% de evolução. | L37: 0.8 | M37: Operations - FSO | O37: Essentia | P37: =IF(O37="Invenergy",IF(F37="-",(D37-C37)*24,F37*24),0) -> 0 | Q37: =P37/VLOOKUP(A37,'YTD Hours'!$A$2:$D$5,4,0) -> 0 | R37: =(C37-$R$3)/7 -> 59.428571 | T37: 1
A38: Chapada I | B38: JOA09-08 | C38: 45612 | D38: 45734 | E38: Rodando | F38: =IF(D38="",TODAY()-C38,"-") -> - | G38: 45752 | H38: Gearbox colapsada. Aguardando MCE. | I38: Gearbox | J38: MCE | K38: Boroscopia no main bearing sendo realizada para verificar se temos danos adicionais. Aguardando MCE. | L38: 1 | M38: Operations - FSO | O38: Essentia | P38: =IF(O38="Invenergy",IF(F38="-",(D38-C38)*24,F38*24),0) -> 0 | Q38: =P38/VLOOKUP(A38,'YTD Hours'!$A$2:$D$5,4,0) -> 0 | R38: =(C38-$R$3)/7 -> 45.714286 | T38: 1
A39: Chapada II | B39: JOA04-01 | C39: 45716 | D39: 45734 | E39: Rodando | F39: =IF(D39="",TODAY()-C39,"-") -> - | H39: Turbina com ramal baixo para troca do rolamento do pitch | I39: Pitch Bearing | J39: MCE | L39: 0 | M39: Operations - FSO | N39: Essentia | O39: 0 | P39: 0 | Q39: 61.571429 | S39: =IF(D39=0,"",(D39-$R$3)/7) -> 63.142857 | T39: 1
A40: Chapada I | B40: JOA16-02 | C40: 45721 | D40: 45737 | E40: Rodando | F40: =IF(D40="",TODAY()-C40,"-") -> - | G40: 45737 | H40: Colapso da Gearbox | I40: Gearbox | J40: MCE | K40: Aguardando MCE. Pós-work sendo realizado. | L40: 1 | M40: Operations - FSO | O40: Invenergy | P40: =IF(O40="Invenergy",IF(F40="-",(D40-C40)*24,F40*24),0) -> 384 | Q40: =P40/VLOOKUP(A40,'YTD Hours'!$A$2:$D$5,4,0) -> 0.00019216911 | R40: =(C40-$R$3)/7 -> 61.285714 | T40: 1
...

Sheet Planilha4
A3: WTGs paradas | B3: Year
A4: Week | B4: 2025 | C4: 2026
A5: 01 | B5: 12 | C5: 2
A6: 02 | B6: 11 | C6: 3
A7: 03 | B7: 13 | C7: 6
A8: 04 | B8: 15 | C8: 6
A9: 05 | B9: 15 | C9: 7
A10: 06 | B10: 13 | C10: 6
A11: 07 | B11: 18 | C11: 5
A12: 08 | B12: 15 | C12: 6
A13: 09 | B13: 14 | C13: 6
A14: 10 | B14: 13 | C14: 5
A15: 11 | B15: 12 | C15: 4
A16: 12 | B16: 14 | C16: 5
... A56: 52 | B56: 3 | C56: 0

Sheet Dashboard_Auren
I1: Stopped Turbines +7 days - Auren
J34: Quantidade de turbinas paradas - Auren | AJ34: Site | AK34: Alto Sertão 2 | AP34: Status | AQ34: Parada
I35: Quantidade de turbinas paradas | J35: =COUNTIFS('Fonte de Dados - Auren'!E:E,"Parada",'Fonte de Dados - Auren'!F:F,">=7") -> 3 | AJ35: Status | AK35: Parada | AP35: Dias parada | AQ35: (Tudo)
I36: % da frota | J36: =J35/237 -> 0.012658228 | AJ36: Dias parada | AK36: - | AP36: Site | AQ36: Caetés
J38: ALTO SERTÃO 2 | L38: CAETÉS | AJ38: Contagem de WTG | AK38: Rótulos de Coluna | AP38: Contagem de WTG | AQ38: Rótulos de Coluna
I39: Quantidade de turbinas paradas | J39: =COUNTIFS('Fonte de Dados - Auren'!$A:$A,"Alto Sertão 2",'Fonte de Dados - Auren'!$E:$E,"Parada",'Fonte de Dados - Auren'!$F:$F,">=7") -> 0 | L39: =COUNTIFS('Fonte de Dados - Auren'!$A:$A,"Caetés",'Fonte de Dados - Auren'!$E:$E,"Parada",'Fonte de Dados - Auren'!$F:$F,">=7") -> 3 | AJ39: Rótulos de Linha | AK39: Total Geral | AP39: Rótulos de Linha | AQ39: MCE | AR39: UPTOWER REPAIR | AS39: Total Geral
I40: % da frota | J40: =J39/130 -> 0 | L40: =L39/107 -> 0.028037383 | AJ40: Total Geral | AP40: Blade | AR40: 1 | AS40: 1
AP41: Gearbox | AQ41: 1 | AS41: 1
AP42: Pitch Bearing | AQ42: 1 | AS42: 1
AP43: Total Geral | AQ43: 2 | AR43: 1 | AS43: 3

Sheet Fonte de Dados - Auren
H1: Stopped Turbines +7 days - Auren
C4: Data hoje | F4: =TODAY() -> 46290
A5: Site | B5: WTG | C5: Data da parada | D5: Data de retorno | E5: Status | F5: Dias parada | G5: Previsão de Retorno | H5: Motivo | I5: Componente/Subsistema | J5: Brief Description | K5: Ação Pendente / Comentários | L5: %MCE | M5: Responsável pelas Ações | N5: Responsável | O5: Responsável pela Disponibilidade | P5: Horas paradas | Q5: Indisponibilidade TB | R5: 45292
A6: Caetés | B6: EBR04-15 | C6: 46203 | D6: 46220 | E6: Rodando | F6: =IF(D6="",TODAY()-C6,"-") -> - | H6: Troca Pitch Bearing | I6: Pitch Bearing | J6: MCE | K6: 16/07: Máquina parada para troca de pitch bearing. Responsabilidade Auren. | M6: Auren
A7: Caetés | B7: EBR07-12 | C7: 46189 | E7: Parada | F7: =IF(D7="",TODAY()-C7,"-") -> 101 | H7: Reparo de Blade | I7: Blade | J7: UPTOWER REPAIR | K7: 16/07: Máquina parada para reparo de blades. Responsabilidade Auren. 23/07: Reparo em andamento. 30/07: Sem previsão de retorno ainda. 10/09: Auren finalizando o reparo. | M7: Auren
A8: Caetés | B8: EBR02-13 | C8: 46218 | D8: 46220 | E8: Rodando | F8: =IF(D8="",TODAY()-C8,"-") -> - | H8: Troca de rolamento de HSS | I8: Gearbox | J8: UPTOWER REPAIR | K8: 16/07: Troca de rolamento HSS em andamento - time Invenergy. | M8: Invenergy
A9: Caetés | B9: EBR06-08 | C9: 46227 | E9: Parada | F9: =IF(D9="",TODAY()-C9,"-") -> 63 | H9: Falha no Pitch Bearing | I9: Pitch Bearing | J9: MCE | K9: 30/07: Falha no pitch bearing devido a danos internos. Previsão de retorno no início de set/26. 13/08: Auren se planejando para realização da troca. 10/09: Troca será feita com o time de Field Services. | M9: Auren
A10: Alto Sertão 2 | B10: PEL-03 | C10: 46216 | D10: 46227 | E10: Rodando | F10: =IF(D10="",TODAY()-C10,"-") -> - | H10: Troca de Gearbox | I10: Gearbox | J10: MCE | K10: 16/07: Troca de gearbox em andamento. | L10: 1 | M10: Auren
A11: Caetés | B11: EBR04-14 | C11: 46224 | D11: 46235 | E11: Rodando | F11: =IF(D11="",TODAY()-C11,"-") -> - | G11: 46234 | H11: Troca de rolamento de HSS | I11: Gearbox | J11: UPTOWER REPAIR | K11: 16/07: Troca de rolamento HSS em andamento - time Invenergy. 30/07: Previsão de retorno dia 31/07. 06/08: Finalizado | M11: Invenergy
A12: Alto Sertão 2 | B12: PEL-01 | C12: 46217 | D12: 46237 | E12: Rodando | F12: =IF(D12="",TODAY()-C12,"-") -> - | G12: 46235 | H12: Falha da fixação do bus bar | I12: Torre | J12: Troubleshooting | K12: 23/07: Máquina apresenta falha de Yaw Runaway, porém, não é possível atender devido a um dano na fixação do bus bar, o que impede asubida de forma segura à máquina. Tech End fará a correção. Início das atividades ocorrerá em 24/07. 30/07: Tech End realizando os reparos ainda. 06/08: Máquina rodando com 03 YDs | M12: Invenergy
A13: Alto Sertão 2 | B13: PEL-06 | C13: 46237 | D13: 46240 | E13: Rodando | F13: =IF(D13="",TODAY()-C13,"-") -> - | H13: Troca do HSS | I13: Gearbox | J13: UPTOWER REPAIR | K13: 06/08: Auren realizando troca do HSS. | M13: Auren
A14: Alto Sertão 2 | B14: AMT-02 | C14: 46186 | D14: 46247 | E14: Rodando | F14: =IF(D14="",TODAY()-C14,"-") -> - | G14: 46247 | H14: Falha de Gerador | I14: Gerador | J14: UPTOWER REPAIR | K14: 16/07: Aguardando mobilização da Positivo. Realizando treinamento de brigada de incêndio. 23/07: Previsão de mobilização da Positivo para semana que vem (28/07). 30/07: Positivo iniciará o serviço amanhã. 06/08: Positivo trocando cabos do relead. 10/08:Troca dos cabos do relead e reparo do wye ring finalizado no dia 10/08. 11/08: Realizada a isolação dos cabos do slipring e retirada de ferramental e conclusão da cura da resina. WTG em operação. Houve recorrência de falha na sequência. 12/08: Identificado cabo da AEBI em curto, substituído cabo e placa. WTG em operação e houve nova falha. Em troubleshooting em máquina identificou IGBTs estourados. 13/08: Time em turbina para finalizar troubleshooting. Aguardando finalização para retorno a operação. | M14: Invenergy
A15: Caetés | B15: EBR04-09 | C15: 46241 | D15: 46254 | E15: Rodando | F15: =IF(D15="",TODAY()-C15,"-") -> - | H15: Falha no Gerador. | I15: Gerador | J15: UPTOWER REPAIR | K15: 13/08: Identificado falhas nos cabos do relead. Aguardando mobilização da Positivo. Previsão de mobilização para essa semana. | M15: Invenergy
A16: Alto Sertão 2 | B16: BOR-04 | C16: 46252 | D16: 46254 | E16: Rodando | F16: =IF(D16="",TODAY()-C16,"-") -> - | G16: 46255 | H16: Troca do rolamento HSS | I16: Gearbox | J16: UPTOWER REPAIR | K16: 20/08: Auren executando troca do rolamento do HSS. | M16: Auren
A17: Alto Sertão 2 | B17: CAE-10 | C17: 46245 | D17: 46261 | E17: Rodando | F17: =IF(D17="",TODAY()-C17,"-") -> - | G17: 46261 | H17: Falha do pitch drive | I17: Pitch Drive | J17: UPTOWER REPAIR | K17: 20/08: Previsão de chegada do hub crane no parque e início da atividade no dia 23/08. 27/08: Troca sendo realizada. | M17: Invenergy
A18: Caetés | B18: EBR01-02 | C18: 46258 | D18: 46261 | E18: Rodando | F18: =IF(D18="",TODAY()-C18,"-") -> - | G18: 46261 | H18: Troca do rolamento HSS | I18: Gearbox | J18: UPTOWER REPAIR | K18: 27/08: Invenergy executando troca do rolamento do HSS. | M18: Invenergy
A19: Alto Sertão 2 | B19: PEL-03 | C19: 46244 | D19: 46272 | E19: Rodando | F19: =IF(D19="",TODAY()-C19,"-") -> - | H19: Falha no gerador | I19: Gerador | J19: Troubleshooting | K19: 12/08: Realizados testes e identificado danos no wye ring (12/08). 13/08: SS813. Aguardando finalização da abertura do gerador para confirmação do modo de falha. 20/08: Aguardando mobilização da positivo (prevista para terça - 25/08). 27/08: Positivo realizou a inspeção e recomendou a troca. Aguardando devolutiva da Auren. | M19: Invenergy
A20: Caetés | B20: EBR06-02 | C20: 46262 | D20: 46276 | E20: Rodando | F20: =IF(D20="",TODAY()-C20,"-") -> - | H20: Falha da gearbox | I20: Gearbox | J20: MCE | K20: 10/09: Auren solicitou a parada da máquina devido a falha do planetário. 17/09: Troca finalizada. | M20: Auren
A21: Alto Sertão 2 | B21: AMT-02 | C21: 46269 | D21: 46278 | E21: Rodando | F21: =IF(D21="",TODAY()-C21,"-") -> - | H21: Falha de gerador | I21: Gerador | J21: UPTOWER REPAIR | K21: 10/09: Positivo executando o reparo no barramento. | M21: Invenergy
A22: Alto Sertão 2 | B22: PIL-18 | C22: 46213 | D22: 46279 | E22: Rodando | F22: =IF(D22="",TODAY()-C22,"-") -> - | H22: Falha de Main Bearing | I22: Main Bearing | J22: MCE | K22: 16/07: Falha de Main Bearing. Aguardando troca do componente. Em avaliação possibilidade de troca com FSO Invenergy. 23/07: Invenergy contratada para troca. Previsão de guindaste operacional dia 17/08. 13/08: Guindaste só estará operacional a partir do dia 25/08 (info Auren). 20/08: Mobilização do guindaste em andamento. 27/08: Montagem de guindaste em andamento. 10/09: Troca em andamento. | M22: Auren
A23: Alto Sertão 2 | B23: DOU-10 | C23: 46235 | D23: 46279 | E23: Rodando | F23: =IF(D23="",TODAY()-C23,"-") -> - | H23: Falha de Gerador | I23: Gerador | J23: MCE | K23: 06/08: Disposição de troca da engenharia Invenergy. 13/08: Auren executou seus próprios testes em campo e também concluiu para a troca do gerador. 10/09: Aguardando a Auren realizar a troca. | M23: Auren
A24: Caetés | B24: EBR05-13 | C24: 46268 | E24: Parada | F24: =IF(D24="",TODAY()-C24,"-") -> 22 | G24: 46297 | H24: Colapso da gearbox | I24: Gearbox | J24: MCE | K24: 10/09: Houve o colapso da gearbox. 17/09: Auren mobilizando para troca. Previsão de finalização da atividade na semana que vem. Atividade será realizada com Liftra. | M24: Auren
A25: Alto Sertão 2 | B25: MAR-12 | C25: 46260 | D25: 46281 | E25: Rodando | F25: =IF(D25="",TODAY()-C25,"-") -> - | H25: Falha do Wye Ring | I25: Gerador | J25: UPTOWER REPAIR | K25: 10/09: Aguardando mobilização da Positivo. | M25: Invenergy

Sheet Planilha4 - Auren
A3: Soma de Total | B3: Year
A4: Week | B4: 2026
A5: 05 | B5: 0
A6: 06 | B6: 0
A7: 07 | B7: 0
A8: 08 | B8: 0
A9: 09 | B9: 0
A10: 10 | B10: 0
A11: 11 | B11: 0
A12: 12 | B12: 0
A13: 13 | B13: 0
A14: 14 | B14: 0
A15: 15 | B15: 0
A16: 16 | B16: 0
... A52: 52 | B52: 0

Sheet Historic - Auren
A1: YEAR+WEEK | B1: Year | C1: Week | D1: Domingo | E1: Sábado | F1: CAE | G1: AS2 | H1: Total | I1: Turbinas afetadas | J1: SOMA | K1: MÉDIA ACUMULADA | L1: MÉDIA ANUAL | M1: #
A2: 2026W05 | B2: =LEFT(A2,4) -> 2026 | C2: =RIGHT(A2,2) -> 05 | D2: 46048 | E2: =D2+6 -> 46054 | H2: =F2+G2 -> 0 | J2: =SUM(F2:G2) -> 0 | K2: =SUM(F2:G2)/M2 -> 0 | M2: 1 | N2: Registro de turbinas com mais de 7 dias paradas
A3: 2026W06 | B3: =LEFT(A3,4) -> 2026 | C3: =RIGHT(A3,2) -> 06 | D3: =D2+7 -> 46055 | E3: =D3+6 -> 46061 | H3: =F3+G3 -> 0 | J3: =SUM(F3:G3) -> 0 | K3: =SUM(F3:G3)/M3 -> 0 | M3: 2
A4: 2026W07 | B4: =LEFT(A4,4) -> 2026 | C4: =RIGHT(A4,2) -> 07 | D4: =D3+7 -> 46062 | E4: =D4+6 -> 46068 | H4: =F4+G4 -> 0 | J4: =SUM(F4:G4) -> 0 | K4: =SUM(F4:G4)/M4 -> 0 | M4: 3
A5: 2026W08 | B5: =LEFT(A5,4) -> 2026 | C5: =RIGHT(A5,2) -> 08 | D5: =D4+7 -> 46069 | E5: =D5+6 -> 46075 | H5: =F5+G5 -> 0 | J5: =SUM(F5:G5) -> 0 | K5: =SUM(F5:G5)/M5 -> 0 | M5: 4
A6: 2026W09 | B6: =LEFT(A6,4) -> 2026 | C6: =RIGHT(A6,2) -> 09 | D6: =D5+7 -> 46076 | E6: =D6+6 -> 46082 | H6: =F6+G6 -> 0 | J6: =SUM(F6:G6) -> 0 | K6: =SUM(F6:G6)/M6 -> 0 | M6: 5
A7: 2026W10 | B7: =LEFT(A7,4) -> 2026 | C7: =RIGHT(A7,2) -> 10 | D7: =D6+7 -> 46083 | E7: =D7+6 -> 46089 | H7: =F7+G7 -> 0 | J7: =SUM(F7:G7) -> 0 | K7: =SUM(F7:G7)/M7 -> 0 | M7: 6
A8: 2026W11 | B8: =LEFT(A8,4) -> 2026 | C8: =RIGHT(A8,2) -> 11 | D8: =D7+7 -> 46090 | E8: =D8+6 -> 46096 | H8: =F8+G8 -> 0 | J8: =SUM(F8:G8) -> 0 | K8: =SUM(F8:G8)/M8 -> 0 | M8: 7
A9: 2026W12 | B9: =LEFT(A9,4) -> 2026 | C9: =RIGHT(A9,2) -> 12 | D9: =D8+7 -> 46097 | E9: =D9+6 -> 46103 | H9: =F9+G9 -> 0 | J9: =SUM(F9:G9) -> 0 | K9: =SUM(F9:G9)/M9 -> 0 | M9: 8
A10: 2026W13 | B10: =LEFT(A10,4) -> 2026 | C10: =RIGHT(A10,2) -> 13 | D10: =D9+7 -> 46104 | E10: =D10+6 -> 46110 | H10: =F10+G10 -> 0 | J10: =SUM(F10:G10) -> 0 | K10: =SUM(F10:G10)/M10 -> 0 | M10: 9
A11: 2026W14 | B11: =LEFT(A11,4) -> 2026 | C11: =RIGHT(A11,2) -> 14 | D11: =D10+7 -> 46111 | E11: =D11+6 -> 46117 | H11: =F11+G11 -> 0 | J11: =SUM(F11:G11) -> 0 | K11: =SUM(F11:G11)/M11 -> 0 | M11: 10
A12: 2026W15 | B12: =LEFT(A12,4) -> 2026 | C12: =RIGHT(A12,2) -> 15 | D12: =D11+7 -> 46118 | E12: =D12+6 -> 46124 | H12: =F12+G12 -> 0 | J12: =SUM(F12:G12) -> 0 | K12: =SUM(F12:G12)/M12 -> 0 | M12: 11
A13: 2026W16 | B13: =LEFT(A13,4) -> 2026 | C13: =RIGHT(A13,2) -> 16 | D13: =D12+7 -> 46125 | E13: =D13+6 -> 46131 | H13: =F13+G13 -> 0 | J13: =SUM(F13:G13) -> 0 | K13: =SUM(F13:G13)/M13 -> 0 | M13: 12
A14: 2026W17 | B14: =LEFT(A14,4) -> 2026 | C14: =RIGHT(A14,2) -> 17 | D14: =D13+7 -> 46132 | E14: =D14+6 -> 46138 | H14: =F14+G14 -> 0 | J14: =SUM(F14:G14) -> 0 | K14: =SUM(F14:G14)/M14 -> 0 | M14: 13
... A25: 2026W28 | B25: =LEFT(A25,4) -> 2026 | C25: =RIGHT(A25,2) -> 28 | D25: =D24+7 -> 46209 | E25: =D25+6 -> 46215 | H25: =F25+G25 -> 0 | J25: =SUM(F25:G25) -> 0 | K25: =SUM(F25:G25)/M25 -> 0 | M25: 24
A26: 2026W29 | B26: =LEFT(A26,4) -> 2026 | C26: =RIGHT(A26,2) -> 29 | D26: =D25+7 -> 46216 | E26: =D26+6 -> 46222 | F26: 2 | G26: 1 | H26: =F26+G26 -> 3 | J26: =SUM(F26:G26) -> 3 | K26: =SUM(F26:G26)/M26 -> 0.12 | M26: 25
